ts_recv,ts_event,rtype,publisher_id,instrument_id,action,side,depth,price,size,flags,ts_in_delta,sequence,bid_px_00,bid_sz_00,bid_ct_00,ask_px_00,ask_sz_00,ask_ct_00,bid_px_01,bid_sz_01,bid_ct_01,ask_px_01,ask_sz_01,ask_ct_01,bid_px_02,bid_sz_02,bid_ct_02,ask_px_02,ask_sz_02,ask_ct_02,bid_px_03,bid_sz_03,bid_ct_03,ask_px_03,ask_sz_03,ask_ct_03,bid_px_04,bid_sz_04,bid_ct_04,ask_px_04,ask_sz_04,ask_ct_04,bid_px_05,bid_sz_05,bid_ct_05,ask_px_05,ask_sz_05,ask_ct_05,bid_px_06,bid_sz_06,bid_ct_06,ask_px_06,ask_sz_06,ask_ct_06,bid_px_07,bid_sz_07,bid_ct_07,ask_px_07,ask_sz_07,ask_ct_07,bid_px_08,bid_sz_08,bid_ct_08,ask_px_08,ask_sz_08,ask_ct_08,bid_px_09,bid_sz_09,bid_ct_09,ask_px_09,ask_sz_09,ask_ct_09,symbol,order_id
2025-07-17T15:44:33.389389030Z,2025-07-17T15:44:33.389223581Z,10,2,1108,C,A,0,14.56,100,130,165449,253745666,13.26,100,1,13.72,15,1,13.04,2,1,13.73,100,1,13.03,100,1,13.74,15,1,12.73,100,1,13.75,100,1,12.71,100,1,14.03,100,1,12.50,700,1,14.07,2,1,12.46,200,2,14.28,100,1,12.43,700,1,14.40,100,1,12.42,700,1,14.56,800,2,12.37,700,1,14.60,700,1,ARL,146960005
2025-07-17T15:44:36.362187673Z,2025-07-17T15:44:36.362022168Z,10,2,1108,C,A,0,13.74,15,130,165505,253783635,13.26,100,1,13.72,15,1,13.04,2,1,13.73,100,1,13.03,100,1,13.75,100,1,12.73,100,1,14.03,100,1,12.71,100,1,14.07,2,1,12.50,700,1,14.28,100,1,12.46,200,2,14.40,100,1,12.43,700,1,14.56,800,2,12.42,700,1,14.60,700,1,12.37,700,1,14.64,100,1,ARL,302458113
2025-07-17T15:44:37.364377419Z,2025-07-17T15:44:37.364212109Z,10,2,1108,A,A,0,13.70,15,130,165310,253797506,13.26,100,1,13.70,15,1,13.04,2,1,13.72,15,1,13.03,100,1,13.73,100,1,12.73,100,1,13.75,100,1,12.71,100,1,14.03,100,1,12.50,700,1,14.07,2,1,12.46,200,2,14.28,100,1,12.43,700,1,14.40,100,1,12.42,700,1,14.56,800,2,12.37,700,1,14.60,700,1,ARL,302750929
2025-07-17T15:44:37.364519067Z,2025-07-17T15:44:37.364353897Z,10,2,1108,A,A,0,13.73,100,130,165170,253797510,13.26,100,1,13.70,15,1,13.04,2,1,13.72,15,1,13.03,100,1,13.73,200,2,12.73,100,1,13.75,100,1,12.71,100,1,14.03,100,1,12.50,700,1,14.07,2,1,12.46,200,2,14.28,100,1,12.43,700,1,14.40,100,1,12.42,700,1,14.56,800,2,12.37,700,1,14.60,700,1,ARL,302750937
2025-07-17T15:44:37.458119494Z,2025-07-17T15:44:37.457954350Z,10,2,1108,C,A,0,13.75,100,130,165144,253798432,13.26,100,1,13.70,15,1,13.04,2,1,13.72,15,1,13.03,100,1,13.73,200,2,12.73,100,1,14.03,100,1,12.71,100,1,14.07,2,1,12.50,700,1,14.28,100,1,12.46,200,2,14.40,100,1,12.43,700,1,14.56,800,2,12.42,700,1,14.60,700,1,12.37,700,1,14.64,100,1,ARL,302649029
2025-07-17T15:44:38.432460509Z,2025-07-17T15:44:38.432294362Z,10,2,1108,C,A,0,13.73,100,0,166147,253807786,13.26,100,1,13.70,15,1,13.04,2,1,13.72,15,1,13.03,100,1,13.73,100,1,12.73,100,1,14.03,100,1,12.71,100,1,14.07,2,1,12.50,700,1,14.28,100,1,12.46,200,2,14.40,100,1,12.43,700,1,14.56,800,2,12.42,700,1,14.60,700,1,12.37,700,1,14.64,100,1,ARL,302662769
2025-07-17T15:44:38.432460509Z,2025-07-17T15:44:38.432294362Z,10,2,1108,A,A,0,13.71,100,130,166147,253807786,13.26,100,1,13.70,15,1,13.04,2,1,13.71,100,1,13.03,100,1,13.72,15,1,12.73,100,1,13.73,100,1,12.71,100,1,14.03,100,1,12.50,700,1,14.07,2,1,12.46,200,2,14.28,100,1,12.43,700,1,14.40,100,1,12.42,700,1,14.56,800,2,12.37,700,1,14.60,700,1,ARL,302763889
2025-07-17T15:44:38.439253975Z,2025-07-17T15:44:38.439088042Z,10,2,1108,C,A,0,15.92,100,0,165933,253808105,13.26,100,1,13.70,15,1,13.04,2,1,13.71,100,1,13.03,100,1,13.72,15,1,12.73,100,1,13.73,100,1,12.71,100,1,14.03,100,1,12.50,700,1,14.07,2,1,12.46,200,2,14.28,100,1,12.43,700,1,14.40,100,1,12.42,700,1,14.56,800,2,12.37,700,1,14.60,700,1,ARL,301747301
2025-07-17T15:44:38.439253975Z,2025-07-17T15:44:38.439088042Z,10,2,1108,A,A,0,15.77,100,130,165933,253808105,13.26,100,1,13.70,15,1,13.04,2,1,13.71,100,1,13.03,100,1,13.72,15,1,12.73,100,1,13.73,100,1,12.71,100,1,14.03,100,1,12.50,700,1,14.07,2,1,12.46,200,2,14.28,100,1,12.43,700,1,14.40,100,1,12.42,700,1,14.56,800,2,12.37,700,1,14.60,700,1,ARL,302764121
2025-07-17T15:44:38.440321697Z,2025-07-17T15:44:38.440156077Z,10,2,1108,C,A,0,17.58,100,0,165620,253808122,13.26,100,1,13.70,15,1,13.04,2,1,13.71,100,1,13.03,100,1,13.72,15,1,12.73,100,1,13.73,100,1,12.71,100,1,14.03,100,1,12.50,700,1,14.07,2,1,12.46,200,2,14.28,100,1,12.43,700,1,14.40,100,1,12.42,700,1,14.56,800,2,12.37,700,1,14.60,700,1,ARL,301747261
2025-07-17T15:44:38.440321697Z,2025-07-17T15:44:38.440156077Z,10,2,1108,A,A,0,17.42,100,130,165620,253808122,13.26,100,1,13.70,15,1,13.04,2,1,13.71,100,1,13.03,100,1,13.72,15,1,12.73,100,1,13.73,100,1,12.71,100,1,14.03,100,1,12.50,700,1,14.07,2,1,12.46,200,2,14.28,100,1,12.43,700,1,14.40,100,1,12.42,700,1,14.56,800,2,12.37,700,1,14.60,700,1,ARL,302764137
2025-07-17T15:44:43.019262217Z,2025-07-17T15:44:43.019083502Z,10,2,1108,C,A,0,13.70,15,128,178715,253875920,13.26,100,1,13.71,100,1,13.04,2,1,13.72,15,1,13.03,100,1,13.73,100,1,12.73,100,1,14.03,100,1,12.71,100,1,14.07,2,1,12.50,700,1,14.28,100,1,12.46,200,2,14.40,100,1,12.43,700,1,14.56,800,2,12.42,700,1,14.60,700,1,12.37,700,1,14.64,100,1,ARL,302750929
2025-07-17T15:44:43.019352658Z,2025-07-17T15:44:43.019184132Z,10,2,1108,C,A,0,13.72,15,128,168526,253876010,13.26,100,1,13.71,100,1,13.04,2,1,13.73,100,1,13.03,100,1,14.03,100,1,12.73,100,1,14.07,2,1,12.71,100,1,14.28,100,1,12.50,700,1,14.40,100,1,12.46,200,2,14.56,800,2,12.43,700,1,14.60,700,1,12.42,700,1,14.64,100,1,12.37,700,1,14.66,200,2,ARL,302649021
2025-07-17T15:44:44.076009999Z,2025-07-17T15:44:44.075843113Z,10,2,1108,A,A,0,13.70,15,128,166886,253892869,13.26,100,1,13.70,15,1,13.04,2,1,13.71,100,1,13.03,100,1,13.73,100,1,12.73,100,1,14.03,100,1,12.71,100,1,14.07,2,1,12.50,700,1,14.28,100,1,12.46,200,2,14.40,100,1,12.43,700,1,14.56,800,2,12.42,700,1,14.60,700,1,12.37,700,1,14.64,100,1,ARL,302867209
2025-07-17T15:44:44.781630732Z,2025-07-17T15:44:44.781464821Z,10,2,1108,C,A,0,13.70,15,130,165911,253901222,13.26,100,1,13.71,100,1,13.04,2,1,13.73,100,1,13.03,100,1,14.03,100,1,12.73,100,1,14.07,2,1,12.71,100,1,14.28,100,1,12.50,700,1,14.40,100,1,12.46,200,2,14.56,800,2,12.43,700,1,14.60,700,1,12.42,700,1,14.64,100,1,12.37,700,1,14.66,200,2,ARL,302867209
2025-07-17T15:44:53.143249270Z,2025-07-17T15:44:53.143083969Z,10,2,1108,C,A,0,13.73,100,130,165301,254011871,13.26,100,1,13.71,100,1,13.04,2,1,14.03,100,1,13.03,100,1,14.07,2,1,12.73,100,1,14.28,100,1,12.71,100,1,14.40,100,1,12.50,700,1,14.56,800,2,12.46,200,2,14.60,700,1,12.43,700,1,14.64,100,1,12.42,700,1,14.66,200,2,12.37,700,1,14.68,1400,2,ARL,302750937
2025-07-17T15:44:57.191188470Z,2025-07-17T15:44:57.191023026Z,10,2,1108,A,A,0,13.75,100,130,165444,254079162,13.26,100,1,13.71,100,1,13.04,2,1,13.75,100,1,13.03,100,1,14.03,100,1,12.73,100,1,14.07,2,1,12.71,100,1,14.28,100,1,12.50,700,1,14.40,100,1,12.46,200,2,14.56,800,2,12.43,700,1,14.60,700,1,12.42,700,1,14.64,100,1,12.37,700,1,14.66,200,2,ARL,303118785
2025-07-17T15:45:07.065756574Z,2025-07-17T15:45:07.065587919Z,10,2,1108,C,A,0,13.71,100,128,168655,254244597,13.26,100,1,13.75,100,1,13.04,2,1,14.03,100,1,13.03,100,1,14.07,2,1,12.73,100,1,14.28,100,1,12.71,100,1,14.40,100,1,12.50,700,1,14.56,800,2,12.46,200,2,14.60,700,1,12.43,700,1,14.64,100,1,12.42,700,1,14.66,200,2,12.37,700,1,14.68,1400,2,ARL,302763889
2025-07-17T15:45:07.080131505Z,2025-07-17T15:45:07.079966224Z,10,2,1108,C,A,0,13.75,100,130,165281,254245492,13.26,100,1,14.03,100,1,13.04,2,1,14.07,2,1,13.03,100,1,14.28,100,1,12.73,100,1,14.40,100,1,12.71,100,1,14.56,800,2,12.50,700,1,14.60,700,1,12.46,200,2,14.64,100,1,12.43,700,1,14.66,200,2,12.42,700,1,14.68,1400,2,12.37,700,1,14.79,100,1,ARL,303118785
2025-07-17T15:45:07.080687215Z,2025-07-17T15:45:07.080521807Z,10,2,1108,C,A,0,14.66,100,0,165408,254245505,13.26,100,1,14.03,100,1,13.04,2,1,14.07,2,1,13.03,100,1,14.28,100,1,12.73,100,1,14.40,100,1,12.71,100,1,14.56,800,2,12.50,700,1,14.60,700,1,12.46,200,2,14.64,100,1,12.43,700,1,14.66,100,1,12.42,700,1,14.68,1400,2,12.37,700,1,14.79,100,1,ARL,302205289
2025-07-17T15:45:07.080687215Z,2025-07-17T15:45:07.080521807Z,10,2,1108,A,A,0,14.89,100,130,165408,254245505,13.26,100,1,14.03,100,1,13.04,2,1,14.07,2,1,13.03,100,1,14.28,100,1,12.73,100,1,14.40,100,1,12.71,100,1,14.56,800,2,12.50,700,1,14.60,700,1,12.46,200,2,14.64,100,1,12.43,700,1,14.66,100,1,12.42,700,1,14.68,1400,2,12.37,700,1,14.79,100,1,ARL,303330477
2025-07-17T15:45:07.080872245Z,2025-07-17T15:45:07.080706110Z,10,2,1108,C,A,0,14.79,100,0,166135,254245511,13.26,100,1,14.03,100,1,13.04,2,1,14.07,2,1,13.03,100,1,14.28,100,1,12.73,100,1,14.40,100,1,12.71,100,1,14.56,800,2,12.50,700,1,14.60,700,1,12.46,200,2,14.64,100,1,12.43,700,1,14.66,100,1,12.42,700,1,14.68,1400,2,12.37,700,1,14.81,200,2,ARL,302662821
2025-07-17T15:45:07.080872245Z,2025-07-17T15:45:07.080706110Z,10,2,1108,A,A,0,15.06,100,130,166135,254245511,13.26,100,1,14.03,100,1,13.04,2,1,14.07,2,1,13.03,100,1,14.28,100,1,12.73,100,1,14.40,100,1,12.71,100,1,14.56,800,2,12.50,700,1,14.60,700,1,12.46,200,2,14.64,100,1,12.43,700,1,14.66,100,1,12.42,700,1,14.68,1400,2,12.37,700,1,14.81,200,2,ARL,303330485
2025-07-17T15:45:07.081578064Z,2025-07-17T15:45:07.081407507Z,10,2,1108,C,A,0,14.81,100,0,170557,254245568,13.26,100,1,14.03,100,1,13.04,2,1,14.07,2,1,13.03,100,1,14.28,100,1,12.73,100,1,14.40,100,1,12.71,100,1,14.56,800,2,12.50,700,1,14.60,700,1,12.46,200,2,14.64,100,1,12.43,700,1,14.66,100,1,12.42,700,1,14.68,1400,2,12.37,700,1,14.81,100,1,ARL,301747001
2025-07-17T15:45:07.081578064Z,2025-07-17T15:45:07.081407507Z,10,2,1108,A,A,0,14.96,100,128,170557,254245568,13.26,100,1,14.03,100,1,13.04,2,1,14.07,2,1,13.03,100,1,14.28,100,1,12.73,100,1,14.40,100,1,12.71,100,1,14.56,800,2,12.50,700,1,14.60,700,1,12.46,200,2,14.64,100,1,12.43,700,1,14.66,100,1,12.42,700,1,14.68,1400,2,12.37,700,1,14.81,100,1,ARL,303330509
2025-07-17T15:45:07.081607970Z,2025-07-17T15:45:07.081441134Z,10,2,1108,C,A,0,14.66,100,0,166836,254245576,13.26,100,1,14.03,100,1,13.04,2,1,14.07,2,1,13.03,100,1,14.28,100,1,12.73,100,1,14.40,100,1,12.71,100,1,14.56,800,2,12.50,700,1,14.60,700,1,12.46,200,2,14.64,100,1,12.43,700,1,14.68,1400,2,12.42,700,1,14.81,100,1,12.37,700,1,14.89,100,1,ARL,302205309
2025-07-17T15:45:07.081607970Z,2025-07-17T15:45:07.081441134Z,10,2,1108,A,A,0,14.89,100,130,166836,254245576,13.26,100,1,14.03,100,1,13.04,2,1,14.07,2,1,13.03,100,1,14.28,100,1,12.73,100,1,14.40,100,1,12.71,100,1,14.56,800,2,12.50,700,1,14.60,700,1,12.46,200,2,14.64,100,1,12.43,700,1,14.68,1400,2,12.42,700,1,14.81,100,1,12.37,700,1,14.89,200,2,ARL,303330521
2025-07-17T15:45:07.083898999Z,2025-07-17T15:45:07.083732443Z,10,2,1108,C,A,0,17.42,100,0,166556,254246327,13.26,100,1,14.03,100,1,13.04,2,1,14.07,2,1,13.03,100,1,14.28,100,1,12.73,100,1,14.40,100,1,12.71,100,1,14.56,800,2,12.50,700,1,14.60,700,1,12.46,200,2,14.64,100,1,12.43,700,1,14.68,1400,2,12.42,700,1,14.81,100,1,12.37,700,1,14.89,200,2,ARL,302764137
2025-07-17T15:45:07.083898999Z,2025-07-17T15:45:07.083732443Z,10,2,1108,A,A,0,17.76,100,130,166556,254246327,13.26,100,1,14.03,100,1,13.04,2,1,14.07,2,1,13.03,100,1,14.28,100,1,12.73,100,1,14.40,100,1,12.71,100,1,14.56,800,2,12.50,700,1,14.60,700,1,12.46,200,2,14.64,100,1,12.43,700,1,14.68,1400,2,12.42,700,1,14.81,100,1,12.37,700,1,14.89,200,2,ARL,303331309
2025-07-17T15:45:07.085222525Z,2025-07-17T15:45:07.085057258Z,10,2,1108,C,A,0,14.03,100,130,165267,254246434,13.26,100,1,14.07,2,1,13.04,2,1,14.28,100,1,13.03,100,1,14.40,100,1,12.73,100,1,14.56,800,2,12.71,100,1,14.60,700,1,12.50,700,1,14.64,100,1,12.46,200,2,14.68,1400,2,12.43,700,1,14.81,100,1,12.42,700,1,14.89,200,2,12.37,700,1,14.96,100,1,ARL,302466157
2025-07-17T15:45:07.085274852Z,2025-07-17T15:45:07.085109545Z,10,2,1108,A,A,0,14.26,100,130,165307,254246437,13.26,100,1,14.07,2,1,13.04,2,1,14.26,100,1,13.03,100,1,14.28,100,1,12.73,100,1,14.40,100,1,12.71,100,1,14.56,800,2,12.50,700,1,14.60,700,1,12.46,200,2,14.64,100,1,12.43,700,1,14.68,1400,2,12.42,700,1,14.81,100,1,12.37,700,1,14.89,200,2,ARL,303331401
2025-07-17T15:45:07.086534700Z,2025-07-17T15:45:07.086368957Z,10,2,1108,C,A,0,14.64,100,130,165743,254246501,13.26,100,1,14.07,2,1,13.04,2,1,14.26,100,1,13.03,100,1,14.28,100,1,12.73,100,1,14.40,100,1,12.71,100,1,14.56,800,2,12.50,700,1,14.60,700,1,12.46,200,2,14.68,1400,2,12.43,700,1,14.81,100,1,12.42,700,1,14.89,200,2,12.37,700,1,14.96,100,1,ARL,301747005
2025-07-17T15:45:07.086660325Z,2025-07-17T15:45:07.086494745Z,10,2,1108,A,A,0,14.78,100,130,165580,254246502,13.26,100,1,14.07,2,1,13.04,2,1,14.26,100,1,13.03,100,1,14.28,100,1,12.73,100,1,14.40,100,1,12.71,100,1,14.56,800,2,12.50,700,1,14.60,700,1,12.46,200,2,14.68,1400,2,12.43,700,1,14.78,100,1,12.42,700,1,14.81,100,1,12.37,700,1,14.89,200,2,ARL,303331425
2025-07-17T15:45:07.087389466Z,2025-07-17T15:45:07.087223859Z,10,2,1108,C,A,0,15.77,100,0,165607,254246529,13.26,100,1,14.07,2,1,13.04,2,1,14.26,100,1,13.03,100,1,14.28,100,1,12.73,100,1,14.40,100,1,12.71,100,1,14.56,800,2,12.50,700,1,14.60,700,1,12.46,200,2,14.68,1400,2,12.43,700,1,14.78,100,1,12.42,700,1,14.81,100,1,12.37,700,1,14.89,200,2,ARL,302764121
2025-07-17T15:45:07.087389466Z,2025-07-17T15:45:07.087223859Z,10,2,1108,A,A,0,16.08,100,130,165607,254246529,13.26,100,1,14.07,2,1,13.04,2,1,14.26,100,1,13.03,100,1,14.28,100,1,12.73,100,1,14.40,100,1,12.71,100,1,14.56,800,2,12.50,700,1,14.60,700,1,12.46,200,2,14.68,1400,2,12.43,700,1,14.78,100,1,12.42,700,1,14.81,100,1,12.37,700,1,14.89,200,2,ARL,303331429
2025-07-17T15:45:07.133978488Z,2025-07-17T15:45:07.133812895Z,10,2,1108,C,A,0,14.81,100,0,165593,254250625,13.26,100,1,14.07,2,1,13.04,2,1,14.26,100,1,13.03,100,1,14.28,100,1,12.73,100,1,14.40,100,1,12.71,100,1,14.56,800,2,12.50,700,1,14.60,700,1,12.46,200,2,14.68,1400,2,12.43,700,1,14.78,100,1,12.42,700,1,14.89,200,2,12.37,700,1,14.96,100,1,ARL,301747957
2025-07-17T15:45:07.133978488Z,2025-07-17T15:45:07.133812895Z,10,2,1108,A,A,0,14.96,100,130,165593,254250625,13.26,100,1,14.07,2,1,13.04,2,1,14.26,100,1,13.03,100,1,14.28,100,1,12.73,100,1,14.40,100,1,12.71,100,1,14.56,800,2,12.50,700,1,14.60,700,1,12.46,200,2,14.68,1400,2,12.43,700,1,14.78,100,1,12.42,700,1,14.89,200,2,12.37,700,1,14.96,200,2,ARL,303334253
2025-07-17T15:45:07.469961302Z,2025-07-17T15:45:07.469796155Z,10,2,1108,A,A,0,14.08,100,130,165147,254258029,13.26,100,1,14.07,2,1,13.04,2,1,14.08,100,1,13.03,100,1,14.26,100,1,12.73,100,1,14.28,100,1,12.71,100,1,14.40,100,1,12.50,700,1,14.56,800,2,12.46,200,2,14.60,700,1,12.43,700,1,14.68,1400,2,12.42,700,1,14.78,100,1,12.37,700,1,14.89,200,2,ARL,303340405
2025-07-17T15:45:08.094768552Z,2025-07-17T15:45:08.094603115Z,10,2,1108,C,A,0,14.89,100,0,165437,254266885,13.26,100,1,14.07,2,1,13.04,2,1,14.08,100,1,13.03,100,1,14.26,100,1,12.73,100,1,14.28,100,1,12.71,100,1,14.40,100,1,12.50,700,1,14.56,800,2,12.46,200,2,14.60,700,1,12.43,700,1,14.68,1400,2,12.42,700,1,14.78,100,1,12.37,700,1,14.89,100,1,ARL,303330521
2025-07-17T15:45:08.094768552Z,2025-07-17T15:45:08.094603115Z,10,2,1108,A,A,0,15.10,100,130,165437,254266885,13.26,100,1,14.07,2,1,13.04,2,1,14.08,100,1,13.03,100,1,14.26,100,1,12.73,100,1,14.28,100,1,12.71,100,1,14.40,100,1,12.50,700,1,14.56,800,2,12.46,200,2,14.60,700,1,12.43,700,1,14.68,1400,2,12.42,700,1,14.78,100,1,12.37,700,1,14.89,100,1,ARL,303349309
2025-07-17T15:45:08.103306644Z,2025-07-17T15:45:08.103141155Z,10,2,1108,C,A,0,14.89,100,0,165489,254266971,13.26,100,1,14.07,2,1,13.04,2,1,14.08,100,1,13.03,100,1,14.26,100,1,12.73,100,1,14.28,100,1,12.71,100,1,14.40,100,1,12.50,700,1,14.56,800,2,12.46,200,2,14.60,700,1,12.43,700,1,14.68,1400,2,12.42,700,1,14.78,100,1,12.37,700,1,14.96,200,2,ARL,303330477
2025-07-17T15:45:08.103306644Z,2025-07-17T15:45:08.103141155Z,10,2,1108,A,A,0,15.10,100,130,165489,254266971,13.26,100,1,14.07,2,1,13.04,2,1,14.08,100,1,13.03,100,1,14.26,100,1,12.73,100,1,14.28,100,1,12.71,100,1,14.40,100,1,12.50,700,1,14.56,800,2,12.46,200,2,14.60,700,1,12.43,700,1,14.68,1400,2,12.42,700,1,14.78,100,1,12.37,700,1,14.96,200,2,ARL,303349377
2025-07-17T15:45:24.187008278Z,2025-07-17T15:45:24.186842413Z,10,2,1108,C,A,0,15.10,100,0,165865,254547413,13.26,100,1,14.07,2,1,13.04,2,1,14.08,100,1,13.03,100,1,14.26,100,1,12.73,100,1,14.28,100,1,12.71,100,1,14.40,100,1,12.50,700,1,14.56,800,2,12.46,200,2,14.60,700,1,12.43,700,1,14.68,1400,2,12.42,700,1,14.78,100,1,12.37,700,1,14.96,200,2,ARL,303349309
2025-07-17T15:45:24.187008278Z,2025-07-17T15:45:24.186842413Z,10,2,1108,A,A,0,14.88,100,130,165865,254547413,13.26,100,1,14.07,2,1,13.04,2,1,14.08,100,1,13.03,100,1,14.26,100,1,12.73,100,1,14.28,100,1,12.71,100,1,14.40,100,1,12.50,700,1,14.56,800,2,12.46,200,2,14.60,700,1,12.43,700,1,14.68,1400,2,12.42,700,1,14.78,100,1,12.37,700,1,14.88,100,1,ARL,303682385
2025-07-17T15:45:24.187441892Z,2025-07-17T15:45:24.187276389Z,10,2,1108,C,A,0,15.10,100,0,165503,254547415,13.26,100,1,14.07,2,1,13.04,2,1,14.08,100,1,13.03,100,1,14.26,100,1,12.73,100,1,14.28,100,1,12.71,100,1,14.40,100,1,12.50,700,1,14.56,800,2,12.46,200,2,14.60,700,1,12.43,700,1,14.68,1400,2,12.42,700,1,14.78,100,1,12.37,700,1,14.88,100,1,ARL,303349377
2025-07-17T15:45:24.187441892Z,2025-07-17T15:45:24.187276389Z,10,2,1108,A,A,0,14.88,100,130,165503,254547415,13.26,100,1,14.07,2,1,13.04,2,1,14.08,100,1,13.03,100,1,14.26,100,1,12.73,100,1,14.28,100,1,12.71,100,1,14.40,100,1,12.50,700,1,14.56,800,2,12.46,200,2,14.60,700,1,12.43,700,1,14.68,1400,2,12.42,700,1,14.78,100,1,12.37,700,1,14.88,200,2,ARL,303682389
2025-07-17T15:45:37.509454888Z,2025-07-17T15:45:37.509289536Z,10,2,1108,A,A,0,13.94,15,130,165352,254851462,13.26,100,1,13.94,15,1,13.04,2,1,14.07,2,1,13.03,100,1,14.08,100,1,12.73,100,1,14.26,100,1,12.71,100,1,14.28,100,1,12.50,700,1,14.40,100,1,12.46,200,2,14.56,800,2,12.43,700,1,14.60,700,1,12.42,700,1,14.68,1400,2,12.37,700,1,14.78,100,1,ARL,304056997
2025-07-17T15:45:37.998133497Z,2025-07-17T15:45:37.997967775Z,10,2,1108,C,A,0,14.08,100,0,165722,254864588,13.26,100,1,13.94,15,1,13.04,2,1,14.07,2,1,13.03,100,1,14.26,100,1,12.73,100,1,14.28,100,1,12.71,100,1,14.40,100,1,12.50,700,1,14.56,800,2,12.46,200,2,14.60,700,1,12.43,700,1,14.68,1400,2,12.42,700,1,14.78,100,1,12.37,700,1,14.88,200,2,ARL,303340405
2025-07-17T15:45:37.998133497Z,2025-07-17T15:45:37.997967775Z,10,2,1108,A,A,0,13.95,100,130,165722,254864588,13.26,100,1,13.94,15,1,13.04,2,1,13.95,100,1,13.03,100,1,14.07,2,1,12.73,100,1,14.26,100,1,12.71,100,1,14.28,100,1,12.50,700,1,14.40,100,1,12.46,200,2,14.56,800,2,12.43,700,1,14.60,700,1,12.42,700,1,14.68,1400,2,12.37,700,1,14.78,100,1,ARL,304072245
2025-07-17T15:45:44.700593408Z,2025-07-17T15:45:44.700428155Z,10,2,1108,A,A,0,13.89,15,130,165253,254999429,13.26,100,1,13.89,15,1,13.04,2,1,13.94,15,1,13.03,100,1,13.95,100,1,12.73,100,1,14.07,2,1,12.71,100,1,14.26,100,1,12.50,700,1,14.28,100,1,12.46,200,2,14.40,100,1,12.43,700,1,14.56,800,2,12.42,700,1,14.60,700,1,12.37,700,1,14.68,1400,2,ARL,304238913
2025-07-17T15:45:45.262537122Z,2025-07-17T15:45:45.262371701Z,10,2,1108,C,A,0,13.95,100,0,165421,255010979,13.26,100,1,13.89,15,1,13.04,2,1,13.94,15,1,13.03,100,1,14.07,2,1,12.73,100,1,14.26,100,1,12.71,100,1,14.28,100,1,12.50,700,1,14.40,100,1,12.46,200,2,14.56,800,2,12.43,700,1,14.60,700,1,12.42,700,1,14.68,1400,2,12.37,700,1,14.78,100,1,ARL,304072245
2025-07-17T15:45:45.262537122Z,2025-07-17T15:45:45.262371701Z,10,2,1108,A,A,0,13.90,100,130,165421,255010979,13.26,100,1,13.89,15,1,13.04,2,1,13.90,100,1,13.03,100,1,13.94,15,1,12.73,100,1,14.07,2,1,12.71,100,1,14.26,100,1,12.50,700,1,14.28,100,1,12.46,200,2,14.40,100,1,12.43,700,1,14.56,800,2,12.42,700,1,14.60,700,1,12.37,700,1,14.68,1400,2,ARL,304252313
2025-07-17T15:45:45.263289023Z,2025-07-17T15:45:45.263123432Z,10,2,1108,C,A,0,15.06,100,0,165591,255010987,13.26,100,1,13.89,15,1,13.04,2,1,13.90,100,1,13.03,100,1,13.94,15,1,12.73,100,1,14.07,2,1,12.71,100,1,14.26,100,1,12.50,700,1,14.28,100,1,12.46,200,2,14.40,100,1,12.43,700,1,14.56,800,2,12.42,700,1,14.60,700,1,12.37,700,1,14.68,1400,2,ARL,303330485
2025-07-17T15:45:45.263289023Z,2025-07-17T15:45:45.263123432Z,10,2,1108,A,A,0,14.98,100,130,165591,255010987,13.26,100,1,13.89,15,1,13.04,2,1,13.90,100,1,13.03,100,1,13.94,15,1,12.73,100,1,14.07,2,1,12.71,100,1,14.26,100,1,12.50,700,1,14.28,100,1,12.46,200,2,14.40,100,1,12.43,700,1,14.56,800,2,12.42,700,1,14.60,700,1,12.37,700,1,14.68,1400,2,ARL,304252333
2025-07-17T15:45:45.274360382Z,2025-07-17T15:45:45.274194870Z,10,2,1108,C,A,0,14.26,100,130,165512,255011158,13.26,100,1,13.89,15,1,13.04,2,1,13.90,100,1,13.03,100,1,13.94,15,1,12.73,100,1,14.07,2,1,12.71,100,1,14.28,100,1,12.50,700,1,14.40,100,1,12.46,200,2,14.56,800,2,12.43,700,1,14.60,700,1,12.42,700,1,14.68,1400,2,12.37,700,1,14.78,100,1,ARL,303331401
2025-07-17T15:45:45.274410721Z,2025-07-17T15:45:45.274245387Z,10,2,1108,A,A,0,14.18,100,130,165334,255011161,13.26,100,1,13.89,15,1,13.04,2,1,13.90,100,1,13.03,100,1,13.94,15,1,12.73,100,1,14.07,2,1,12.71,100,1,14.18,100,1,12.50,700,1,14.28,100,1,12.46,200,2,14.40,100,1,12.43,700,1,14.56,800,2,12.42,700,1,14.60,700,1,12.37,700,1,14.68,1400,2,ARL,304252469
2025-07-17T15:45:58.419783333Z,2025-07-17T15:45:58.419617935Z,10,2,1108,C,A,0,13.94,15,130,165398,255183198,13.26,100,1,13.89,15,1,13.04,2,1,13.90,100,1,13.03,100,1,14.07,2,1,12.73,100,1,14.18,100,1,12.71,100,1,14.28,100,1,12.50,700,1,14.40,100,1,12.46,200,2,14.56,800,2,12.43,700,1,14.60,700,1,12.42,700,1,14.68,1400,2,12.37,700,1,14.78,100,1,ARL,304056997
2025-07-17T15:45:58.420278691Z,2025-07-17T15:45:58.420113307Z,10,2,1108,C,A,0,14.88,100,0,165384,255183203,13.26,100,1,13.89,15,1,13.04,2,1,13.90,100,1,13.03,100,1,14.07,2,1,12.73,100,1,14.18,100,1,12.71,100,1,14.28,100,1,12.50,700,1,14.40,100,1,12.46,200,2,14.56,800,2,12.43,700,1,14.60,700,1,12.42,700,1,14.68,1400,2,12.37,700,1,14.78,100,1,ARL,303682389
2025-07-17T15:45:58.420278691Z,2025-07-17T15:45:58.420113307Z,10,2,1108,A,A,0,14.77,100,130,165384,255183203,13.26,100,1,13.89,15,1,13.04,2,1,13.90,100,1,13.03,100,1,14.07,2,1,12.73,100,1,14.18,100,1,12.71,100,1,14.28,100,1,12.50,700,1,14.40,100,1,12.46,200,2,14.56,800,2,12.43,700,1,14.60,700,1,12.42,700,1,14.68,1400,2,12.37,700,1,14.77,100,1,ARL,304503585
2025-07-17T15:45:58.420755889Z,2025-07-17T15:45:58.420590199Z,10,2,1108,C,A,0,14.88,100,0,165690,255183204,13.26,100,1,13.89,15,1,13.04,2,1,13.90,100,1,13.03,100,1,14.07,2,1,12.73,100,1,14.18,100,1,12.71,100,1,14.28,100,1,12.50,700,1,14.40,100,1,12.46,200,2,14.56,800,2,12.43,700,1,14.60,700,1,12.42,700,1,14.68,1400,2,12.37,700,1,14.77,100,1,ARL,303682385
2025-07-17T15:45:58.420755889Z,2025-07-17T15:45:58.420590199Z,10,2,1108,A,A,0,14.77,100,130,165690,255183204,13.26,100,1,13.89,15,1,13.04,2,1,13.90,100,1,13.03,100,1,14.07,2,1,12.73,100,1,14.18,100,1,12.71,100,1,14.28,100,1,12.50,700,1,14.40,100,1,12.46,200,2,14.56,800,2,12.43,700,1,14.60,700,1,12.42,700,1,14.68,1400,2,12.37,700,1,14.77,200,2,ARL,304503593
2025-07-17T15:45:58.782892109Z,2025-07-17T15:45:58.782726994Z,10,2,1108,C,A,0,13.89,15,130,165115,255189425,13.26,100,1,13.90,100,1,13.04,2,1,14.07,2,1,13.03,100,1,14.18,100,1,12.73,100,1,14.28,100,1,12.71,100,1,14.40,100,1,12.50,700,1,14.56,800,2,12.46,200,2,14.60,700,1,12.43,700,1,14.68,1400,2,12.42,700,1,14.77,200,2,12.37,700,1,14.78,100,1,ARL,304238913
2025-07-17T15:46:16.783057616Z,2025-07-17T15:46:16.782892334Z,10,2,1108,A,A,0,13.88,15,130,165282,255552962,13.26,100,1,13.88,15,1,13.04,2,1,13.90,100,1,13.03,100,1,14.07,2,1,12.73,100,1,14.18,100,1,12.71,100,1,14.28,100,1,12.50,700,1,14.40,100,1,12.46,200,2,14.56,800,2,12.43,700,1,14.60,700,1,12.42,700,1,14.68,1400,2,12.37,700,1,14.77,200,2,ARL,304949689
2025-07-17T15:46:16.783326241Z,2025-07-17T15:46:16.783160795Z,10,2,1108,C,A,0,13.90,100,0,165446,255552970,13.26,100,1,13.88,15,1,13.04,2,1,14.07,2,1,13.03,100,1,14.18,100,1,12.73,100,1,14.28,100,1,12.71,100,1,14.40,100,1,12.50,700,1,14.56,800,2,12.46,200,2,14.60,700,1,12.43,700,1,14.68,1400,2,12.42,700,1,14.77,200,2,12.37,700,1,14.78,100,1,ARL,304252313
2025-07-17T15:46:16.783326241Z,2025-07-17T15:46:16.783160795Z,10,2,1108,A,A,0,13.89,100,130,165446,255552970,13.26,100,1,13.88,15,1,13.04,2,1,13.89,100,1,13.03,100,1,14.07,2,1,12.73,100,1,14.18,100,1,12.71,100,1,14.28,100,1,12.50,700,1,14.40,100,1,12.46,200,2,14.56,800,2,12.43,700,1,14.60,700,1,12.42,700,1,14.68,1400,2,12.37,700,1,14.77,200,2,ARL,304949697
2025-07-17T15:46:18.782897570Z,2025-07-17T15:46:18.782732218Z,10,2,1108,C,A,0,13.88,15,130,165352,255587336,13.26,100,1,13.89,100,1,13.04,2,1,14.07,2,1,13.03,100,1,14.18,100,1,12.73,100,1,14.28,100,1,12.71,100,1,14.40,100,1,12.50,700,1,14.56,800,2,12.46,200,2,14.60,700,1,12.43,700,1,14.68,1400,2,12.42,700,1,14.77,200,2,12.37,700,1,14.78,100,1,ARL,304949689
2025-07-17T15:46:28.474166897Z,2025-07-17T15:46:28.474001551Z,10,2,1108,C,A,0,13.89,100,130,165346,255746167,13.26,100,1,14.07,2,1,13.04,2,1,14.18,100,1,13.03,100,1,14.28,100,1,12.73,100,1,14.40,100,1,12.71,100,1,14.56,800,2,12.50,700,1,14.60,700,1,12.46,200,2,14.68,1400,2,12.43,700,1,14.77,200,2,12.42,700,1,14.78,100,1,12.37,700,1,14.96,200,2,ARL,304949697
2025-07-17T15:46:28.474726594Z,2025-07-17T15:46:28.474561156Z,10,2,1108,C,A,0,14.77,100,0,165438,255746173,13.26,100,1,14.07,2,1,13.04,2,1,14.18,100,1,13.03,100,1,14.28,100,1,12.73,100,1,14.40,100,1,12.71,100,1,14.56,800,2,12.50,700,1,14.60,700,1,12.46,200,2,14.68,1400,2,12.43,700,1,14.77,100,1,12.42,700,1,14.78,100,1,12.37,700,1,14.96,200,2,ARL,304503593
2025-07-17T15:46:28.474726594Z,2025-07-17T15:46:28.474561156Z,10,2,1108,A,A,0,14.88,100,130,165438,255746173,13.26,100,1,14.07,2,1,13.04,2,1,14.18,100,1,13.03,100,1,14.28,100,1,12.73,100,1,14.40,100,1,12.71,100,1,14.56,800,2,12.50,700,1,14.60,700,1,12.46,200,2,14.68,1400,2,12.43,700,1,14.77,100,1,12.42,700,1,14.78,100,1,12.37,700,1,14.88,100,1,ARL,305184937
2025-07-17T15:46:28.474896460Z,2025-07-17T15:46:28.474730225Z,10,2,1108,C,A,0,14.77,100,0,166235,255746176,13.26,100,1,14.07,2,1,13.04,2,1,14.18,100,1,13.03,100,1,14.28,100,1,12.73,100,1,14.40,100,1,12.71,100,1,14.56,800,2,12.50,700,1,14.60,700,1,12.46,200,2,14.68,1400,2,12.43,700,1,14.78,100,1,12.42,700,1,14.88,100,1,12.37,700,1,14.96,200,2,ARL,304503585
2025-07-17T15:46:28.474896460Z,2025-07-17T15:46:28.474730225Z,10,2,1108,A,A,0,14.88,100,130,166235,255746176,13.26,100,1,14.07,2,1,13.04,2,1,14.18,100,1,13.03,100,1,14.28,100,1,12.73,100,1,14.40,100,1,12.71,100,1,14.56,800,2,12.50,700,1,14.60,700,1,12.46,200,2,14.68,1400,2,12.43,700,1,14.78,100,1,12.42,700,1,14.88,200,2,12.37,700,1,14.96,200,2,ARL,305184953
2025-07-17T15:46:28.474902154Z,2025-07-17T15:46:28.474736101Z,10,2,1108,C,A,0,14.98,100,0,166053,255746178,13.26,100,1,14.07,2,1,13.04,2,1,14.18,100,1,13.03,100,1,14.28,100,1,12.73,100,1,14.40,100,1,12.71,100,1,14.56,800,2,12.50,700,1,14.60,700,1,12.46,200,2,14.68,1400,2,12.43,700,1,14.78,100,1,12.42,700,1,14.88,200,2,12.37,700,1,14.96,200,2,ARL,304252333
2025-07-17T15:46:28.474902154Z,2025-07-17T15:46:28.474736101Z,10,2,1108,A,A,0,15.03,100,128,166053,255746178,13.26,100,1,14.07,2,1,13.04,2,1,14.18,100,1,13.03,100,1,14.28,100,1,12.73,100,1,14.40,100,1,12.71,100,1,14.56,800,2,12.50,700,1,14.60,700,1,12.46,200,2,14.68,1400,2,12.43,700,1,14.78,100,1,12.42,700,1,14.88,200,2,12.37,700,1,14.96,200,2,ARL,305184957
2025-07-17T15:46:28.492881980Z,2025-07-17T15:46:28.492716775Z,10,2,1108,C,A,0,14.18,100,130,165205,255746619,13.26,100,1,14.07,2,1,13.04,2,1,14.28,100,1,13.03,100,1,14.40,100,1,12.73,100,1,14.56,800,2,12.71,100,1,14.60,700,1,12.50,700,1,14.68,1400,2,12.46,200,2,14.78,100,1,12.43,700,1,14.88,200,2,12.42,700,1,14.96,200,2,12.37,700,1,15.03,100,1,ARL,304252469
2025-07-17T15:46:28.492931279Z,2025-07-17T15:46:28.492765859Z,10,2,1108,A,A,0,14.26,100,130,165420,255746621,13.26,100,1,14.07,2,1,13.04,2,1,14.26,100,1,13.03,100,1,14.28,100,1,12.73,100,1,14.40,100,1,12.71,100,1,14.56,800,2,12.50,700,1,14.60,700,1,12.46,200,2,14.68,1400,2,12.43,700,1,14.78,100,1,12.42,700,1,14.88,200,2,12.37,700,1,14.96,200,2,ARL,305185529
2025-07-17T15:46:28.646273467Z,2025-07-17T15:46:28.646108242Z,10,2,1108,A,A,0,14.08,100,130,165225,255748568,13.26,100,1,14.07,2,1,13.04,2,1,14.08,100,1,13.03,100,1,14.26,100,1,12.73,100,1,14.28,100,1,12.71,100,1,14.40,100,1,12.50,700,1,14.56,800,2,12.46,200,2,14.60,700,1,12.43,700,1,14.68,1400,2,12.42,700,1,14.78,100,1,12.37,700,1,14.88,200,2,ARL,305187077
2025-07-17T15:46:57.524024658Z,2025-07-17T15:46:57.523859388Z,10,2,1108,A,A,0,13.92,15,130,165270,256268482,13.26,100,1,13.92,15,1,13.04,2,1,14.07,2,1,13.03,100,1,14.08,100,1,12.73,100,1,14.26,100,1,12.71,100,1,14.28,100,1,12.50,700,1,14.40,100,1,12.46,200,2,14.56,800,2,12.43,700,1,14.60,700,1,12.42,700,1,14.68,1400,2,12.37,700,1,14.78,100,1,ARL,305862145
2025-07-17T15:46:57.932842994Z,2025-07-17T15:46:57.932677299Z,10,2,1108,C,A,0,14.08,100,0,165695,256280751,13.26,100,1,13.92,15,1,13.04,2,1,14.07,2,1,13.03,100,1,14.26,100,1,12.73,100,1,14.28,100,1,12.71,100,1,14.40,100,1,12.50,700,1,14.56,800,2,12.46,200,2,14.60,700,1,12.43,700,1,14.68,1400,2,12.42,700,1,14.78,100,1,12.37,700,1,14.88,200,2,ARL,305187077
2025-07-17T15:46:57.932842994Z,2025-07-17T15:46:57.932677299Z,10,2,1108,A,A,0,13.93,100,130,165695,256280751,13.26,100,1,13.92,15,1,13.04,2,1,13.93,100,1,13.03,100,1,14.07,2,1,12.73,100,1,14.26,100,1,12.71,100,1,14.28,100,1,12.50,700,1,14.40,100,1,12.46,200,2,14.56,800,2,12.43,700,1,14.60,700,1,12.42,700,1,14.68,1400,2,12.37,700,1,14.78,100,1,ARL,305878881
2025-07-17T15:47:06.609456251Z,2025-07-17T15:47:06.609290857Z,10,2,1108,A,A,0,13.88,15,130,165394,256488374,13.26,100,1,13.88,15,1,13.04,2,1,13.92,15,1,13.03,100,1,13.93,100,1,12.73,100,1,14.07,2,1,12.71,100,1,14.26,100,1,12.50,700,1,14.28,100,1,12.46,200,2,14.40,100,1,12.43,700,1,14.56,800,2,12.42,700,1,14.60,700,1,12.37,700,1,14.68,1400,2,ARL,306121113
2025-07-17T15:47:08.787695144Z,2025-07-17T15:47:08.787529505Z,10,2,1108,C,A,0,13.93,100,0,165639,256532991,13.26,100,1,13.88,15,1,13.04,2,1,13.92,15,1,13.03,100,1,14.07,2,1,12.73,100,1,14.26,100,1,12.71,100,1,14.28,100,1,12.50,700,1,14.40,100,1,12.46,200,2,14.56,800,2,12.43,700,1,14.60,700,1,12.42,700,1,14.68,1400,2,12.37,700,1,14.78,100,1,ARL,305878881
2025-07-17T15:47:08.787695144Z,2025-07-17T15:47:08.787529505Z,10,2,1108,A,A,0,13.89,100,130,165639,256532991,13.26,100,1,13.88,15,1,13.04,2,1,13.89,100,1,13.03,100,1,13.92,15,1,12.73,100,1,14.07,2,1,12.71,100,1,14.26,100,1,12.50,700,1,14.28,100,1,12.46,200,2,14.40,100,1,12.43,700,1,14.56,800,2,12.42,700,1,14.60,700,1,12.37,700,1,14.68,1400,2,ARL,306170837
2025-07-17T15:47:08.788440762Z,2025-07-17T15:47:08.788275184Z,10,2,1108,C,A,0,15.03,100,0,165578,256533005,13.26,100,1,13.88,15,1,13.04,2,1,13.89,100,1,13.03,100,1,13.92,15,1,12.73,100,1,14.07,2,1,12.71,100,1,14.26,100,1,12.50,700,1,14.28,100,1,12.46,200,2,14.40,100,1,12.43,700,1,14.56,800,2,12.42,700,1,14.60,700,1,12.37,700,1,14.68,1400,2,ARL,305184957
2025-07-17T15:47:08.788440762Z,2025-07-17T15:47:08.788275184Z,10,2,1108,A,A,0,14.97,100,130,165578,256533005,13.26,100,1,13.88,15,1,13.04,2,1,13.89,100,1,13.03,100,1,13.92,15,1,12.73,100,1,14.07,2,1,12.71,100,1,14.26,100,1,12.50,700,1,14.28,100,1,12.46,200,2,14.40,100,1,12.43,700,1,14.56,800,2,12.42,700,1,14.60,700,1,12.37,700,1,14.68,1400,2,ARL,306170869
2025-07-17T15:47:08.805983406Z,2025-07-17T15:47:08.805818249Z,10,2,1108,C,A,0,14.26,100,130,165157,256533442,13.26,100,1,13.88,15,1,13.04,2,1,13.89,100,1,13.03,100,1,13.92,15,1,12.73,100,1,14.07,2,1,12.71,100,1,14.28,100,1,12.50,700,1,14.40,100,1,12.46,200,2,14.56,800,2,12.43,700,1,14.60,700,1,12.42,700,1,14.68,1400,2,12.37,700,1,14.78,100,1,ARL,305185529
2025-07-17T15:47:08.806033773Z,2025-07-17T15:47:08.805868059Z,10,2,1108,A,A,0,14.17,100,130,165714,256533443,13.26,100,1,13.88,15,1,13.04,2,1,13.89,100,1,13.03,100,1,13.92,15,1,12.73,100,1,14.07,2,1,12.71,100,1,14.17,100,1,12.50,700,1,14.28,100,1,12.46,200,2,14.40,100,1,12.43,700,1,14.56,800,2,12.42,700,1,14.60,700,1,12.37,700,1,14.68,1400,2,ARL,306171457
2025-07-17T15:47:13.121454355Z,2025-07-17T15:47:13.121288953Z,10,2,1108,C,A,0,13.88,15,130,165402,256612694,13.26,100,1,13.89,100,1,13.04,2,1,13.92,15,1,13.03,100,1,14.07,2,1,12.73,100,1,14.17,100,1,12.71,100,1,14.28,100,1,12.50,700,1,14.40,100,1,12.46,200,2,14.56,800,2,12.43,700,1,14.60,700,1,12.42,700,1,14.68,1400,2,12.37,700,1,14.78,100,1,ARL,306121113
2025-07-17T15:47:13.122562533Z,2025-07-17T15:47:13.122396816Z,10,2,1108,C,A,0,13.92,15,130,165717,256612757,13.26,100,1,13.89,100,1,13.04,2,1,14.07,2,1,13.03,100,1,14.17,100,1,12.73,100,1,14.28,100,1,12.71,100,1,14.40,100,1,12.50,700,1,14.56,800,2,12.46,200,2,14.60,700,1,12.43,700,1,14.68,1400,2,12.42,700,1,14.78,100,1,12.37,700,1,14.88,200,2,ARL,305862145
2025-07-17T15:47:24.786476266Z,2025-07-17T15:47:24.786310694Z,10,2,1108,A,A,0,13.87,15,130,165572,256812416,13.26,100,1,13.87,15,1,13.04,2,1,13.89,100,1,13.03,100,1,14.07,2,1,12.73,100,1,14.17,100,1,12.71,100,1,14.28,100,1,12.50,700,1,14.40,100,1,12.46,200,2,14.56,800,2,12.43,700,1,14.60,700,1,12.42,700,1,14.68,1400,2,12.37,700,1,14.78,100,1,ARL,306519385
2025-07-17T15:47:24.786745657Z,2025-07-17T15:47:24.786580061Z,10,2,1108,C,A,0,13.89,100,0,165596,256812420,13.26,100,1,13.87,15,1,13.04,2,1,14.07,2,1,13.03,100,1,14.17,100,1,12.73,100,1,14.28,100,1,12.71,100,1,14.40,100,1,12.50,700,1,14.56,800,2,12.46,200,2,14.60,700,1,12.43,700,1,14.68,1400,2,12.42,700,1,14.78,100,1,12.37,700,1,14.88,200,2,ARL,306170837
2025-07-17T15:47:24.786745657Z,2025-07-17T15:47:24.786580061Z,10,2,1108,A,A,0,13.88,100,130,165596,256812420,13.26,100,1,13.87,15,1,13.04,2,1,13.88,100,1,13.03,100,1,14.07,2,1,12.73,100,1,14.17,100,1,12.71,100,1,14.28,100,1,12.50,700,1,14.40,100,1,12.46,200,2,14.56,800,2,12.43,700,1,14.60,700,1,12.42,700,1,14.68,1400,2,12.37,700,1,14.78,100,1,ARL,306519397
2025-07-17T15:47:24.786925729Z,2025-07-17T15:47:24.786759805Z,10,2,1108,C,A,0,14.88,100,0,165924,256812422,13.26,100,1,13.87,15,1,13.04,2,1,13.88,100,1,13.03,100,1,14.07,2,1,12.73,100,1,14.17,100,1,12.71,100,1,14.28,100,1,12.50,700,1,14.40,100,1,12.46,200,2,14.56,800,2,12.43,700,1,14.60,700,1,12.42,700,1,14.68,1400,2,12.37,700,1,14.78,100,1,ARL,305184937
2025-07-17T15:47:24.786925729Z,2025-07-17T15:47:24.786759805Z,10,2,1108,A,A,0,14.77,100,130,165924,256812422,13.26,100,1,13.87,15,1,13.04,2,1,13.88,100,1,13.03,100,1,14.07,2,1,12.73,100,1,14.17,100,1,12.71,100,1,14.28,100,1,12.50,700,1,14.40,100,1,12.46,200,2,14.56,800,2,12.43,700,1,14.60,700,1,12.42,700,1,14.68,1400,2,12.37,700,1,14.77,100,1,ARL,306519409
2025-07-17T15:47:24.800616004Z,2025-07-17T15:47:24.800449950Z,10,2,1108,C,A,0,14.88,100,0,166054,256812578,13.26,100,1,13.87,15,1,13.04,2,1,13.88,100,1,13.03,100,1,14.07,2,1,12.73,100,1,14.17,100,1,12.71,100,1,14.28,100,1,12.50,700,1,14.40,100,1,12.46,200,2,14.56,800,2,12.43,700,1,14.60,700,1,12.42,700,1,14.68,1400,2,12.37,700,1,14.77,100,1,ARL,305184953
2025-07-17T15:47:24.800616004Z,2025-07-17T15:47:24.800449950Z,10,2,1108,A,A,0,14.75,100,130,166054,256812578,13.26,100,1,13.87,15,1,13.04,2,1,13.88,100,1,13.03,100,1,14.07,2,1,12.73,100,1,14.17,100,1,12.71,100,1,14.28,100,1,12.50,700,1,14.40,100,1,12.46,200,2,14.56,800,2,12.43,700,1,14.60,700,1,12.42,700,1,14.68,1400,2,12.37,700,1,14.75,100,1,ARL,306519741
2025-07-17T15:47:27.860272892Z,2025-07-17T15:47:27.860107552Z,10,2,1108,A,A,0,13.83,15,130,165340,256866835,13.26,100,1,13.83,15,1,13.04,2,1,13.87,15,1,13.03,100,1,13.88,100,1,12.73,100,1,14.07,2,1,12.71,100,1,14.17,100,1,12.50,700,1,14.28,100,1,12.46,200,2,14.40,100,1,12.43,700,1,14.56,800,2,12.42,700,1,14.60,700,1,12.37,700,1,14.68,1400,2,ARL,306587393
2025-07-17T15:47:31.407029312Z,2025-07-17T15:47:31.406863918Z,10,2,1108,C,A,0,13.88,100,0,165394,256910124,13.26,100,1,13.83,15,1,13.04,2,1,13.87,15,1,13.03,100,1,14.07,2,1,12.73,100,1,14.17,100,1,12.71,100,1,14.28,100,1,12.50,700,1,14.40,100,1,12.46,200,2,14.56,800,2,12.43,700,1,14.60,700,1,12.42,700,1,14.68,1400,2,12.37,700,1,14.75,100,1,ARL,306519397
2025-07-17T15:47:31.407029312Z,2025-07-17T15:47:31.406863918Z,10,2,1108,A,A,0,13.84,100,130,165394,256910124,13.26,100,1,13.83,15,1,13.04,2,1,13.84,100,1,13.03,100,1,13.87,15,1,12.73,100,1,14.07,2,1,12.71,100,1,14.17,100,1,12.50,700,1,14.28,100,1,12.46,200,2,14.40,100,1,12.43,700,1,14.56,800,2,12.42,700,1,14.60,700,1,12.37,700,1,14.68,1400,2,ARL,306647425
2025-07-17T15:47:31.407771110Z,2025-07-17T15:47:31.407605685Z,10,2,1108,C,A,0,14.97,100,0,165425,256910129,13.26,100,1,13.83,15,1,13.04,2,1,13.84,100,1,13.03,100,1,13.87,15,1,12.73,100,1,14.07,2,1,12.71,100,1,14.17,100,1,12.50,700,1,14.28,100,1,12.46,200,2,14.40,100,1,12.43,700,1,14.56,800,2,12.42,700,1,14.60,700,1,12.37,700,1,14.68,1400,2,ARL,306170869
2025-07-17T15:47:31.407771110Z,2025-07-17T15:47:31.407605685Z,10,2,1108,A,A,0,14.91,100,130,165425,256910129,13.26,100,1,13.83,15,1,13.04,2,1,13.84,100,1,13.03,100,1,13.87,15,1,12.73,100,1,14.07,2,1,12.71,100,1,14.17,100,1,12.50,700,1,14.28,100,1,12.46,200,2,14.40,100,1,12.43,700,1,14.56,800,2,12.42,700,1,14.60,700,1,12.37,700,1,14.68,1400,2,ARL,306647445
2025-07-17T15:47:31.413491477Z,2025-07-17T15:47:31.413325908Z,10,2,1108,C,A,0,14.78,100,0,165569,256910184,13.26,100,1,13.83,15,1,13.04,2,1,13.84,100,1,13.03,100,1,13.87,15,1,12.73,100,1,14.07,2,1,12.71,100,1,14.17,100,1,12.50,700,1,14.28,100,1,12.46,200,2,14.40,100,1,12.43,700,1,14.56,800,2,12.42,700,1,14.60,700,1,12.37,700,1,14.68,1400,2,ARL,303331425
2025-07-17T15:47:31.413491477Z,2025-07-17T15:47:31.413325908Z,10,2,1108,A,A,0,14.64,100,130,165569,256910184,13.26,100,1,13.83,15,1,13.04,2,1,13.84,100,1,13.03,100,1,13.87,15,1,12.73,100,1,14.07,2,1,12.71,100,1,14.17,100,1,12.50,700,1,14.28,100,1,12.46,200,2,14.40,100,1,12.43,700,1,14.56,800,2,12.42,700,1,14.60,700,1,12.37,700,1,14.64,100,1,ARL,306647521
2025-07-17T15:47:31.433486283Z,2025-07-17T15:47:31.433320466Z,10,2,1108,C,A,0,14.96,100,0,165817,256910721,13.26,100,1,13.83,15,1,13.04,2,1,13.84,100,1,13.03,100,1,13.87,15,1,12.73,100,1,14.07,2,1,12.71,100,1,14.17,100,1,12.50,700,1,14.28,100,1,12.46,200,2,14.40,100,1,12.43,700,1,14.56,800,2,12.42,700,1,14.60,700,1,12.37,700,1,14.64,100,1,ARL,303330509
2025-07-17T15:47:31.433486283Z,2025-07-17T15:47:31.433320466Z,10,2,1108,A,A,0,14.81,100,130,165817,256910721,13.26,100,1,13.83,15,1,13.04,2,1,13.84,100,1,13.03,100,1,13.87,15,1,12.73,100,1,14.07,2,1,12.71,100,1,14.17,100,1,12.50,700,1,14.28,100,1,12.46,200,2,14.40,100,1,12.43,700,1,14.56,800,2,12.42,700,1,14.60,700,1,12.37,700,1,14.64,100,1,ARL,306649913
2025-07-17T15:47:31.574128504Z,2025-07-17T15:47:31.573963059Z,10,2,1108,C,A,0,16.08,100,0,165445,256912087,13.26,100,1,13.83,15,1,13.04,2,1,13.84,100,1,13.03,100,1,13.87,15,1,12.73,100,1,14.07,2,1,12.71,100,1,14.17,100,1,12.50,700,1,14.28,100,1,12.46,200,2,14.40,100,1,12.43,700,1,14.56,800,2,12.42,700,1,14.60,700,1,12.37,700,1,14.64,100,1,ARL,303331429
2025-07-17T15:47:31.574128504Z,2025-07-17T15:47:31.573963059Z,10,2,1108,A,A,0,15.92,100,130,165445,256912087,13.26,100,1,13.83,15,1,13.04,2,1,13.84,100,1,13.03,100,1,13.87,15,1,12.73,100,1,14.07,2,1,12.71,100,1,14.17,100,1,12.50,700,1,14.28,100,1,12.46,200,2,14.40,100,1,12.43,700,1,14.56,800,2,12.42,700,1,14.60,700,1,12.37,700,1,14.64,100,1,ARL,306652001
2025-07-17T15:47:31.575374481Z,2025-07-17T15:47:31.575209032Z,10,2,1108,C,A,0,17.76,100,0,165449,256912094,13.26,100,1,13.83,15,1,13.04,2,1,13.84,100,1,13.03,100,1,13.87,15,1,12.73,100,1,14.07,2,1,12.71,100,1,14.17,100,1,12.50,700,1,14.28,100,1,12.46,200,2,14.40,100,1,12.43,700,1,14.56,800,2,12.42,700,1,14.60,700,1,12.37,700,1,14.64,100,1,ARL,303331309
2025-07-17T15:47:31.575374481Z,2025-07-17T15:47:31.575209032Z,10,2,1108,A,A,0,17.58,100,130,165449,256912094,13.26,100,1,13.83,15,1,13.04,2,1,13.84,100,1,13.03,100,1,13.87,15,1,12.73,100,1,14.07,2,1,12.71,100,1,14.17,100,1,12.50,700,1,14.28,100,1,12.46,200,2,14.40,100,1,12.43,700,1,14.56,800,2,12.42,700,1,14.60,700,1,12.37,700,1,14.64,100,1,ARL,306652017
2025-07-17T15:47:31.740095714Z,2025-07-17T15:47:31.739930142Z,10,2,1108,C,A,0,14.96,100,0,165572,256914067,13.26,100,1,13.83,15,1,13.04,2,1,13.84,100,1,13.03,100,1,13.87,15,1,12.73,100,1,14.07,2,1,12.71,100,1,14.17,100,1,12.50,700,1,14.28,100,1,12.46,200,2,14.40,100,1,12.43,700,1,14.56,800,2,12.42,700,1,14.60,700,1,12.37,700,1,14.64,100,1,ARL,303334253
2025-07-17T15:47:31.740095714Z,2025-07-17T15:47:31.739930142Z,10,2,1108,A,A,0,14.81,100,130,165572,256914067,13.26,100,1,13.83,15,1,13.04,2,1,13.84,100,1,13.03,100,1,13.87,15,1,12.73,100,1,14.07,2,1,12.71,100,1,14.17,100,1,12.50,700,1,14.28,100,1,12.46,200,2,14.40,100,1,12.43,700,1,14.56,800,2,12.42,700,1,14.60,700,1,12.37,700,1,14.64,100,1,ARL,306653713
2025-07-17T15:47:37.159589804Z,2025-07-17T15:47:37.159424166Z,10,2,1108,C,A,0,13.87,15,130,165638,256983942,13.26,100,1,13.83,15,1,13.04,2,1,13.84,100,1,13.03,100,1,14.07,2,1,12.73,100,1,14.17,100,1,12.71,100,1,14.28,100,1,12.50,700,1,14.40,100,1,12.46,200,2,14.56,800,2,12.43,700,1,14.60,700,1,12.42,700,1,14.64,100,1,12.37,700,1,14.68,1400,2,ARL,306519385
2025-07-17T15:47:37.172000440Z,2025-07-17T15:47:37.171834941Z,10,2,1108,A,A,0,13.85,100,130,165499,256984053,13.26,100,1,13.83,15,1,13.04,2,1,13.84,100,1,13.03,100,1,13.85,100,1,12.73,100,1,14.07,2,1,12.71,100,1,14.17,100,1,12.50,700,1,14.28,100,1,12.46,200,2,14.40,100,1,12.43,700,1,14.56,800,2,12.42,700,1,14.60,700,1,12.37,700,1,14.64,100,1,ARL,306749753
2025-07-17T15:47:38.161181283Z,2025-07-17T15:47:38.161015969Z,10,2,1108,A,A,0,13.79,15,130,165314,256998606,13.26,100,1,13.79,15,1,13.04,2,1,13.83,15,1,13.03,100,1,13.84,100,1,12.73,100,1,13.85,100,1,12.71,100,1,14.07,2,1,12.50,700,1,14.17,100,1,12.46,200,2,14.28,100,1,12.43,700,1,14.40,100,1,12.42,700,1,14.56,800,2,12.37,700,1,14.60,700,1,ARL,306770041
2025-07-17T15:47:38.794962245Z,2025-07-17T15:47:38.794795887Z,10,2,1108,C,A,0,13.84,100,0,166358,257010989,13.26,100,1,13.79,15,1,13.04,2,1,13.83,15,1,13.03,100,1,13.85,100,1,12.73,100,1,14.07,2,1,12.71,100,1,14.17,100,1,12.50,700,1,14.28,100,1,12.46,200,2,14.40,100,1,12.43,700,1,14.56,800,2,12.42,700,1,14.60,700,1,12.37,700,1,14.64,100,1,ARL,306647425
2025-07-17T15:47:38.794962245Z,2025-07-17T15:47:38.794795887Z,10,2,1108,A,A,0,13.80,100,128,166358,257010989,13.26,100,1,13.79,15,1,13.04,2,1,13.80,100,1,13.03,100,1,13.83,15,1,12.73,100,1,13.85,100,1,12.71,100,1,14.07,2,1,12.50,700,1,14.17,100,1,12.46,200,2,14.28,100,1,12.43,700,1,14.40,100,1,12.42,700,1,14.56,800,2,12.37,700,1,14.60,700,1,ARL,306784133
2025-07-17T15:47:38.795723570Z,2025-07-17T15:47:38.795557785Z,10,2,1108,C,A,0,14.91,100,0,165785,257011058,13.26,100,1,13.79,15,1,13.04,2,1,13.80,100,1,13.03,100,1,13.83,15,1,12.73,100,1,13.85,100,1,12.71,100,1,14.07,2,1,12.50,700,1,14.17,100,1,12.46,200,2,14.28,100,1,12.43,700,1,14.40,100,1,12.42,700,1,14.56,800,2,12.37,700,1,14.60,700,1,ARL,306647445
2025-07-17T15:47:38.795723570Z,2025-07-17T15:47:38.795557785Z,10,2,1108,A,A,0,14.87,100,130,165785,257011058,13.26,100,1,13.79,15,1,13.04,2,1,13.80,100,1,13.03,100,1,13.83,15,1,12.73,100,1,13.85,100,1,12.71,100,1,14.07,2,1,12.50,700,1,14.17,100,1,12.46,200,2,14.28,100,1,12.43,700,1,14.40,100,1,12.42,700,1,14.56,800,2,12.37,700,1,14.60,700,1,ARL,306784201
2025-07-17T15:47:38.804624258Z,2025-07-17T15:47:38.804458744Z,10,2,1108,C,A,0,14.17,100,130,165514,257011716,13.26,100,1,13.79,15,1,13.04,2,1,13.80,100,1,13.03,100,1,13.83,15,1,12.73,100,1,13.85,100,1,12.71,100,1,14.07,2,1,12.50,700,1,14.28,100,1,12.46,200,2,14.40,100,1,12.43,700,1,14.56,800,2,12.42,700,1,14.60,700,1,12.37,700,1,14.64,100,1,ARL,306171457
2025-07-17T15:47:38.804679592Z,2025-07-17T15:47:38.804513793Z,10,2,1108,A,A,0,14.08,100,130,165799,257011717,13.26,100,1,13.79,15,1,13.04,2,1,13.80,100,1,13.03,100,1,13.83,15,1,12.73,100,1,13.85,100,1,12.71,100,1,14.07,2,1,12.50,700,1,14.08,100,1,12.46,200,2,14.28,100,1,12.43,700,1,14.40,100,1,12.42,700,1,14.56,800,2,12.37,700,1,14.60,700,1,ARL,306784853
2025-07-17T15:47:39.092472059Z,2025-07-17T15:47:39.092305947Z,10,2,1108,C,A,0,13.79,15,130,166112,257018687,13.26,100,1,13.80,100,1,13.04,2,1,13.83,15,1,13.03,100,1,13.85,100,1,12.73,100,1,14.07,2,1,12.71,100,1,14.08,100,1,12.50,700,1,14.28,100,1,12.46,200,2,14.40,100,1,12.43,700,1,14.56,800,2,12.42,700,1,14.60,700,1,12.37,700,1,14.64,100,1,ARL,306770041
2025-07-17T15:47:39.095920859Z,2025-07-17T15:47:39.095755335Z,10,2,1108,C,A,0,13.83,15,130,165524,257018796,13.26,100,1,13.80,100,1,13.04,2,1,13.85,100,1,13.03,100,1,14.07,2,1,12.73,100,1,14.08,100,1,12.71,100,1,14.28,100,1,12.50,700,1,14.40,100,1,12.46,200,2,14.56,800,2,12.43,700,1,14.60,700,1,12.42,700,1,14.64,100,1,12.37,700,1,14.68,1400,2,ARL,306587393
2025-07-17T15:48:08.909366905Z,2025-07-17T15:48:08.909201576Z,10,2,1108,A,A,0,13.83,100,130,165329,257603755,13.26,100,1,13.80,100,1,13.04,2,1,13.83,100,1,13.03,100,1,13.85,100,1,12.73,100,1,14.07,2,1,12.71,100,1,14.08,100,1,12.50,700,1,14.28,100,1,12.46,200,2,14.40,100,1,12.43,700,1,14.56,800,2,12.42,700,1,14.60,700,1,12.37,700,1,14.64,100,1,ARL,307567929
2025-07-17T15:48:08.916721098Z,2025-07-17T15:48:08.916555821Z,10,2,1108,C,A,0,13.85,100,130,165277,257604057,13.26,100,1,13.80,100,1,13.04,2,1,13.83,100,1,13.03,100,1,14.07,2,1,12.73,100,1,14.08,100,1,12.71,100,1,14.28,100,1,12.50,700,1,14.40,100,1,12.46,200,2,14.56,800,2,12.43,700,1,14.60,700,1,12.42,700,1,14.64,100,1,12.37,700,1,14.68,1400,2,ARL,306749753
2025-07-17T15:48:09.653473465Z,2025-07-17T15:48:09.653308042Z,10,2,1108,A,A,0,13.78,15,130,165423,257621095,13.26,100,1,13.78,15,1,13.04,2,1,13.80,100,1,13.03,100,1,13.83,100,1,12.73,100,1,14.07,2,1,12.71,100,1,14.08,100,1,12.50,700,1,14.28,100,1,12.46,200,2,14.40,100,1,12.43,700,1,14.56,800,2,12.42,700,1,14.60,700,1,12.37,700,1,14.64,100,1,ARL,307587873
2025-07-17T15:48:11.166689254Z,2025-07-17T15:48:11.166517494Z,10,2,1108,C,A,0,13.78,15,128,171760,257644020,13.26,100,1,13.80,100,1,13.04,2,1,13.83,100,1,13.03,100,1,14.07,2,1,12.73,100,1,14.08,100,1,12.71,100,1,14.28,100,1,12.50,700,1,14.40,100,1,12.46,200,2,14.56,800,2,12.43,700,1,14.60,700,1,12.42,700,1,14.64,100,1,12.37,700,1,14.68,1400,2,ARL,307587873
2025-07-17T15:48:13.509078553Z,2025-07-17T15:48:13.508913083Z,10,2,1108,A,A,0,13.78,15,130,165470,257727039,13.26,100,1,13.78,15,1,13.04,2,1,13.80,100,1,13.03,100,1,13.83,100,1,12.73,100,1,14.07,2,1,12.71,100,1,14.08,100,1,12.50,700,1,14.28,100,1,12.46,200,2,14.40,100,1,12.43,700,1,14.56,800,2,12.42,700,1,14.60,700,1,12.37,700,1,14.64,100,1,ARL,307714769
2025-07-17T15:48:13.525953545Z,2025-07-17T15:48:13.525788139Z,10,2,1108,A,A,0,13.81,100,130,165406,257727301,13.26,100,1,13.78,15,1,13.04,2,1,13.80,100,1,13.03,100,1,13.81,100,1,12.73,100,1,13.83,100,1,12.71,100,1,14.07,2,1,12.50,700,1,14.08,100,1,12.46,200,2,14.28,100,1,12.43,700,1,14.40,100,1,12.42,700,1,14.56,800,2,12.37,700,1,14.60,700,1,ARL,307715101
2025-07-17T15:48:13.532608874Z,2025-07-17T15:48:13.532443045Z,10,2,1108,C,A,0,13.83,100,130,165829,257727457,13.26,100,1,13.78,15,1,13.04,2,1,13.80,100,1,13.03,100,1,13.81,100,1,12.73,100,1,14.07,2,1,12.71,100,1,14.08,100,1,12.50,700,1,14.28,100,1,12.46,200,2,14.40,100,1,12.43,700,1,14.56,800,2,12.42,700,1,14.60,700,1,12.37,700,1,14.64,100,1,ARL,307567929
2025-07-17T15:48:15.568544154Z,2025-07-17T15:48:15.568378275Z,10,2,1108,C,A,0,13.80,100,0,165879,257757458,13.26,100,1,13.78,15,1,13.04,2,1,13.81,100,1,13.03,100,1,14.07,2,1,12.73,100,1,14.08,100,1,12.71,100,1,14.28,100,1,12.50,700,1,14.40,100,1,12.46,200,2,14.56,800,2,12.43,700,1,14.60,700,1,12.42,700,1,14.64,100,1,12.37,700,1,14.68,1400,2,ARL,306784133
2025-07-17T15:48:15.568544154Z,2025-07-17T15:48:15.568378275Z,10,2,1108,A,A,0,13.79,100,130,165879,257757458,13.26,100,1,13.78,15,1,13.04,2,1,13.79,100,1,13.03,100,1,13.81,100,1,12.73,100,1,14.07,2,1,12.71,100,1,14.08,100,1,12.50,700,1,14.28,100,1,12.46,200,2,14.40,100,1,12.43,700,1,14.56,800,2,12.42,700,1,14.60,700,1,12.37,700,1,14.64,100,1,ARL,307753241
2025-07-17T15:48:24.009355346Z,2025-07-17T15:48:24.009190157Z,10,2,1108,A,A,0,13.75,15,130,165189,257928318,13.26,100,1,13.75,15,1,13.04,2,1,13.78,15,1,13.03,100,1,13.79,100,1,12.73,100,1,13.81,100,1,12.71,100,1,14.07,2,1,12.50,700,1,14.08,100,1,12.46,200,2,14.28,100,1,12.43,700,1,14.40,100,1,12.42,700,1,14.56,800,2,12.37,700,1,14.60,700,1,ARL,307964605
2025-07-17T15:48:24.009522633Z,2025-07-17T15:48:24.009357442Z,10,2,1108,A,A,0,13.79,100,130,165191,257928319,13.26,100,1,13.75,15,1,13.04,2,1,13.78,15,1,13.03,100,1,13.79,200,2,12.73,100,1,13.81,100,1,12.71,100,1,14.07,2,1,12.50,700,1,14.08,100,1,12.46,200,2,14.28,100,1,12.43,700,1,14.40,100,1,12.42,700,1,14.56,800,2,12.37,700,1,14.60,700,1,ARL,307964609
2025-07-17T15:48:24.009944381Z,2025-07-17T15:48:24.009778967Z,10,2,1108,C,A,0,13.79,100,0,165414,257928325,13.26,100,1,13.75,15,1,13.04,2,1,13.78,15,1,13.03,100,1,13.79,100,1,12.73,100,1,13.81,100,1,12.71,100,1,14.07,2,1,12.50,700,1,14.08,100,1,12.46,200,2,14.28,100,1,12.43,700,1,14.40,100,1,12.42,700,1,14.56,800,2,12.37,700,1,14.60,700,1,ARL,307753241
2025-07-17T15:48:24.009944381Z,2025-07-17T15:48:24.009778967Z,10,2,1108,A,A,0,13.76,100,130,165414,257928325,13.26,100,1,13.75,15,1,13.04,2,1,13.76,100,1,13.03,100,1,13.78,15,1,12.73,100,1,13.79,100,1,12.71,100,1,13.81,100,1,12.50,700,1,14.07,2,1,12.46,200,2,14.08,100,1,12.43,700,1,14.28,100,1,12.42,700,1,14.40,100,1,12.37,700,1,14.56,800,2,ARL,307964621
2025-07-17T15:48:24.009974166Z,2025-07-17T15:48:24.009808793Z,10,2,1108,C,A,0,13.81,100,130,165373,257928326,13.26,100,1,13.75,15,1,13.04,2,1,13.76,100,1,13.03,100,1,13.78,15,1,12.73,100,1,13.79,100,1,12.71,100,1,14.07,2,1,12.50,700,1,14.08,100,1,12.46,200,2,14.28,100,1,12.43,700,1,14.40,100,1,12.42,700,1,14.56,800,2,12.37,700,1,14.60,700,1,ARL,307715101
2025-07-17T15:48:24.010555416Z,2025-07-17T15:48:24.010390029Z,10,2,1108,C,A,0,14.77,100,0,165387,257928333,13.26,100,1,13.75,15,1,13.04,2,1,13.76,100,1,13.03,100,1,13.78,15,1,12.73,100,1,13.79,100,1,12.71,100,1,14.07,2,1,12.50,700,1,14.08,100,1,12.46,200,2,14.28,100,1,12.43,700,1,14.40,100,1,12.42,700,1,14.56,800,2,12.37,700,1,14.60,700,1,ARL,306519409
2025-07-17T15:48:24.010555416Z,2025-07-17T15:48:24.010390029Z,10,2,1108,A,A,0,14.65,100,130,165387,257928333,13.26,100,1,13.75,15,1,13.04,2,1,13.76,100,1,13.03,100,1,13.78,15,1,12.73,100,1,13.79,100,1,12.71,100,1,14.07,2,1,12.50,700,1,14.08,100,1,12.46,200,2,14.28,100,1,12.43,700,1,14.40,100,1,12.42,700,1,14.56,800,2,12.37,700,1,14.60,700,1,ARL,307964661
2025-07-17T15:48:24.010677522Z,2025-07-17T15:48:24.010512050Z,10,2,1108,C,A,0,14.87,100,0,165472,257928340,13.26,100,1,13.75,15,1,13.04,2,1,13.76,100,1,13.03,100,1,13.78,15,1,12.73,100,1,13.79,100,1,12.71,100,1,14.07,2,1,12.50,700,1,14.08,100,1,12.46,200,2,14.28,100,1,12.43,700,1,14.40,100,1,12.42,700,1,14.56,800,2,12.37,700,1,14.60,700,1,ARL,306784201
2025-07-17T15:48:24.010677522Z,2025-07-17T15:48:24.010512050Z,10,2,1108,A,A,0,14.83,100,130,165472,257928340,13.26,100,1,13.75,15,1,13.04,2,1,13.76,100,1,13.03,100,1,13.78,15,1,12.73,100,1,13.79,100,1,12.71,100,1,14.07,2,1,12.50,700,1,14.08,100,1,12.46,200,2,14.28,100,1,12.43,700,1,14.40,100,1,12.42,700,1,14.56,800,2,12.37,700,1,14.60,700,1,ARL,307964665
2025-07-17T15:48:42.009954046Z,2025-07-17T15:48:42.009788565Z,10,2,1108,C,A,0,13.78,15,130,165481,258199397,13.26,100,1,13.75,15,1,13.04,2,1,13.76,100,1,13.03,100,1,13.79,100,1,12.73,100,1,14.07,2,1,12.71,100,1,14.08,100,1,12.50,700,1,14.28,100,1,12.46,200,2,14.40,100,1,12.43,700,1,14.56,800,2,12.42,700,1,14.60,700,1,12.37,700,1,14.64,100,1,ARL,307714769
2025-07-17T15:48:42.011846392Z,2025-07-17T15:48:42.011680742Z,10,2,1108,C,A,0,14.75,100,0,165650,258199535,13.26,100,1,13.75,15,1,13.04,2,1,13.76,100,1,13.03,100,1,13.79,100,1,12.73,100,1,14.07,2,1,12.71,100,1,14.08,100,1,12.50,700,1,14.28,100,1,12.46,200,2,14.40,100,1,12.43,700,1,14.56,800,2,12.42,700,1,14.60,700,1,12.37,700,1,14.64,100,1,ARL,306519741
2025-07-17T15:48:42.011846392Z,2025-07-17T15:48:42.011680742Z,10,2,1108,A,A,0,14.64,100,130,165650,258199535,13.26,100,1,13.75,15,1,13.04,2,1,13.76,100,1,13.03,100,1,13.79,100,1,12.73,100,1,14.07,2,1,12.71,100,1,14.08,100,1,12.50,700,1,14.28,100,1,12.46,200,2,14.40,100,1,12.43,700,1,14.56,800,2,12.42,700,1,14.60,700,1,12.37,700,1,14.64,200,2,ARL,308296381
2025-07-17T15:48:42.016761374Z,2025-07-17T15:48:42.016595806Z,10,2,1108,A,A,0,13.77,100,130,165568,258199787,13.26,100,1,13.75,15,1,13.04,2,1,13.76,100,1,13.03,100,1,13.77,100,1,12.73,100,1,13.79,100,1,12.71,100,1,14.07,2,1,12.50,700,1,14.08,100,1,12.46,200,2,14.28,100,1,12.43,700,1,14.40,100,1,12.42,700,1,14.56,800,2,12.37,700,1,14.60,700,1,ARL,308296741
2025-07-17T15:48:42.023432407Z,2025-07-17T15:48:42.023266760Z,10,2,1108,C,A,0,13.79,100,130,165647,258199990,13.26,100,1,13.75,15,1,13.04,2,1,13.76,100,1,13.03,100,1,13.77,100,1,12.73,100,1,14.07,2,1,12.71,100,1,14.08,100,1,12.50,700,1,14.28,100,1,12.46,200,2,14.40,100,1,12.43,700,1,14.56,800,2,12.42,700,1,14.60,700,1,12.37,700,1,14.64,200,2,ARL,307964609
2025-07-17T15:48:46.750088490Z,2025-07-17T15:48:46.749922127Z,10,2,1108,A,A,0,13.73,15,128,166363,258260871,13.26,100,1,13.73,15,1,13.04,2,1,13.75,15,1,13.03,100,1,13.76,100,1,12.73,100,1,13.77,100,1,12.71,100,1,14.07,2,1,12.50,700,1,14.08,100,1,12.46,200,2,14.28,100,1,12.43,700,1,14.40,100,1,12.42,700,1,14.56,800,2,12.37,700,1,14.60,700,1,ARL,308374537
2025-07-17T15:48:46.758551033Z,2025-07-17T15:48:46.758385367Z,10,2,1108,C,A,0,13.76,100,0,165666,258261154,13.26,100,1,13.73,15,1,13.04,2,1,13.75,15,1,13.03,100,1,13.77,100,1,12.73,100,1,14.07,2,1,12.71,100,1,14.08,100,1,12.50,700,1,14.28,100,1,12.46,200,2,14.40,100,1,12.43,700,1,14.56,800,2,12.42,700,1,14.60,700,1,12.37,700,1,14.64,200,2,ARL,307964621
2025-07-17T15:48:46.758551033Z,2025-07-17T15:48:46.758385367Z,10,2,1108,A,A,0,13.74,100,130,165666,258261154,13.26,100,1,13.73,15,1,13.04,2,1,13.74,100,1,13.03,100,1,13.75,15,1,12.73,100,1,13.77,100,1,12.71,100,1,14.07,2,1,12.50,700,1,14.08,100,1,12.46,200,2,14.28,100,1,12.43,700,1,14.40,100,1,12.42,700,1,14.56,800,2,12.37,700,1,14.60,700,1,ARL,308374881
2025-07-17T15:48:46.773668988Z,2025-07-17T15:48:46.773503306Z,10,2,1108,C,A,0,14.08,100,130,165682,258261538,13.26,100,1,13.73,15,1,13.04,2,1,13.74,100,1,13.03,100,1,13.75,15,1,12.73,100,1,13.77,100,1,12.71,100,1,14.07,2,1,12.50,700,1,14.28,100,1,12.46,200,2,14.40,100,1,12.43,700,1,14.56,800,2,12.42,700,1,14.60,700,1,12.37,700,1,14.64,200,2,ARL,306784853
2025-07-17T15:48:46.773720726Z,2025-07-17T15:48:46.773555566Z,10,2,1108,A,A,0,14.01,100,130,165160,258261539,13.26,100,1,13.73,15,1,13.04,2,1,13.74,100,1,13.03,100,1,13.75,15,1,12.73,100,1,13.77,100,1,12.71,100,1,14.01,100,1,12.50,700,1,14.07,2,1,12.46,200,2,14.28,100,1,12.43,700,1,14.40,100,1,12.42,700,1,14.56,800,2,12.37,700,1,14.60,700,1,ARL,308375185
2025-07-17T15:49:02.010494480Z,2025-07-17T15:49:02.010329052Z,10,2,1108,A,A,0,13.75,100,130,165428,258502869,13.26,100,1,13.73,15,1,13.04,2,1,13.74,100,1,13.03,100,1,13.75,115,2,12.73,100,1,13.77,100,1,12.71,100,1,14.01,100,1,12.50,700,1,14.07,2,1,12.46,200,2,14.28,100,1,12.43,700,1,14.40,100,1,12.42,700,1,14.56,800,2,12.37,700,1,14.60,700,1,ARL,308705489
2025-07-17T15:49:02.019989567Z,2025-07-17T15:49:02.019824230Z,10,2,1108,C,A,0,13.77,100,130,165337,258502929,13.26,100,1,13.73,15,1,13.04,2,1,13.74,100,1,13.03,100,1,13.75,115,2,12.73,100,1,14.01,100,1,12.71,100,1,14.07,2,1,12.50,700,1,14.28,100,1,12.46,200,2,14.40,100,1,12.43,700,1,14.56,800,2,12.42,700,1,14.60,700,1,12.37,700,1,14.64,200,2,ARL,308296741
2025-07-17T15:49:03.406005590Z,2025-07-17T15:49:03.405840358Z,10,2,1108,C,A,0,13.75,15,130,165232,258527308,13.26,100,1,13.73,15,1,13.04,2,1,13.74,100,1,13.03,100,1,13.75,100,1,12.73,100,1,14.01,100,1,12.71,100,1,14.07,2,1,12.50,700,1,14.28,100,1,12.46,200,2,14.40,100,1,12.43,700,1,14.56,800,2,12.42,700,1,14.60,700,1,12.37,700,1,14.64,200,2,ARL,307964605
2025-07-17T15:49:04.713997925Z,2025-07-17T15:49:04.713831675Z,10,2,1108,A,A,0,13.71,15,128,166250,258547335,13.26,100,1,13.71,15,1,13.04,2,1,13.73,15,1,13.03,100,1,13.74,100,1,12.73,100,1,13.75,100,1,12.71,100,1,14.01,100,1,12.50,700,1,14.07,2,1,12.46,200,2,14.28,100,1,12.43,700,1,14.40,100,1,12.42,700,1,14.56,800,2,12.37,700,1,14.60,700,1,ARL,308763065
2025-07-17T15:49:06.013111941Z,2025-07-17T15:49:06.012946379Z,10,2,1108,A,A,0,13.73,100,130,165562,258567259,13.26,100,1,13.71,15,1,13.04,2,1,13.73,115,2,13.03,100,1,13.74,100,1,12.73,100,1,13.75,100,1,12.71,100,1,14.01,100,1,12.50,700,1,14.07,2,1,12.46,200,2,14.28,100,1,12.43,700,1,14.40,100,1,12.42,700,1,14.56,800,2,12.37,700,1,14.60,700,1,ARL,308786185
2025-07-17T15:49:06.023292147Z,2025-07-17T15:49:06.023126600Z,10,2,1108,C,A,0,13.75,100,130,165547,258567405,13.26,100,1,13.71,15,1,13.04,2,1,13.73,115,2,13.03,100,1,13.74,100,1,12.73,100,1,14.01,100,1,12.71,100,1,14.07,2,1,12.50,700,1,14.28,100,1,12.46,200,2,14.40,100,1,12.43,700,1,14.56,800,2,12.42,700,1,14.60,700,1,12.37,700,1,14.64,200,2,ARL,308705489
2025-07-17T15:49:06.344356890Z,2025-07-17T15:49:06.344191321Z,10,2,1108,C,A,0,13.74,100,0,165569,258574949,13.26,100,1,13.71,15,1,13.04,2,1,13.73,115,2,13.03,100,1,14.01,100,1,12.73,100,1,14.07,2,1,12.71,100,1,14.28,100,1,12.50,700,1,14.40,100,1,12.46,200,2,14.56,800,2,12.43,700,1,14.60,700,1,12.42,700,1,14.64,200,2,12.37,700,1,14.65,100,1,ARL,308374881
2025-07-17T15:49:06.344356890Z,2025-07-17T15:49:06.344191321Z,10,2,1108,A,A,0,13.72,100,130,165569,258574949,13.26,100,1,13.71,15,1,13.04,2,1,13.72,100,1,13.03,100,1,13.73,115,2,12.73,100,1,14.01,100,1,12.71,100,1,14.07,2,1,12.50,700,1,14.28,100,1,12.46,200,2,14.40,100,1,12.43,700,1,14.56,800,2,12.42,700,1,14.60,700,1,12.37,700,1,14.64,200,2,ARL,308797069
2025-07-17T15:49:06.345104491Z,2025-07-17T15:49:06.344938975Z,10,2,1108,C,A,0,14.83,100,0,165516,258575013,13.26,100,1,13.71,15,1,13.04,2,1,13.72,100,1,13.03,100,1,13.73,115,2,12.73,100,1,14.01,100,1,12.71,100,1,14.07,2,1,12.50,700,1,14.28,100,1,12.46,200,2,14.40,100,1,12.43,700,1,14.56,800,2,12.42,700,1,14.60,700,1,12.37,700,1,14.64,200,2,ARL,307964665
2025-07-17T15:49:06.345104491Z,2025-07-17T15:49:06.344938975Z,10,2,1108,A,A,0,14.78,100,130,165516,258575013,13.26,100,1,13.71,15,1,13.04,2,1,13.72,100,1,13.03,100,1,13.73,115,2,12.73,100,1,14.01,100,1,12.71,100,1,14.07,2,1,12.50,700,1,14.28,100,1,12.46,200,2,14.40,100,1,12.43,700,1,14.56,800,2,12.42,700,1,14.60,700,1,12.37,700,1,14.64,200,2,ARL,308797245
2025-07-17T15:49:06.362945410Z,2025-07-17T15:49:06.362779870Z,10,2,1108,C,A,0,17.58,100,0,165540,258575963,13.26,100,1,13.71,15,1,13.04,2,1,13.72,100,1,13.03,100,1,13.73,115,2,12.73,100,1,14.01,100,1,12.71,100,1,14.07,2,1,12.50,700,1,14.28,100,1,12.46,200,2,14.40,100,1,12.43,700,1,14.56,800,2,12.42,700,1,14.60,700,1,12.37,700,1,14.64,200,2,ARL,306652017
2025-07-17T15:49:06.362945410Z,2025-07-17T15:49:06.362779870Z,10,2,1108,A,A,0,17.43,100,130,165540,258575963,13.26,100,1,13.71,15,1,13.04,2,1,13.72,100,1,13.03,100,1,13.73,115,2,12.73,100,1,14.01,100,1,12.71,100,1,14.07,2,1,12.50,700,1,14.28,100,1,12.46,200,2,14.40,100,1,12.43,700,1,14.56,800,2,12.42,700,1,14.60,700,1,12.37,700,1,14.64,200,2,ARL,308799373
2025-07-17T15:49:10.459317885Z,2025-07-17T15:49:10.459152457Z,10,2,1108,C,A,0,13.73,15,130,165428,258636400,13.26,100,1,13.71,15,1,13.04,2,1,13.72,100,1,13.03,100,1,13.73,100,1,12.73,100,1,14.01,100,1,12.71,100,1,14.07,2,1,12.50,700,1,14.28,100,1,12.46,200,2,14.40,100,1,12.43,700,1,14.56,800,2,12.42,700,1,14.60,700,1,12.37,700,1,14.64,200,2,ARL,308374537
2025-07-17T15:49:11.460597600Z,2025-07-17T15:49:11.460432218Z,10,2,1108,A,A,0,13.69,15,130,165382,258650544,13.26,100,1,13.69,15,1,13.04,2,1,13.71,15,1,13.03,100,1,13.72,100,1,12.73,100,1,13.73,100,1,12.71,100,1,14.01,100,1,12.50,700,1,14.07,2,1,12.46,200,2,14.28,100,1,12.43,700,1,14.40,100,1,12.42,700,1,14.56,800,2,12.37,700,1,14.60,700,1,ARL,308893737
2025-07-17T15:49:11.891643099Z,2025-07-17T15:49:11.891477604Z,10,2,1108,C,A,0,13.72,100,0,165495,258658721,13.26,100,1,13.69,15,1,13.04,2,1,13.71,15,1,13.03,100,1,13.73,100,1,12.73,100,1,14.01,100,1,12.71,100,1,14.07,2,1,12.50,700,1,14.28,100,1,12.46,200,2,14.40,100,1,12.43,700,1,14.56,800,2,12.42,700,1,14.60,700,1,12.37,700,1,14.64,200,2,ARL,308797069
2025-07-17T15:49:11.891643099Z,2025-07-17T15:49:11.891477604Z,10,2,1108,A,A,0,13.70,100,130,165495,258658721,13.26,100,1,13.69,15,1,13.04,2,1,13.70,100,1,13.03,100,1,13.71,15,1,12.73,100,1,13.73,100,1,12.71,100,1,14.01,100,1,12.50,700,1,14.07,2,1,12.46,200,2,14.28,100,1,12.43,700,1,14.40,100,1,12.42,700,1,14.56,800,2,12.37,700,1,14.60,700,1,ARL,308901793
2025-07-17T15:49:11.893989071Z,2025-07-17T15:49:11.893823458Z,10,2,1108,C,A,0,14.81,100,0,165613,258658835,13.26,100,1,13.69,15,1,13.04,2,1,13.70,100,1,13.03,100,1,13.71,15,1,12.73,100,1,13.73,100,1,12.71,100,1,14.01,100,1,12.50,700,1,14.07,2,1,12.46,200,2,14.28,100,1,12.43,700,1,14.40,100,1,12.42,700,1,14.56,800,2,12.37,700,1,14.60,700,1,ARL,306649913
2025-07-17T15:49:11.893989071Z,2025-07-17T15:49:11.893823458Z,10,2,1108,A,A,0,14.66,100,130,165613,258658835,13.26,100,1,13.69,15,1,13.04,2,1,13.70,100,1,13.03,100,1,13.71,15,1,12.73,100,1,13.73,100,1,12.71,100,1,14.01,100,1,12.50,700,1,14.07,2,1,12.46,200,2,14.28,100,1,12.43,700,1,14.40,100,1,12.42,700,1,14.56,800,2,12.37,700,1,14.60,700,1,ARL,308901981
2025-07-17T15:49:11.904231149Z,2025-07-17T15:49:11.904065674Z,10,2,1108,C,A,0,15.92,100,0,165475,258659039,13.26,100,1,13.69,15,1,13.04,2,1,13.70,100,1,13.03,100,1,13.71,15,1,12.73,100,1,13.73,100,1,12.71,100,1,14.01,100,1,12.50,700,1,14.07,2,1,12.46,200,2,14.28,100,1,12.43,700,1,14.40,100,1,12.42,700,1,14.56,800,2,12.37,700,1,14.60,700,1,ARL,306652001
2025-07-17T15:49:11.904231149Z,2025-07-17T15:49:11.904065674Z,10,2,1108,A,A,0,15.76,100,130,165475,258659039,13.26,100,1,13.69,15,1,13.04,2,1,13.70,100,1,13.03,100,1,13.71,15,1,12.73,100,1,13.73,100,1,12.71,100,1,14.01,100,1,12.50,700,1,14.07,2,1,12.46,200,2,14.28,100,1,12.43,700,1,14.40,100,1,12.42,700,1,14.56,800,2,12.37,700,1,14.60,700,1,ARL,308902229
2025-07-17T15:49:11.935521687Z,2025-07-17T15:49:11.935356090Z,10,2,1108,C,A,0,14.81,100,0,165597,258659320,13.26,100,1,13.69,15,1,13.04,2,1,13.70,100,1,13.03,100,1,13.71,15,1,12.73,100,1,13.73,100,1,12.71,100,1,14.01,100,1,12.50,700,1,14.07,2,1,12.46,200,2,14.28,100,1,12.43,700,1,14.40,100,1,12.42,700,1,14.56,800,2,12.37,700,1,14.60,700,1,ARL,306653713
2025-07-17T15:49:11.935521687Z,2025-07-17T15:49:11.935356090Z,10,2,1108,A,A,0,14.66,100,130,165597,258659320,13.26,100,1,13.69,15,1,13.04,2,1,13.70,100,1,13.03,100,1,13.71,15,1,12.73,100,1,13.73,100,1,12.71,100,1,14.01,100,1,12.50,700,1,14.07,2,1,12.46,200,2,14.28,100,1,12.43,700,1,14.40,100,1,12.42,700,1,14.56,800,2,12.37,700,1,14.60,700,1,ARL,308903001
2025-07-17T15:49:11.948701049Z,2025-07-17T15:49:11.948535655Z,10,2,1108,C,A,0,14.64,100,130,165394,258659496,13.26,100,1,13.69,15,1,13.04,2,1,13.70,100,1,13.03,100,1,13.71,15,1,12.73,100,1,13.73,100,1,12.71,100,1,14.01,100,1,12.50,700,1,14.07,2,1,12.46,200,2,14.28,100,1,12.43,700,1,14.40,100,1,12.42,700,1,14.56,800,2,12.37,700,1,14.60,700,1,ARL,306647521
2025-07-17T15:49:11.948829112Z,2025-07-17T15:49:11.948663655Z,10,2,1108,A,A,0,14.50,100,130,165457,258659499,13.26,100,1,13.69,15,1,13.04,2,1,13.70,100,1,13.03,100,1,13.71,15,1,12.73,100,1,13.73,100,1,12.71,100,1,14.01,100,1,12.50,700,1,14.07,2,1,12.46,200,2,14.28,100,1,12.43,700,1,14.40,100,1,12.42,700,1,14.50,100,1,12.37,700,1,14.56,800,2,ARL,308903349
2025-07-17T15:49:12.221221367Z,2025-07-17T15:49:12.221056085Z,10,2,1108,A,A,0,13.71,100,130,165282,258663292,13.26,100,1,13.69,15,1,13.04,2,1,13.70,100,1,13.03,100,1,13.71,115,2,12.73,100,1,13.73,100,1,12.71,100,1,14.01,100,1,12.50,700,1,14.07,2,1,12.46,200,2,14.28,100,1,12.43,700,1,14.40,100,1,12.42,700,1,14.50,100,1,12.37,700,1,14.56,800,2,ARL,308909249
2025-07-17T15:49:12.227986905Z,2025-07-17T15:49:12.227821500Z,10,2,1108,C,A,0,13.73,100,130,165405,258663378,13.26,100,1,13.69,15,1,13.04,2,1,13.70,100,1,13.03,100,1,13.71,115,2,12.73,100,1,14.01,100,1,12.71,100,1,14.07,2,1,12.50,700,1,14.28,100,1,12.46,200,2,14.40,100,1,12.43,700,1,14.50,100,1,12.42,700,1,14.56,800,2,12.37,700,1,14.60,700,1,ARL,308786185
2025-07-17T15:49:14.463229121Z,2025-07-17T15:49:14.463063539Z,10,2,1108,C,A,0,13.71,15,130,165582,258702625,13.26,100,1,13.69,15,1,13.04,2,1,13.70,100,1,13.03,100,1,13.71,100,1,12.73,100,1,14.01,100,1,12.71,100,1,14.07,2,1,12.50,700,1,14.28,100,1,12.46,200,2,14.40,100,1,12.43,700,1,14.50,100,1,12.42,700,1,14.56,800,2,12.37,700,1,14.60,700,1,ARL,308763065
2025-07-17T15:49:15.466365122Z,2025-07-17T15:49:15.466199239Z,10,2,1108,A,A,0,13.67,15,130,165883,258716863,13.26,100,1,13.67,15,1,13.04,2,1,13.69,15,1,13.03,100,1,13.70,100,1,12.73,100,1,13.71,100,1,12.71,100,1,14.01,100,1,12.50,700,1,14.07,2,1,12.46,200,2,14.28,100,1,12.43,700,1,14.40,100,1,12.42,700,1,14.50,100,1,12.37,700,1,14.56,800,2,ARL,308980305
2025-07-17T15:49:16.351024588Z,2025-07-17T15:49:16.350859152Z,10,2,1108,C,A,0,13.70,100,0,165436,258727929,13.26,100,1,13.67,15,1,13.04,2,1,13.69,15,1,13.03,100,1,13.71,100,1,12.73,100,1,14.01,100,1,12.71,100,1,14.07,2,1,12.50,700,1,14.28,100,1,12.46,200,2,14.40,100,1,12.43,700,1,14.50,100,1,12.42,700,1,14.56,800,2,12.37,700,1,14.60,700,1,ARL,308901793
2025-07-17T15:49:16.351024588Z,2025-07-17T15:49:16.350859152Z,10,2,1108,A,A,0,13.68,100,130,165436,258727929,13.26,100,1,13.67,15,1,13.04,2,1,13.68,100,1,13.03,100,1,13.69,15,1,12.73,100,1,13.71,100,1,12.71,100,1,14.01,100,1,12.50,700,1,14.07,2,1,12.46,200,2,14.28,100,1,12.43,700,1,14.40,100,1,12.42,700,1,14.50,100,1,12.37,700,1,14.56,800,2,ARL,308998225
2025-07-17T15:49:16.351759618Z,2025-07-17T15:49:16.351594042Z,10,2,1108,C,A,0,14.78,100,0,165576,258727956,13.26,100,1,13.67,15,1,13.04,2,1,13.68,100,1,13.03,100,1,13.69,15,1,12.73,100,1,13.71,100,1,12.71,100,1,14.01,100,1,12.50,700,1,14.07,2,1,12.46,200,2,14.28,100,1,12.43,700,1,14.40,100,1,12.42,700,1,14.50,100,1,12.37,700,1,14.56,800,2,ARL,308797245
2025-07-17T15:49:16.351759618Z,2025-07-17T15:49:16.351594042Z,10,2,1108,A,A,0,14.74,100,130,165576,258727956,13.26,100,1,13.67,15,1,13.04,2,1,13.68,100,1,13.03,100,1,13.69,15,1,12.73,100,1,13.71,100,1,12.71,100,1,14.01,100,1,12.50,700,1,14.07,2,1,12.46,200,2,14.28,100,1,12.43,700,1,14.40,100,1,12.42,700,1,14.50,100,1,12.37,700,1,14.56,800,2,ARL,308998341
2025-07-17T15:49:16.494111490Z,2025-07-17T15:49:16.493946243Z,10,2,1108,A,A,0,13.69,100,130,165247,258729266,13.26,100,1,13.67,15,1,13.04,2,1,13.68,100,1,13.03,100,1,13.69,115,2,12.73,100,1,13.71,100,1,12.71,100,1,14.01,100,1,12.50,700,1,14.07,2,1,12.46,200,2,14.28,100,1,12.43,700,1,14.40,100,1,12.42,700,1,14.50,100,1,12.37,700,1,14.56,800,2,ARL,309001525
2025-07-17T15:49:16.557924863Z,2025-07-17T15:49:16.557759633Z,10,2,1108,C,A,0,13.71,100,130,165230,258730034,13.26,100,1,13.67,15,1,13.04,2,1,13.68,100,1,13.03,100,1,13.69,115,2,12.73,100,1,14.01,100,1,12.71,100,1,14.07,2,1,12.50,700,1,14.28,100,1,12.46,200,2,14.40,100,1,12.43,700,1,14.50,100,1,12.42,700,1,14.56,800,2,12.37,700,1,14.60,700,1,ARL,308909249
2025-07-17T15:49:21.186150487Z,2025-07-17T15:49:21.185984774Z,10,2,1108,C,A,0,14.07,2,0,165713,258786552,13.26,100,1,13.67,15,1,13.04,2,1,13.68,100,1,13.03,100,1,13.69,115,2,12.73,100,1,14.01,100,1,12.71,100,1,14.28,100,1,12.50,700,1,14.40,100,1,12.46,200,2,14.50,100,1,12.43,700,1,14.56,800,2,12.42,700,1,14.60,700,1,12.37,700,1,14.64,100,1,ARL,296478973
2025-07-17T15:49:21.186150487Z,2025-07-17T15:49:21.185984774Z,10,2,1108,A,A,0,13.98,2,130,165713,258786552,13.26,100,1,13.67,15,1,13.04,2,1,13.68,100,1,13.03,100,1,13.69,115,2,12.73,100,1,13.98,2,1,12.71,100,1,14.01,100,1,12.50,700,1,14.28,100,1,12.46,200,2,14.40,100,1,12.43,700,1,14.50,100,1,12.42,700,1,14.56,800,2,12.37,700,1,14.60,700,1,ARL,309091513
2025-07-17T15:49:24.283152112Z,2025-07-17T15:49:24.282985894Z,10,2,1108,C,A,0,13.69,15,130,166218,258838460,13.26,100,1,13.67,15,1,13.04,2,1,13.68,100,1,13.03,100,1,13.69,100,1,12.73,100,1,13.98,2,1,12.71,100,1,14.01,100,1,12.50,700,1,14.28,100,1,12.46,200,2,14.40,100,1,12.43,700,1,14.50,100,1,12.42,700,1,14.56,800,2,12.37,700,1,14.60,700,1,ARL,308893737
2025-07-17T15:49:34.570197134Z,2025-07-17T15:49:34.570031718Z,10,2,1108,C,A,0,13.67,15,130,165416,258980876,13.26,100,1,13.68,100,1,13.04,2,1,13.69,100,1,13.03,100,1,13.98,2,1,12.73,100,1,14.01,100,1,12.71,100,1,14.28,100,1,12.50,700,1,14.40,100,1,12.46,200,2,14.50,100,1,12.43,700,1,14.56,800,2,12.42,700,1,14.60,700,1,12.37,700,1,14.64,100,1,ARL,308980305
2025-07-17T15:49:34.591512915Z,2025-07-17T15:49:34.591347169Z,10,2,1108,C,A,0,13.69,100,130,165746,258983321,13.26,100,1,13.68,100,1,13.04,2,1,13.98,2,1,13.03,100,1,14.01,100,1,12.73,100,1,14.28,100,1,12.71,100,1,14.40,100,1,12.50,700,1,14.50,100,1,12.46,200,2,14.56,800,2,12.43,700,1,14.60,700,1,12.42,700,1,14.64,100,1,12.37,700,1,14.65,100,1,ARL,309001525
2025-07-17T15:49:38.610017394Z,2025-07-17T15:49:38.609851985Z,10,2,1108,A,A,0,13.72,100,130,165409,259031220,13.26,100,1,13.68,100,1,13.04,2,1,13.72,100,1,13.03,100,1,13.98,2,1,12.73,100,1,14.01,100,1,12.71,100,1,14.28,100,1,12.50,700,1,14.40,100,1,12.46,200,2,14.50,100,1,12.43,700,1,14.56,800,2,12.42,700,1,14.60,700,1,12.37,700,1,14.64,100,1,ARL,309410565
2025-07-17T15:49:38.610073334Z,2025-07-17T15:49:38.609907720Z,10,2,1108,C,B,0,13.26,100,130,165614,259031221,13.04,2,1,13.68,100,1,13.03,100,1,13.72,100,1,12.73,100,1,13.98,2,1,12.71,100,1,14.01,100,1,12.50,700,1,14.28,100,1,12.46,200,2,14.40,100,1,12.43,700,1,14.50,100,1,12.42,700,1,14.56,800,2,12.37,700,1,14.60,700,1,12.36,200,2,14.64,100,1,ARL,291975017
2025-07-17T15:49:39.068515005Z,2025-07-17T15:49:39.068349660Z,10,2,1108,A,B,0,13.02,100,130,165345,259035032,13.04,2,1,13.68,100,1,13.03,100,1,13.72,100,1,13.02,100,1,13.98,2,1,12.73,100,1,14.01,100,1,12.71,100,1,14.28,100,1,12.50,700,1,14.40,100,1,12.46,200,2,14.50,100,1,12.43,700,1,14.56,800,2,12.42,700,1,14.60,700,1,12.37,700,1,14.64,100,1,ARL,309415429
2025-07-17T15:49:44.788414401Z,2025-07-17T15:49:44.788249210Z,10,2,1108,A,A,0,13.67,15,130,165191,259105347,13.04,2,1,13.67,15,1,13.03,100,1,13.68,100,1,13.02,100,1,13.72,100,1,12.73,100,1,13.98,2,1,12.71,100,1,14.01,100,1,12.50,700,1,14.28,100,1,12.46,200,2,14.40,100,1,12.43,700,1,14.50,100,1,12.42,700,1,14.56,800,2,12.37,700,1,14.60,700,1,ARL,309524921
2025-07-17T15:49:44.789020757Z,2025-07-17T15:49:44.788855587Z,10,2,1108,A,A,0,13.70,100,130,165170,259105361,13.04,2,1,13.67,15,1,13.03,100,1,13.68,100,1,13.02,100,1,13.70,100,1,12.73,100,1,13.72,100,1,12.71,100,1,13.98,2,1,12.50,700,1,14.01,100,1,12.46,200,2,14.28,100,1,12.43,700,1,14.40,100,1,12.42,700,1,14.50,100,1,12.37,700,1,14.56,800,2,ARL,309524933
2025-07-17T15:49:44.789702916Z,2025-07-17T15:49:44.789537536Z,10,2,1108,C,A,0,13.72,100,130,165380,259105380,13.04,2,1,13.67,15,1,13.03,100,1,13.68,100,1,13.02,100,1,13.70,100,1,12.73,100,1,13.98,2,1,12.71,100,1,14.01,100,1,12.50,700,1,14.28,100,1,12.46,200,2,14.40,100,1,12.43,700,1,14.50,100,1,12.42,700,1,14.56,800,2,12.37,700,1,14.60,700,1,ARL,309410565
2025-07-17T15:49:54.788658841Z,2025-07-17T15:49:54.788493605Z,10,2,1108,A,A,0,13.65,15,130,165236,259253294,13.04,2,1,13.65,15,1,13.03,100,1,13.67,15,1,13.02,100,1,13.68,100,1,12.73,100,1,13.70,100,1,12.71,100,1,13.98,2,1,12.50,700,1,14.01,100,1,12.46,200,2,14.28,100,1,12.43,700,1,14.40,100,1,12.42,700,1,14.50,100,1,12.37,700,1,14.56,800,2,ARL,309707269
2025-07-17T15:49:54.799535744Z,2025-07-17T15:49:54.799370442Z,10,2,1108,A,A,0,13.68,100,130,165302,259253527,13.04,2,1,13.65,15,1,13.03,100,1,13.67,15,1,13.02,100,1,13.68,200,2,12.73,100,1,13.70,100,1,12.71,100,1,13.98,2,1,12.50,700,1,14.01,100,1,12.46,200,2,14.28,100,1,12.43,700,1,14.40,100,1,12.42,700,1,14.50,100,1,12.37,700,1,14.56,800,2,ARL,309707413
2025-07-17T15:49:54.820634917Z,2025-07-17T15:49:54.820469390Z,10,2,1108,C,A,0,13.70,100,130,165527,259253732,13.04,2,1,13.65,15,1,13.03,100,1,13.67,15,1,13.02,100,1,13.68,200,2,12.73,100,1,13.98,2,1,12.71,100,1,14.01,100,1,12.50,700,1,14.28,100,1,12.46,200,2,14.40,100,1,12.43,700,1,14.50,100,1,12.42,700,1,14.56,800,2,12.37,700,1,14.60,700,1,ARL,309524933
2025-07-17T15:49:59.512104064Z,2025-07-17T15:49:59.511938438Z,10,2,1108,C,A,0,13.68,100,0,165626,259313537,13.04,2,1,13.65,15,1,13.03,100,1,13.67,15,1,13.02,100,1,13.68,100,1,12.73,100,1,13.98,2,1,12.71,100,1,14.01,100,1,12.50,700,1,14.28,100,1,12.46,200,2,14.40,100,1,12.43,700,1,14.50,100,1,12.42,700,1,14.56,800,2,12.37,700,1,14.60,700,1,ARL,308998225
2025-07-17T15:49:59.512104064Z,2025-07-17T15:49:59.511938438Z,10,2,1108,A,A,0,13.66,100,130,165626,259313537,13.04,2,1,13.65,15,1,13.03,100,1,13.66,100,1,13.02,100,1,13.67,15,1,12.73,100,1,13.68,100,1,12.71,100,1,13.98,2,1,12.50,700,1,14.01,100,1,12.46,200,2,14.28,100,1,12.43,700,1,14.40,100,1,12.42,700,1,14.50,100,1,12.37,700,1,14.56,800,2,ARL,309782481
2025-07-17T15:49:59.534062634Z,2025-07-17T15:49:59.533897369Z,10,2,1108,C,A,0,14.01,100,130,165265,259314032,13.04,2,1,13.65,15,1,13.03,100,1,13.66,100,1,13.02,100,1,13.67,15,1,12.73,100,1,13.68,100,1,12.71,100,1,13.98,2,1,12.50,700,1,14.28,100,1,12.46,200,2,14.40,100,1,12.43,700,1,14.50,100,1,12.42,700,1,14.56,800,2,12.37,700,1,14.60,700,1,ARL,308375185
2025-07-17T15:49:59.534115275Z,2025-07-17T15:49:59.533948952Z,10,2,1108,A,A,0,13.93,100,130,166323,259314033,13.04,2,1,13.65,15,1,13.03,100,1,13.66,100,1,13.02,100,1,13.67,15,1,12.73,100,1,13.68,100,1,12.71,100,1,13.93,100,1,12.50,700,1,13.98,2,1,12.46,200,2,14.28,100,1,12.43,700,1,14.40,100,1,12.42,700,1,14.50,100,1,12.37,700,1,14.56,800,2,ARL,309782973
2025-07-17T15:50:00.547404972Z,2025-07-17T15:50:00.547239401Z,10,2,1108,C,A,0,13.67,15,130,165571,259349868,13.04,2,1,13.65,15,1,13.03,100,1,13.66,100,1,13.02,100,1,13.68,100,1,12.73,100,1,13.93,100,1,12.71,100,1,13.98,2,1,12.50,700,1,14.28,100,1,12.46,200,2,14.40,100,1,12.43,700,1,14.50,100,1,12.42,700,1,14.56,800,2,12.37,700,1,14.60,700,1,ARL,309524921
2025-07-17T15:50:00.555536688Z,2025-07-17T15:50:00.555363249Z,10,2,1108,C,A,0,14.65,100,0,173439,259353226,13.04,2,1,13.65,15,1,13.03,100,1,13.66,100,1,13.02,100,1,13.68,100,1,12.73,100,1,13.93,100,1,12.71,100,1,13.98,2,1,12.50,700,1,14.28,100,1,12.46,200,2,14.40,100,1,12.43,700,1,14.50,100,1,12.42,700,1,14.56,800,2,12.37,700,1,14.60,700,1,ARL,307964661
2025-07-17T15:50:00.555536688Z,2025-07-17T15:50:00.555363249Z,10,2,1108,A,A,0,14.54,100,128,173439,259353226,13.04,2,1,13.65,15,1,13.03,100,1,13.66,100,1,13.02,100,1,13.68,100,1,12.73,100,1,13.93,100,1,12.71,100,1,13.98,2,1,12.50,700,1,14.28,100,1,12.46,200,2,14.40,100,1,12.43,700,1,14.50,100,1,12.42,700,1,14.54,100,1,12.37,700,1,14.56,800,2,ARL,309823025
2025-07-17T15:50:03.412422880Z,2025-07-17T15:50:03.412257475Z,10,2,1108,A,A,0,13.63,15,130,165405,259413272,13.04,2,1,13.63,15,1,13.03,100,1,13.65,15,1,13.02,100,1,13.66,100,1,12.73,100,1,13.68,100,1,12.71,100,1,13.93,100,1,12.50,700,1,13.98,2,1,12.46,200,2,14.28,100,1,12.43,700,1,14.40,100,1,12.42,700,1,14.50,100,1,12.37,700,1,14.54,100,1,ARL,309899025
2025-07-17T15:50:03.415527372Z,2025-07-17T15:50:03.415361851Z,10,2,1108,C,A,0,14.64,100,0,165521,259413427,13.04,2,1,13.63,15,1,13.03,100,1,13.65,15,1,13.02,100,1,13.66,100,1,12.73,100,1,13.68,100,1,12.71,100,1,13.93,100,1,12.50,700,1,13.98,2,1,12.46,200,2,14.28,100,1,12.43,700,1,14.40,100,1,12.42,700,1,14.50,100,1,12.37,700,1,14.54,100,1,ARL,308296381
2025-07-17T15:50:03.415527372Z,2025-07-17T15:50:03.415361851Z,10,2,1108,A,A,0,14.53,100,130,165521,259413427,13.04,2,1,13.63,15,1,13.03,100,1,13.65,15,1,13.02,100,1,13.66,100,1,12.73,100,1,13.68,100,1,12.71,100,1,13.93,100,1,12.50,700,1,13.98,2,1,12.46,200,2,14.28,100,1,12.43,700,1,14.40,100,1,12.42,700,1,14.50,100,1,12.37,700,1,14.53,100,1,ARL,309899141
2025-07-17T15:50:03.824292152Z,2025-07-17T15:50:03.824126753Z,10,2,1108,C,A,0,13.66,100,0,165399,259418661,13.04,2,1,13.63,15,1,13.03,100,1,13.65,15,1,13.02,100,1,13.68,100,1,12.73,100,1,13.93,100,1,12.71,100,1,13.98,2,1,12.50,700,1,14.28,100,1,12.46,200,2,14.40,100,1,12.43,700,1,14.50,100,1,12.42,700,1,14.53,100,1,12.37,700,1,14.54,100,1,ARL,309782481
2025-07-17T15:50:03.824292152Z,2025-07-17T15:50:03.824126753Z,10,2,1108,A,A,0,13.64,100,130,165399,259418661,13.04,2,1,13.63,15,1,13.03,100,1,13.64,100,1,13.02,100,1,13.65,15,1,12.73,100,1,13.68,100,1,12.71,100,1,13.93,100,1,12.50,700,1,13.98,2,1,12.46,200,2,14.28,100,1,12.43,700,1,14.40,100,1,12.42,700,1,14.50,100,1,12.37,700,1,14.53,100,1,ARL,309903973
2025-07-17T15:50:03.825028460Z,2025-07-17T15:50:03.824863026Z,10,2,1108,C,A,0,14.74,100,0,165434,259418664,13.04,2,1,13.63,15,1,13.03,100,1,13.64,100,1,13.02,100,1,13.65,15,1,12.73,100,1,13.68,100,1,12.71,100,1,13.93,100,1,12.50,700,1,13.98,2,1,12.46,200,2,14.28,100,1,12.43,700,1,14.40,100,1,12.42,700,1,14.50,100,1,12.37,700,1,14.53,100,1,ARL,308998341
2025-07-17T15:50:03.825028460Z,2025-07-17T15:50:03.824863026Z,10,2,1108,A,A,0,14.70,100,130,165434,259418664,13.04,2,1,13.63,15,1,13.03,100,1,13.64,100,1,13.02,100,1,13.65,15,1,12.73,100,1,13.68,100,1,12.71,100,1,13.93,100,1,12.50,700,1,13.98,2,1,12.46,200,2,14.28,100,1,12.43,700,1,14.40,100,1,12.42,700,1,14.50,100,1,12.37,700,1,14.53,100,1,ARL,309903993
2025-07-17T15:50:04.484898759Z,2025-07-17T15:50:04.484733438Z,10,2,1108,A,A,0,13.66,100,130,165321,259433904,13.04,2,1,13.63,15,1,13.03,100,1,13.64,100,1,13.02,100,1,13.65,15,1,12.73,100,1,13.66,100,1,12.71,100,1,13.68,100,1,12.50,700,1,13.93,100,1,12.46,200,2,13.98,2,1,12.43,700,1,14.28,100,1,12.42,700,1,14.40,100,1,12.37,700,1,14.50,100,1,ARL,309922345
2025-07-17T15:50:04.524729039Z,2025-07-17T15:50:04.524563568Z,10,2,1108,C,A,0,13.68,100,130,165471,259434652,13.04,2,1,13.63,15,1,13.03,100,1,13.64,100,1,13.02,100,1,13.65,15,1,12.73,100,1,13.66,100,1,12.71,100,1,13.93,100,1,12.50,700,1,13.98,2,1,12.46,200,2,14.28,100,1,12.43,700,1,14.40,100,1,12.42,700,1,14.50,100,1,12.37,700,1,14.53,100,1,ARL,309707413
2025-07-17T15:50:06.787826975Z,2025-07-17T15:50:06.787661846Z,10,2,1108,C,A,0,13.63,15,130,165129,259472951,13.04,2,1,13.64,100,1,13.03,100,1,13.65,15,1,13.02,100,1,13.66,100,1,12.73,100,1,13.93,100,1,12.71,100,1,13.98,2,1,12.50,700,1,14.28,100,1,12.46,200,2,14.40,100,1,12.43,700,1,14.50,100,1,12.42,700,1,14.53,100,1,12.37,700,1,14.54,100,1,ARL,309899025
2025-07-17T15:50:09.185499367Z,2025-07-17T15:50:09.185334126Z,10,2,1108,A,A,0,13.61,15,130,165241,259516855,13.04,2,1,13.61,15,1,13.03,100,1,13.64,100,1,13.02,100,1,13.65,15,1,12.73,100,1,13.66,100,1,12.71,100,1,13.93,100,1,12.50,700,1,13.98,2,1,12.46,200,2,14.28,100,1,12.43,700,1,14.40,100,1,12.42,700,1,14.50,100,1,12.37,700,1,14.53,100,1,ARL,310030465
2025-07-17T15:50:09.198476437Z,2025-07-17T15:50:09.198311198Z,10,2,1108,A,A,0,13.64,100,130,165239,259517754,13.04,2,1,13.61,15,1,13.03,100,1,13.64,200,2,13.02,100,1,13.65,15,1,12.73,100,1,13.66,100,1,12.71,100,1,13.93,100,1,12.50,700,1,13.98,2,1,12.46,200,2,14.28,100,1,12.43,700,1,14.40,100,1,12.42,700,1,14.50,100,1,12.37,700,1,14.53,100,1,ARL,310031625
2025-07-17T15:50:09.205487416Z,2025-07-17T15:50:09.205322092Z,10,2,1108,C,A,0,13.66,100,130,165324,259517973,13.04,2,1,13.61,15,1,13.03,100,1,13.64,200,2,13.02,100,1,13.65,15,1,12.73,100,1,13.93,100,1,12.71,100,1,13.98,2,1,12.50,700,1,14.28,100,1,12.46,200,2,14.40,100,1,12.43,700,1,14.50,100,1,12.42,700,1,14.53,100,1,12.37,700,1,14.54,100,1,ARL,309922345
2025-07-17T15:50:09.330738153Z,2025-07-17T15:50:09.330572653Z,10,2,1108,C,A,0,13.64,100,0,165500,259522708,13.04,2,1,13.61,15,1,13.03,100,1,13.64,100,1,13.02,100,1,13.65,15,1,12.73,100,1,13.93,100,1,12.71,100,1,13.98,2,1,12.50,700,1,14.28,100,1,12.46,200,2,14.40,100,1,12.43,700,1,14.50,100,1,12.42,700,1,14.53,100,1,12.37,700,1,14.54,100,1,ARL,309903973
2025-07-17T15:50:09.330738153Z,2025-07-17T15:50:09.330572653Z,10,2,1108,A,A,0,13.62,100,130,165500,259522708,13.04,2,1,13.61,15,1,13.03,100,1,13.62,100,1,13.02,100,1,13.64,100,1,12.73,100,1,13.65,15,1,12.71,100,1,13.93,100,1,12.50,700,1,13.98,2,1,12.46,200,2,14.28,100,1,12.43,700,1,14.40,100,1,12.42,700,1,14.50,100,1,12.37,700,1,14.53,100,1,ARL,310037965
2025-07-17T15:50:20.204539185Z,2025-07-17T15:50:20.204373858Z,10,2,1108,C,A,0,13.65,15,130,165327,259737768,13.04,2,1,13.61,15,1,13.03,100,1,13.62,100,1,13.02,100,1,13.64,100,1,12.73,100,1,13.93,100,1,12.71,100,1,13.98,2,1,12.50,700,1,14.28,100,1,12.46,200,2,14.40,100,1,12.43,700,1,14.50,100,1,12.42,700,1,14.53,100,1,12.37,700,1,14.54,100,1,ARL,309707269
2025-07-17T15:50:25.935579034Z,2025-07-17T15:50:25.935412900Z,10,2,1108,A,A,0,13.59,15,128,166134,259828644,13.04,2,1,13.59,15,1,13.03,100,1,13.61,15,1,13.02,100,1,13.62,100,1,12.73,100,1,13.64,100,1,12.71,100,1,13.93,100,1,12.50,700,1,13.98,2,1,12.46,200,2,14.28,100,1,12.43,700,1,14.40,100,1,12.42,700,1,14.50,100,1,12.37,700,1,14.53,100,1,ARL,310424077
2025-07-17T15:50:26.954828150Z,2025-07-17T15:50:26.954662143Z,10,2,1108,C,A,0,13.62,100,0,166007,259847181,13.04,2,1,13.59,15,1,13.03,100,1,13.61,15,1,13.02,100,1,13.64,100,1,12.73,100,1,13.93,100,1,12.71,100,1,13.98,2,1,12.50,700,1,14.28,100,1,12.46,200,2,14.40,100,1,12.43,700,1,14.50,100,1,12.42,700,1,14.53,100,1,12.37,700,1,14.54,100,1,ARL,310037965
2025-07-17T15:50:26.954828150Z,2025-07-17T15:50:26.954662143Z,10,2,1108,A,A,0,13.60,100,130,166007,259847181,13.04,2,1,13.59,15,1,13.03,100,1,13.60,100,1,13.02,100,1,13.61,15,1,12.73,100,1,13.64,100,1,12.71,100,1,13.93,100,1,12.50,700,1,13.98,2,1,12.46,200,2,14.28,100,1,12.43,700,1,14.40,100,1,12.42,700,1,14.50,100,1,12.37,700,1,14.53,100,1,ARL,310446249
2025-07-17T15:50:26.955565904Z,2025-07-17T15:50:26.955400327Z,10,2,1108,C,A,0,14.70,100,0,165577,259847190,13.04,2,1,13.59,15,1,13.03,100,1,13.60,100,1,13.02,100,1,13.61,15,1,12.73,100,1,13.64,100,1,12.71,100,1,13.93,100,1,12.50,700,1,13.98,2,1,12.46,200,2,14.28,100,1,12.43,700,1,14.40,100,1,12.42,700,1,14.50,100,1,12.37,700,1,14.53,100,1,ARL,309903993
2025-07-17T15:50:26.955565904Z,2025-07-17T15:50:26.955400327Z,10,2,1108,A,A,0,14.65,100,130,165577,259847190,13.04,2,1,13.59,15,1,13.03,100,1,13.60,100,1,13.02,100,1,13.61,15,1,12.73,100,1,13.64,100,1,12.71,100,1,13.93,100,1,12.50,700,1,13.98,2,1,12.46,200,2,14.28,100,1,12.43,700,1,14.40,100,1,12.42,700,1,14.50,100,1,12.37,700,1,14.53,100,1,ARL,310446269
2025-07-17T15:50:26.956259508Z,2025-07-17T15:50:26.956094101Z,10,2,1108,C,A,0,17.43,100,0,165407,259847199,13.04,2,1,13.59,15,1,13.03,100,1,13.60,100,1,13.02,100,1,13.61,15,1,12.73,100,1,13.64,100,1,12.71,100,1,13.93,100,1,12.50,700,1,13.98,2,1,12.46,200,2,14.28,100,1,12.43,700,1,14.40,100,1,12.42,700,1,14.50,100,1,12.37,700,1,14.53,100,1,ARL,308799373
2025-07-17T15:50:26.956259508Z,2025-07-17T15:50:26.956094101Z,10,2,1108,A,A,0,17.28,100,130,165407,259847199,13.04,2,1,13.59,15,1,13.03,100,1,13.60,100,1,13.02,100,1,13.61,15,1,12.73,100,1,13.64,100,1,12.71,100,1,13.93,100,1,12.50,700,1,13.98,2,1,12.46,200,2,14.28,100,1,12.43,700,1,14.40,100,1,12.42,700,1,14.50,100,1,12.37,700,1,14.53,100,1,ARL,310446293
2025-07-17T15:50:26.983044736Z,2025-07-17T15:50:26.982879448Z,10,2,1108,A,A,0,15.51,100,130,165288,259847556,13.04,2,1,13.59,15,1,13.03,100,1,13.60,100,1,13.02,100,1,13.61,15,1,12.73,100,1,13.64,100,1,12.71,100,1,13.93,100,1,12.50,700,1,13.98,2,1,12.46,200,2,14.28,100,1,12.43,700,1,14.40,100,1,12.42,700,1,14.50,100,1,12.37,700,1,14.53,100,1,ARL,310447441
2025-07-17T15:50:26.983057675Z,2025-07-17T15:50:26.982892468Z,10,2,1108,C,A,0,15.78,100,130,165207,259847557,13.04,2,1,13.59,15,1,13.03,100,1,13.60,100,1,13.02,100,1,13.61,15,1,12.73,100,1,13.64,100,1,12.71,100,1,13.93,100,1,12.50,700,1,13.98,2,1,12.46,200,2,14.28,100,1,12.43,700,1,14.40,100,1,12.42,700,1,14.50,100,1,12.37,700,1,14.53,100,1,ARL,282776733
2025-07-17T15:50:30.046879569Z,2025-07-17T15:50:30.046714265Z,10,2,1108,C,A,0,13.59,15,130,165304,259916670,13.04,2,1,13.60,100,1,13.03,100,1,13.61,15,1,13.02,100,1,13.64,100,1,12.73,100,1,13.93,100,1,12.71,100,1,13.98,2,1,12.50,700,1,14.28,100,1,12.46,200,2,14.40,100,1,12.43,700,1,14.50,100,1,12.42,700,1,14.53,100,1,12.37,700,1,14.54,100,1,ARL,310424077
2025-07-17T15:50:30.047015114Z,2025-07-17T15:50:30.046849726Z,10,2,1108,C,A,0,13.61,15,130,165388,259916674,13.04,2,1,13.60,100,1,13.03,100,1,13.64,100,1,13.02,100,1,13.93,100,1,12.73,100,1,13.98,2,1,12.71,100,1,14.28,100,1,12.50,700,1,14.40,100,1,12.46,200,2,14.50,100,1,12.43,700,1,14.53,100,1,12.42,700,1,14.54,100,1,12.37,700,1,14.56,800,2,ARL,310030465
2025-07-17T15:51:37.986158330Z,2025-07-17T15:51:37.985992174Z,10,2,1108,C,A,0,13.98,2,0,166156,261130345,13.04,2,1,13.60,100,1,13.03,100,1,13.64,100,1,13.02,100,1,13.93,100,1,12.73,100,1,14.28,100,1,12.71,100,1,14.40,100,1,12.50,700,1,14.50,100,1,12.46,200,2,14.53,100,1,12.43,700,1,14.54,100,1,12.42,700,1,14.56,800,2,12.37,700,1,14.60,700,1,ARL,309091513
2025-07-17T15:51:37.986158330Z,2025-07-17T15:51:37.985992174Z,10,2,1108,A,A,0,13.89,2,130,166156,261130345,13.04,2,1,13.60,100,1,13.03,100,1,13.64,100,1,13.02,100,1,13.89,2,1,12.73,100,1,13.93,100,1,12.71,100,1,14.28,100,1,12.50,700,1,14.40,100,1,12.46,200,2,14.50,100,1,12.43,700,1,14.53,100,1,12.42,700,1,14.54,100,1,12.37,700,1,14.56,800,2,ARL,311979125
2025-07-17T15:52:16.371517839Z,2025-07-17T15:52:16.371351021Z,10,2,1108,T,N,0,13.41,58,0,166818,261713745,13.04,2,1,13.60,100,1,13.03,100,1,13.64,100,1,13.02,100,1,13.89,2,1,12.73,100,1,13.93,100,1,12.71,100,1,14.28,100,1,12.50,700,1,14.40,100,1,12.46,200,2,14.50,100,1,12.43,700,1,14.53,100,1,12.42,700,1,14.54,100,1,12.37,700,1,14.56,800,2,ARL,0
2025-07-17T15:52:16.371517839Z,2025-07-17T15:52:16.371351021Z,10,2,1108,T,N,0,13.28,12,130,166818,261713746,13.04,2,1,13.60,100,1,13.03,100,1,13.64,100,1,13.02,100,1,13.89,2,1,12.73,100,1,13.93,100,1,12.71,100,1,14.28,100,1,12.50,700,1,14.40,100,1,12.46,200,2,14.50,100,1,12.43,700,1,14.53,100,1,12.42,700,1,14.54,100,1,12.37,700,1,14.56,800,2,ARL,0
2025-07-17T15:52:16.372434625Z,2025-07-17T15:52:16.372269170Z,10,2,1108,C,A,0,13.60,100,130,165455,261713790,13.04,2,1,13.64,100,1,13.03,100,1,13.89,2,1,13.02,100,1,13.93,100,1,12.73,100,1,14.28,100,1,12.71,100,1,14.40,100,1,12.50,700,1,14.50,100,1,12.46,200,2,14.53,100,1,12.43,700,1,14.54,100,1,12.42,700,1,14.56,800,2,12.37,700,1,14.60,700,1,ARL,310446249
2025-07-17T15:52:16.373188791Z,2025-07-17T15:52:16.373023186Z,10,2,1108,C,A,0,14.65,100,0,165605,261713830,13.04,2,1,13.64,100,1,13.03,100,1,13.89,2,1,13.02,100,1,13.93,100,1,12.73,100,1,14.28,100,1,12.71,100,1,14.40,100,1,12.50,700,1,14.50,100,1,12.46,200,2,14.53,100,1,12.43,700,1,14.54,100,1,12.42,700,1,14.56,800,2,12.37,700,1,14.60,700,1,ARL,310446269
2025-07-17T15:52:16.373188791Z,2025-07-17T15:52:16.373023186Z,10,2,1108,A,A,0,14.70,100,130,165605,261713830,13.04,2,1,13.64,100,1,13.03,100,1,13.89,2,1,13.02,100,1,13.93,100,1,12.73,100,1,14.28,100,1,12.71,100,1,14.40,100,1,12.50,700,1,14.50,100,1,12.46,200,2,14.53,100,1,12.43,700,1,14.54,100,1,12.42,700,1,14.56,800,2,12.37,700,1,14.60,700,1,ARL,312771573
2025-07-17T15:52:16.374353159Z,2025-07-17T15:52:16.374186508Z,10,2,1108,C,A,0,13.64,100,130,166651,261713870,13.04,2,1,13.89,2,1,13.03,100,1,13.93,100,1,13.02,100,1,14.28,100,1,12.73,100,1,14.40,100,1,12.71,100,1,14.50,100,1,12.50,700,1,14.53,100,1,12.46,200,2,14.54,100,1,12.43,700,1,14.56,800,2,12.42,700,1,14.60,700,1,12.37,700,1,14.66,200,2,ARL,310031625
2025-07-17T15:52:16.374480183Z,2025-07-17T15:52:16.374312976Z,10,2,1108,A,A,0,15.86,100,128,167207,261713880,13.04,2,1,13.89,2,1,13.03,100,1,13.93,100,1,13.02,100,1,14.28,100,1,12.73,100,1,14.40,100,1,12.71,100,1,14.50,100,1,12.50,700,1,14.53,100,1,12.46,200,2,14.54,100,1,12.43,700,1,14.56,800,2,12.42,700,1,14.60,700,1,12.37,700,1,14.66,200,2,ARL,312771645
2025-07-17T15:52:16.374493650Z,2025-07-17T15:52:16.374327668Z,10,2,1108,C,A,0,15.51,100,130,165982,261713884,13.04,2,1,13.89,2,1,13.03,100,1,13.93,100,1,13.02,100,1,14.28,100,1,12.73,100,1,14.40,100,1,12.71,100,1,14.50,100,1,12.50,700,1,14.53,100,1,12.46,200,2,14.54,100,1,12.43,700,1,14.56,800,2,12.42,700,1,14.60,700,1,12.37,700,1,14.66,200,2,ARL,310447441
2025-07-17T15:52:16.375388285Z,2025-07-17T15:52:16.375222836Z,10,2,1108,C,A,0,14.54,100,0,165449,261713944,13.04,2,1,13.89,2,1,13.03,100,1,13.93,100,1,13.02,100,1,14.28,100,1,12.73,100,1,14.40,100,1,12.71,100,1,14.50,100,1,12.50,700,1,14.53,100,1,12.46,200,2,14.56,800,2,12.43,700,1,14.60,700,1,12.42,700,1,14.66,200,2,12.37,700,1,14.68,1400,2,ARL,309823025
2025-07-17T15:52:16.375388285Z,2025-07-17T15:52:16.375222836Z,10,2,1108,A,A,0,14.81,100,130,165449,261713944,13.04,2,1,13.89,2,1,13.03,100,1,13.93,100,1,13.02,100,1,14.28,100,1,12.73,100,1,14.40,100,1,12.71,100,1,14.50,100,1,12.50,700,1,14.53,100,1,12.46,200,2,14.56,800,2,12.43,700,1,14.60,700,1,12.42,700,1,14.66,200,2,12.37,700,1,14.68,1400,2,ARL,312771781
2025-07-17T15:52:16.375414247Z,2025-07-17T15:52:16.375248654Z,10,2,1108,C,A,0,14.66,100,0,165593,261713945,13.04,2,1,13.89,2,1,13.03,100,1,13.93,100,1,13.02,100,1,14.28,100,1,12.73,100,1,14.40,100,1,12.71,100,1,14.50,100,1,12.50,700,1,14.53,100,1,12.46,200,2,14.56,800,2,12.43,700,1,14.60,700,1,12.42,700,1,14.66,100,1,12.37,700,1,14.68,1400,2,ARL,308901981
2025-07-17T15:52:16.375414247Z,2025-07-17T15:52:16.375248654Z,10,2,1108,A,A,0,14.89,100,130,165593,261713945,13.04,2,1,13.89,2,1,13.03,100,1,13.93,100,1,13.02,100,1,14.28,100,1,12.73,100,1,14.40,100,1,12.71,100,1,14.50,100,1,12.50,700,1,14.53,100,1,12.46,200,2,14.56,800,2,12.43,700,1,14.60,700,1,12.42,700,1,14.66,100,1,12.37,700,1,14.68,1400,2,ARL,312771785
2025-07-17T15:52:16.375828154Z,2025-07-17T15:52:16.375662552Z,10,2,1108,C,A,0,14.53,100,0,165602,261713959,13.04,2,1,13.89,2,1,13.03,100,1,13.93,100,1,13.02,100,1,14.28,100,1,12.73,100,1,14.40,100,1,12.71,100,1,14.50,100,1,12.50,700,1,14.56,800,2,12.46,200,2,14.60,700,1,12.43,700,1,14.66,100,1,12.42,700,1,14.68,1400,2,12.37,700,1,14.70,100,1,ARL,309899141
2025-07-17T15:52:16.375828154Z,2025-07-17T15:52:16.375662552Z,10,2,1108,A,A,0,14.76,100,130,165602,261713959,13.04,2,1,13.89,2,1,13.03,100,1,13.93,100,1,13.02,100,1,14.28,100,1,12.73,100,1,14.40,100,1,12.71,100,1,14.50,100,1,12.50,700,1,14.56,800,2,12.46,200,2,14.60,700,1,12.43,700,1,14.66,100,1,12.42,700,1,14.68,1400,2,12.37,700,1,14.70,100,1,ARL,312771829
2025-07-17T15:52:16.377345053Z,2025-07-17T15:52:16.377179230Z,10,2,1108,C,A,0,17.28,100,0,165823,261714104,13.04,2,1,13.89,2,1,13.03,100,1,13.93,100,1,13.02,100,1,14.28,100,1,12.73,100,1,14.40,100,1,12.71,100,1,14.50,100,1,12.50,700,1,14.56,800,2,12.46,200,2,14.60,700,1,12.43,700,1,14.66,100,1,12.42,700,1,14.68,1400,2,12.37,700,1,14.70,100,1,ARL,310446293
2025-07-17T15:52:16.377345053Z,2025-07-17T15:52:16.377179230Z,10,2,1108,A,A,0,17.70,100,130,165823,261714104,13.04,2,1,13.89,2,1,13.03,100,1,13.93,100,1,13.02,100,1,14.28,100,1,12.73,100,1,14.40,100,1,12.71,100,1,14.50,100,1,12.50,700,1,14.56,800,2,12.46,200,2,14.60,700,1,12.43,700,1,14.66,100,1,12.42,700,1,14.68,1400,2,12.37,700,1,14.70,100,1,ARL,312772009
2025-07-17T15:52:16.378239114Z,2025-07-17T15:52:16.378073674Z,10,2,1108,C,A,0,15.76,100,0,165440,261714140,13.04,2,1,13.89,2,1,13.03,100,1,13.93,100,1,13.02,100,1,14.28,100,1,12.73,100,1,14.40,100,1,12.71,100,1,14.50,100,1,12.50,700,1,14.56,800,2,12.46,200,2,14.60,700,1,12.43,700,1,14.66,100,1,12.42,700,1,14.68,1400,2,12.37,700,1,14.70,100,1,ARL,308902229
2025-07-17T15:52:16.378239114Z,2025-07-17T15:52:16.378073674Z,10,2,1108,A,A,0,16.02,100,130,165440,261714140,13.04,2,1,13.89,2,1,13.03,100,1,13.93,100,1,13.02,100,1,14.28,100,1,12.73,100,1,14.40,100,1,12.71,100,1,14.50,100,1,12.50,700,1,14.56,800,2,12.46,200,2,14.60,700,1,12.43,700,1,14.66,100,1,12.42,700,1,14.68,1400,2,12.37,700,1,14.70,100,1,ARL,312772057
2025-07-17T15:52:16.378385943Z,2025-07-17T15:52:16.378220434Z,10,2,1108,C,A,0,14.50,100,0,165509,261714145,13.04,2,1,13.89,2,1,13.03,100,1,13.93,100,1,13.02,100,1,14.28,100,1,12.73,100,1,14.40,100,1,12.71,100,1,14.56,800,2,12.50,700,1,14.60,700,1,12.46,200,2,14.66,100,1,12.43,700,1,14.68,1400,2,12.42,700,1,14.70,100,1,12.37,700,1,14.76,100,1,ARL,308903349
2025-07-17T15:52:16.378385943Z,2025-07-17T15:52:16.378220434Z,10,2,1108,A,A,0,14.72,100,130,165509,261714145,13.04,2,1,13.89,2,1,13.03,100,1,13.93,100,1,13.02,100,1,14.28,100,1,12.73,100,1,14.40,100,1,12.71,100,1,14.56,800,2,12.50,700,1,14.60,700,1,12.46,200,2,14.66,100,1,12.43,700,1,14.68,1400,2,12.42,700,1,14.70,100,1,12.37,700,1,14.72,100,1,ARL,312772061
2025-07-17T15:52:16.378870638Z,2025-07-17T15:52:16.378705201Z,10,2,1108,A,B,0,13.27,10,130,165437,261714171,13.27,10,1,13.89,2,1,13.04,2,1,13.93,100,1,13.03,100,1,14.28,100,1,13.02,100,1,14.40,100,1,12.73,100,1,14.56,800,2,12.71,100,1,14.60,700,1,12.50,700,1,14.66,100,1,12.46,200,2,14.68,1400,2,12.43,700,1,14.70,100,1,12.42,700,1,14.72,100,1,ARL,312772069
2025-07-17T15:52:16.378872385Z,2025-07-17T15:52:16.378707041Z,10,2,1108,A,A,0,13.86,15,130,165344,261714172,13.27,10,1,13.86,15,1,13.04,2,1,13.89,2,1,13.03,100,1,13.93,100,1,13.02,100,1,14.28,100,1,12.73,100,1,14.40,100,1,12.71,100,1,14.56,800,2,12.50,700,1,14.60,700,1,12.46,200,2,14.66,100,1,12.43,700,1,14.68,1400,2,12.42,700,1,14.70,100,1,ARL,312772073
2025-07-17T15:52:16.379127782Z,2025-07-17T15:52:16.378962330Z,10,2,1108,C,B,0,13.02,100,0,165452,261714185,13.27,10,1,13.86,15,1,13.04,2,1,13.89,2,1,13.03,100,1,13.93,100,1,12.73,100,1,14.28,100,1,12.71,100,1,14.40,100,1,12.50,700,1,14.56,800,2,12.46,200,2,14.60,700,1,12.43,700,1,14.66,100,1,12.42,700,1,14.68,1400,2,12.37,700,1,14.70,100,1,ARL,309415429
2025-07-17T15:52:16.379127782Z,2025-07-17T15:52:16.378962330Z,10,2,1108,A,B,0,13.26,100,130,165452,261714185,13.27,10,1,13.86,15,1,13.26,100,1,13.89,2,1,13.04,2,1,13.93,100,1,13.03,100,1,14.28,100,1,12.73,100,1,14.40,100,1,12.71,100,1,14.56,800,2,12.50,700,1,14.60,700,1,12.46,200,2,14.66,100,1,12.43,700,1,14.68,1400,2,12.42,700,1,14.70,100,1,ARL,312772077
2025-07-17T15:52:16.389025469Z,2025-07-17T15:52:16.388859982Z,10,2,1108,C,A,0,13.93,100,130,165487,261714477,13.27,10,1,13.86,15,1,13.26,100,1,13.89,2,1,13.04,2,1,14.28,100,1,13.03,100,1,14.40,100,1,12.73,100,1,14.56,800,2,12.71,100,1,14.60,700,1,12.50,700,1,14.66,100,1,12.46,200,2,14.68,1400,2,12.43,700,1,14.70,100,1,12.42,700,1,14.72,100,1,ARL,309782973
2025-07-17T15:52:16.389082451Z,2025-07-17T15:52:16.388917108Z,10,2,1108,A,A,0,14.19,100,130,165343,261714481,13.27,10,1,13.86,15,1,13.26,100,1,13.89,2,1,13.04,2,1,14.19,100,1,13.03,100,1,14.28,100,1,12.73,100,1,14.40,100,1,12.71,100,1,14.56,800,2,12.50,700,1,14.60,700,1,12.46,200,2,14.66,100,1,12.43,700,1,14.68,1400,2,12.42,700,1,14.70,100,1,ARL,312772501
2025-07-17T15:52:16.396174502Z,2025-07-17T15:52:16.396008715Z,10,2,1108,C,A,0,14.66,100,0,165787,261714603,13.27,10,1,13.86,15,1,13.26,100,1,13.89,2,1,13.04,2,1,14.19,100,1,13.03,100,1,14.28,100,1,12.73,100,1,14.40,100,1,12.71,100,1,14.56,800,2,12.50,700,1,14.60,700,1,12.46,200,2,14.68,1400,2,12.43,700,1,14.70,100,1,12.42,700,1,14.72,100,1,ARL,308903001
2025-07-17T15:52:16.396174502Z,2025-07-17T15:52:16.396008715Z,10,2,1108,A,A,0,14.96,100,130,165787,261714603,13.27,10,1,13.86,15,1,13.26,100,1,13.89,2,1,13.04,2,1,14.19,100,1,13.03,100,1,14.28,100,1,12.73,100,1,14.40,100,1,12.71,100,1,14.56,800,2,12.50,700,1,14.60,700,1,12.46,200,2,14.68,1400,2,12.43,700,1,14.70,100,1,12.42,700,1,14.72,100,1,ARL,312772869
2025-07-17T15:52:16.397677681Z,2025-07-17T15:52:16.397512710Z,10,2,1108,C,A,0,14.19,100,130,164971,261714619,13.27,10,1,13.86,15,1,13.26,100,1,13.89,2,1,13.04,2,1,14.28,100,1,13.03,100,1,14.40,100,1,12.73,100,1,14.56,800,2,12.71,100,1,14.60,700,1,12.50,700,1,14.68,1400,2,12.46,200,2,14.70,100,1,12.43,700,1,14.72,100,1,12.42,700,1,14.76,100,1,ARL,312772501
2025-07-17T15:52:16.397727042Z,2025-07-17T15:52:16.397561691Z,10,2,1108,A,A,0,14.26,100,130,165351,261714620,13.27,10,1,13.86,15,1,13.26,100,1,13.89,2,1,13.04,2,1,14.26,100,1,13.03,100,1,14.28,100,1,12.73,100,1,14.40,100,1,12.71,100,1,14.56,800,2,12.50,700,1,14.60,700,1,12.46,200,2,14.68,1400,2,12.43,700,1,14.70,100,1,12.42,700,1,14.72,100,1,ARL,312772901
2025-07-17T15:52:16.424137423Z,2025-07-17T15:52:16.423972000Z,10,2,1108,C,A,0,14.70,100,0,165423,261714976,13.27,10,1,13.86,15,1,13.26,100,1,13.89,2,1,13.04,2,1,14.26,100,1,13.03,100,1,14.28,100,1,12.73,100,1,14.40,100,1,12.71,100,1,14.56,800,2,12.50,700,1,14.60,700,1,12.46,200,2,14.68,1400,2,12.43,700,1,14.72,100,1,12.42,700,1,14.76,100,1,ARL,312771573
2025-07-17T15:52:16.424137423Z,2025-07-17T15:52:16.423972000Z,10,2,1108,A,A,0,15.06,100,130,165423,261714976,13.27,10,1,13.86,15,1,13.26,100,1,13.89,2,1,13.04,2,1,14.26,100,1,13.03,100,1,14.28,100,1,12.73,100,1,14.40,100,1,12.71,100,1,14.56,800,2,12.50,700,1,14.60,700,1,12.46,200,2,14.68,1400,2,12.43,700,1,14.72,100,1,12.42,700,1,14.76,100,1,ARL,312773353
2025-07-17T15:52:16.464781343Z,2025-07-17T15:52:16.464616142Z,10,2,1108,A,A,0,13.87,100,130,165201,261715303,13.27,10,1,13.86,15,1,13.26,100,1,13.87,100,1,13.04,2,1,13.89,2,1,13.03,100,1,14.26,100,1,12.73,100,1,14.28,100,1,12.71,100,1,14.40,100,1,12.50,700,1,14.56,800,2,12.46,200,2,14.60,700,1,12.43,700,1,14.68,1400,2,12.42,700,1,14.72,100,1,ARL,312773881
2025-07-17T15:52:16.473556948Z,2025-07-17T15:52:16.473391480Z,10,2,1108,C,A,0,15.06,100,0,165468,261715409,13.27,10,1,13.86,15,1,13.26,100,1,13.87,100,1,13.04,2,1,13.89,2,1,13.03,100,1,14.26,100,1,12.73,100,1,14.28,100,1,12.71,100,1,14.40,100,1,12.50,700,1,14.56,800,2,12.46,200,2,14.60,700,1,12.43,700,1,14.68,1400,2,12.42,700,1,14.72,100,1,ARL,312773353
2025-07-17T15:52:16.473556948Z,2025-07-17T15:52:16.473391480Z,10,2,1108,A,A,0,14.95,100,130,165468,261715409,13.27,10,1,13.86,15,1,13.26,100,1,13.87,100,1,13.04,2,1,13.89,2,1,13.03,100,1,14.26,100,1,12.73,100,1,14.28,100,1,12.71,100,1,14.40,100,1,12.50,700,1,14.56,800,2,12.46,200,2,14.60,700,1,12.43,700,1,14.68,1400,2,12.42,700,1,14.72,100,1,ARL,312774001
2025-07-17T15:52:16.480090894Z,2025-07-17T15:52:16.479925781Z,10,2,1108,C,A,0,14.26,100,130,165113,261715467,13.27,10,1,13.86,15,1,13.26,100,1,13.87,100,1,13.04,2,1,13.89,2,1,13.03,100,1,14.28,100,1,12.73,100,1,14.40,100,1,12.71,100,1,14.56,800,2,12.50,700,1,14.60,700,1,12.46,200,2,14.68,1400,2,12.43,700,1,14.72,100,1,12.42,700,1,14.76,100,1,ARL,312772901
2025-07-17T15:52:16.480140131Z,2025-07-17T15:52:16.479974840Z,10,2,1108,A,A,0,14.15,100,130,165291,261715468,13.27,10,1,13.86,15,1,13.26,100,1,13.87,100,1,13.04,2,1,13.89,2,1,13.03,100,1,14.15,100,1,12.73,100,1,14.28,100,1,12.71,100,1,14.40,100,1,12.50,700,1,14.56,800,2,12.46,200,2,14.60,700,1,12.43,700,1,14.68,1400,2,12.42,700,1,14.72,100,1,ARL,312774033
2025-07-17T15:52:28.787316865Z,2025-07-17T15:52:28.787151494Z,10,2,1108,C,B,0,13.27,10,130,165371,261883294,13.26,100,1,13.86,15,1,13.04,2,1,13.87,100,1,13.03,100,1,13.89,2,1,12.73,100,1,14.15,100,1,12.71,100,1,14.28,100,1,12.50,700,1,14.40,100,1,12.46,200,2,14.56,800,2,12.43,700,1,14.60,700,1,12.42,700,1,14.68,1400,2,12.37,700,1,14.72,100,1,ARL,312772069
2025-07-17T15:52:28.787317827Z,2025-07-17T15:52:28.787152437Z,10,2,1108,C,A,0,13.86,15,130,165390,261883295,13.26,100,1,13.87,100,1,13.04,2,1,13.89,2,1,13.03,100,1,14.15,100,1,12.73,100,1,14.28,100,1,12.71,100,1,14.40,100,1,12.50,700,1,14.56,800,2,12.46,200,2,14.60,700,1,12.43,700,1,14.68,1400,2,12.42,700,1,14.72,100,1,12.37,700,1,14.76,100,1,ARL,312772073
2025-07-17T15:52:43.128371033Z,2025-07-17T15:52:43.128203357Z,10,2,1108,C,A,0,13.89,2,0,167676,262115170,13.26,100,1,13.87,100,1,13.04,2,1,14.15,100,1,13.03,100,1,14.28,100,1,12.73,100,1,14.40,100,1,12.71,100,1,14.56,800,2,12.50,700,1,14.60,700,1,12.46,200,2,14.68,1400,2,12.43,700,1,14.72,100,1,12.42,700,1,14.76,100,1,12.37,700,1,14.81,100,1,ARL,311979125
2025-07-17T15:52:43.128371033Z,2025-07-17T15:52:43.128203357Z,10,2,1108,A,A,0,13.99,2,128,167676,262115170,13.26,100,1,13.87,100,1,13.04,2,1,13.99,2,1,13.03,100,1,14.15,100,1,12.73,100,1,14.28,100,1,12.71,100,1,14.40,100,1,12.50,700,1,14.56,800,2,12.46,200,2,14.60,700,1,12.43,700,1,14.68,1400,2,12.42,700,1,14.72,100,1,12.37,700,1,14.76,100,1,ARL,313336713
2025-07-17T15:54:24.908483782Z,2025-07-17T15:54:24.908318259Z,10,2,1108,A,B,0,13.29,10,130,165523,263863872,13.29,10,1,13.87,100,1,13.26,100,1,13.99,2,1,13.04,2,1,14.15,100,1,13.03,100,1,14.28,100,1,12.73,100,1,14.40,100,1,12.71,100,1,14.56,800,2,12.50,700,1,14.60,700,1,12.46,200,2,14.68,1400,2,12.43,700,1,14.72,100,1,12.42,700,1,14.76,100,1,ARL,315581981
2025-07-17T15:54:26.792478456Z,2025-07-17T15:54:26.792313320Z,10,2,1108,C,B,0,13.29,10,130,165136,263895481,13.26,100,1,13.87,100,1,13.04,2,1,13.99,2,1,13.03,100,1,14.15,100,1,12.73,100,1,14.28,100,1,12.71,100,1,14.40,100,1,12.50,700,1,14.56,800,2,12.46,200,2,14.60,700,1,12.43,700,1,14.68,1400,2,12.42,700,1,14.72,100,1,12.37,700,1,14.76,100,1,ARL,315581981
2025-07-17T15:54:52.986116083Z,2025-07-17T15:54:52.985950259Z,10,2,1108,C,A,0,13.99,2,0,165824,264262615,13.26,100,1,13.87,100,1,13.04,2,1,14.15,100,1,13.03,100,1,14.28,100,1,12.73,100,1,14.40,100,1,12.71,100,1,14.56,800,2,12.50,700,1,14.60,700,1,12.46,200,2,14.68,1400,2,12.43,700,1,14.72,100,1,12.42,700,1,14.76,100,1,12.37,700,1,14.81,100,1,ARL,313336713
2025-07-17T15:54:52.986116083Z,2025-07-17T15:54:52.985950259Z,10,2,1108,A,A,0,14.10,2,130,165824,264262615,13.26,100,1,13.87,100,1,13.04,2,1,14.10,2,1,13.03,100,1,14.15,100,1,12.73,100,1,14.28,100,1,12.71,100,1,14.40,100,1,12.50,700,1,14.56,800,2,12.46,200,2,14.60,700,1,12.43,700,1,14.68,1400,2,12.42,700,1,14.72,100,1,12.37,700,1,14.76,100,1,ARL,316098525
2025-07-17T15:55:33.673598252Z,2025-07-17T15:55:33.673432762Z,10,2,1108,A,B,0,13.29,10,130,165490,264905534,13.29,10,1,13.87,100,1,13.26,100,1,14.10,2,1,13.04,2,1,14.15,100,1,13.03,100,1,14.28,100,1,12.73,100,1,14.40,100,1,12.71,100,1,14.56,800,2,12.50,700,1,14.60,700,1,12.46,200,2,14.68,1400,2,12.43,700,1,14.72,100,1,12.42,700,1,14.76,100,1,ARL,316911465
2025-07-17T15:55:34.257417204Z,2025-07-17T15:55:34.257251787Z,10,2,1108,C,B,0,13.26,100,0,165417,264919835,13.29,10,1,13.87,100,1,13.04,2,1,14.10,2,1,13.03,100,1,14.15,100,1,12.73,100,1,14.28,100,1,12.71,100,1,14.40,100,1,12.50,700,1,14.56,800,2,12.46,200,2,14.60,700,1,12.43,700,1,14.68,1400,2,12.42,700,1,14.72,100,1,12.37,700,1,14.76,100,1,ARL,312772077
2025-07-17T15:55:34.257417204Z,2025-07-17T15:55:34.257251787Z,10,2,1108,A,B,0,13.28,100,130,165417,264919835,13.29,10,1,13.87,100,1,13.28,100,1,14.10,2,1,13.04,2,1,14.15,100,1,13.03,100,1,14.28,100,1,12.73,100,1,14.40,100,1,12.71,100,1,14.56,800,2,12.50,700,1,14.60,700,1,12.46,200,2,14.68,1400,2,12.43,700,1,14.72,100,1,12.42,700,1,14.76,100,1,ARL,316924721
2025-07-17T15:55:40.197750400Z,2025-07-17T15:55:40.197584524Z,10,2,1108,C,B,0,13.29,10,130,165876,265015966,13.28,100,1,13.87,100,1,13.04,2,1,14.10,2,1,13.03,100,1,14.15,100,1,12.73,100,1,14.28,100,1,12.71,100,1,14.40,100,1,12.50,700,1,14.56,800,2,12.46,200,2,14.60,700,1,12.43,700,1,14.68,1400,2,12.42,700,1,14.72,100,1,12.37,700,1,14.76,100,1,ARL,316911465
2025-07-17T15:57:51.111288955Z,2025-07-17T15:57:51.111121910Z,10,2,1108,T,N,0,13.60,1,0,167045,267268162,13.28,100,1,13.87,100,1,13.04,2,1,14.10,2,1,13.03,100,1,14.15,100,1,12.73,100,1,14.28,100,1,12.71,100,1,14.40,100,1,12.50,700,1,14.56,800,2,12.46,200,2,14.60,700,1,12.43,700,1,14.68,1400,2,12.42,700,1,14.72,100,1,12.37,700,1,14.76,100,1,ARL,0
2025-07-17T15:57:51.111288955Z,2025-07-17T15:57:51.111121910Z,10,2,1108,T,N,0,13.57,99,130,167045,267268163,13.28,100,1,13.87,100,1,13.04,2,1,14.10,2,1,13.03,100,1,14.15,100,1,12.73,100,1,14.28,100,1,12.71,100,1,14.40,100,1,12.50,700,1,14.56,800,2,12.46,200,2,14.60,700,1,12.43,700,1,14.68,1400,2,12.42,700,1,14.72,100,1,12.37,700,1,14.76,100,1,ARL,0
2025-07-17T15:57:51.111693755Z,2025-07-17T15:57:51.111527963Z,10,2,1108,T,N,0,13.57,100,130,165792,267268168,13.28,100,1,13.87,100,1,13.04,2,1,14.10,2,1,13.03,100,1,14.15,100,1,12.73,100,1,14.28,100,1,12.71,100,1,14.40,100,1,12.50,700,1,14.56,800,2,12.46,200,2,14.60,700,1,12.43,700,1,14.68,1400,2,12.42,700,1,14.72,100,1,12.37,700,1,14.76,100,1,ARL,0
2025-07-17T15:57:51.112077532Z,2025-07-17T15:57:51.111911476Z,10,2,1108,T,N,0,13.57,1,130,166056,267268183,13.28,100,1,13.87,100,1,13.04,2,1,14.10,2,1,13.03,100,1,14.15,100,1,12.73,100,1,14.28,100,1,12.71,100,1,14.40,100,1,12.50,700,1,14.56,800,2,12.46,200,2,14.60,700,1,12.43,700,1,14.68,1400,2,12.42,700,1,14.72,100,1,12.37,700,1,14.76,100,1,ARL,0
2025-07-17T15:57:51.328863560Z,2025-07-17T15:57:51.328698198Z,10,2,1108,C,A,0,13.87,100,130,165362,267272430,13.28,100,1,14.10,2,1,13.04,2,1,14.15,100,1,13.03,100,1,14.28,100,1,12.73,100,1,14.40,100,1,12.71,100,1,14.56,800,2,12.50,700,1,14.60,700,1,12.46,200,2,14.68,1400,2,12.43,700,1,14.72,100,1,12.42,700,1,14.76,100,1,12.37,700,1,14.81,100,1,ARL,312773881
2025-07-17T15:57:51.329613584Z,2025-07-17T15:57:51.329447325Z,10,2,1108,C,A,0,14.95,100,0,166259,267272438,13.28,100,1,14.10,2,1,13.04,2,1,14.15,100,1,13.03,100,1,14.28,100,1,12.73,100,1,14.40,100,1,12.71,100,1,14.56,800,2,12.50,700,1,14.60,700,1,12.46,200,2,14.68,1400,2,12.43,700,1,14.72,100,1,12.42,700,1,14.76,100,1,12.37,700,1,14.81,100,1,ARL,312774001
2025-07-17T15:57:51.329613584Z,2025-07-17T15:57:51.329447325Z,10,2,1108,A,A,0,15.00,100,130,166259,267272438,13.28,100,1,14.10,2,1,13.04,2,1,14.15,100,1,13.03,100,1,14.28,100,1,12.73,100,1,14.40,100,1,12.71,100,1,14.56,800,2,12.50,700,1,14.60,700,1,12.46,200,2,14.68,1400,2,12.43,700,1,14.72,100,1,12.42,700,1,14.76,100,1,12.37,700,1,14.81,100,1,ARL,319985021
2025-07-17T15:57:51.329857672Z,2025-07-17T15:57:51.329692071Z,10,2,1108,C,A,0,14.76,100,0,165601,267272442,13.28,100,1,14.10,2,1,13.04,2,1,14.15,100,1,13.03,100,1,14.28,100,1,12.73,100,1,14.40,100,1,12.71,100,1,14.56,800,2,12.50,700,1,14.60,700,1,12.46,200,2,14.68,1400,2,12.43,700,1,14.72,100,1,12.42,700,1,14.81,100,1,12.37,700,1,14.89,100,1,ARL,312771829
2025-07-17T15:57:51.329857672Z,2025-07-17T15:57:51.329692071Z,10,2,1108,A,A,0,14.89,100,130,165601,267272442,13.28,100,1,14.10,2,1,13.04,2,1,14.15,100,1,13.03,100,1,14.28,100,1,12.73,100,1,14.40,100,1,12.71,100,1,14.56,800,2,12.50,700,1,14.60,700,1,12.46,200,2,14.68,1400,2,12.43,700,1,14.72,100,1,12.42,700,1,14.81,100,1,12.37,700,1,14.89,200,2,ARL,319985025
2025-07-17T15:57:51.339328219Z,2025-07-17T15:57:51.339162512Z,10,2,1108,C,A,0,14.15,100,130,165707,267272660,13.28,100,1,14.10,2,1,13.04,2,1,14.28,100,1,13.03,100,1,14.40,100,1,12.73,100,1,14.56,800,2,12.71,100,1,14.60,700,1,12.50,700,1,14.68,1400,2,12.46,200,2,14.72,100,1,12.43,700,1,14.81,100,1,12.42,700,1,14.89,200,2,12.37,700,1,14.96,100,1,ARL,312774033
2025-07-17T15:57:51.339382098Z,2025-07-17T15:57:51.339216923Z,10,2,1108,A,A,0,14.26,100,130,165175,267272665,13.28,100,1,14.10,2,1,13.04,2,1,14.26,100,1,13.03,100,1,14.28,100,1,12.73,100,1,14.40,100,1,12.71,100,1,14.56,800,2,12.50,700,1,14.60,700,1,12.46,200,2,14.68,1400,2,12.43,700,1,14.72,100,1,12.42,700,1,14.81,100,1,12.37,700,1,14.89,200,2,ARL,319985165
2025-07-17T15:57:51.379736852Z,2025-07-17T15:57:51.379570470Z,10,2,1108,C,A,0,15.00,100,0,166382,267273071,13.28,100,1,14.10,2,1,13.04,2,1,14.26,100,1,13.03,100,1,14.28,100,1,12.73,100,1,14.40,100,1,12.71,100,1,14.56,800,2,12.50,700,1,14.60,700,1,12.46,200,2,14.68,1400,2,12.43,700,1,14.72,100,1,12.42,700,1,14.81,100,1,12.37,700,1,14.89,200,2,ARL,319985021
2025-07-17T15:57:51.379736852Z,2025-07-17T15:57:51.379570470Z,10,2,1108,A,A,0,15.06,100,128,166382,267273071,13.28,100,1,14.10,2,1,13.04,2,1,14.26,100,1,13.03,100,1,14.28,100,1,12.73,100,1,14.40,100,1,12.71,100,1,14.56,800,2,12.50,700,1,14.60,700,1,12.46,200,2,14.68,1400,2,12.43,700,1,14.72,100,1,12.42,700,1,14.81,100,1,12.37,700,1,14.89,200,2,ARL,319985497
2025-07-17T15:57:52.378369524Z,2025-07-17T15:57:52.378204338Z,10,2,1108,A,A,0,14.11,100,130,165186,267283873,13.28,100,1,14.10,2,1,13.04,2,1,14.11,100,1,13.03,100,1,14.26,100,1,12.73,100,1,14.28,100,1,12.71,100,1,14.40,100,1,12.50,700,1,14.56,800,2,12.46,200,2,14.60,700,1,12.43,700,1,14.68,1400,2,12.42,700,1,14.72,100,1,12.37,700,1,14.81,100,1,ARL,320000233
2025-07-17T15:58:14.483879079Z,2025-07-17T15:58:14.483712278Z,10,2,1108,T,N,0,13.41,44,130,166801,267657010,13.28,100,1,14.10,2,1,13.04,2,1,14.11,100,1,13.03,100,1,14.26,100,1,12.73,100,1,14.28,100,1,12.71,100,1,14.40,100,1,12.50,700,1,14.56,800,2,12.46,200,2,14.60,700,1,12.43,700,1,14.68,1400,2,12.42,700,1,14.72,100,1,12.37,700,1,14.81,100,1,ARL,0
2025-07-17T15:58:14.483909354Z,2025-07-17T15:58:14.483743947Z,10,2,1108,A,A,0,13.76,4,130,165407,267657011,13.28,100,1,13.76,4,1,13.04,2,1,14.10,2,1,13.03,100,1,14.11,100,1,12.73,100,1,14.26,100,1,12.71,100,1,14.28,100,1,12.50,700,1,14.40,100,1,12.46,200,2,14.56,800,2,12.43,700,1,14.60,700,1,12.42,700,1,14.68,1400,2,12.37,700,1,14.72,100,1,ARL,320484625
2025-07-17T15:58:14.484164551Z,2025-07-17T15:58:14.483999049Z,10,2,1108,C,A,0,14.11,100,0,165502,267657013,13.28,100,1,13.76,4,1,13.04,2,1,14.10,2,1,13.03,100,1,14.26,100,1,12.73,100,1,14.28,100,1,12.71,100,1,14.40,100,1,12.50,700,1,14.56,800,2,12.46,200,2,14.60,700,1,12.43,700,1,14.68,1400,2,12.42,700,1,14.72,100,1,12.37,700,1,14.81,100,1,ARL,320000233
2025-07-17T15:58:14.484164551Z,2025-07-17T15:58:14.483999049Z,10,2,1108,A,A,0,13.77,100,130,165502,267657013,13.28,100,1,13.76,4,1,13.04,2,1,13.77,100,1,13.03,100,1,14.10,2,1,12.73,100,1,14.26,100,1,12.71,100,1,14.28,100,1,12.50,700,1,14.40,100,1,12.46,200,2,14.56,800,2,12.43,700,1,14.60,700,1,12.42,700,1,14.68,1400,2,12.37,700,1,14.72,100,1,ARL,320484637
2025-07-17T15:58:14.484183413Z,2025-07-17T15:58:14.484017806Z,10,2,1108,C,B,0,13.28,100,130,165607,267657014,13.04,2,1,13.76,4,1,13.03,100,1,13.77,100,1,12.73,100,1,14.10,2,1,12.71,100,1,14.26,100,1,12.50,700,1,14.28,100,1,12.46,200,2,14.40,100,1,12.43,700,1,14.56,800,2,12.42,700,1,14.60,700,1,12.37,700,1,14.68,1400,2,12.36,200,2,14.72,100,1,ARL,316924721
2025-07-17T15:58:14.484299450Z,2025-07-17T15:58:14.484133730Z,10,2,1108,T,N,0,13.41,8,130,165720,267657017,13.04,2,1,13.76,4,1,13.03,100,1,13.77,100,1,12.73,100,1,14.10,2,1,12.71,100,1,14.26,100,1,12.50,700,1,14.28,100,1,12.46,200,2,14.40,100,1,12.43,700,1,14.56,800,2,12.42,700,1,14.60,700,1,12.37,700,1,14.68,1400,2,12.36,200,2,14.72,100,1,ARL,0
2025-07-17T15:58:14.484312532Z,2025-07-17T15:58:14.484147359Z,10,2,1108,A,A,0,13.79,100,130,165173,267657020,13.04,2,1,13.76,4,1,13.03,100,1,13.77,100,1,12.73,100,1,13.79,100,1,12.71,100,1,14.10,2,1,12.50,700,1,14.26,100,1,12.46,200,2,14.28,100,1,12.43,700,1,14.40,100,1,12.42,700,1,14.56,800,2,12.37,700,1,14.60,700,1,12.36,200,2,14.68,1400,2,ARL,320484661
2025-07-17T15:58:14.484902175Z,2025-07-17T15:58:14.484736787Z,10,2,1108,C,A,0,15.06,100,0,165388,267657063,13.04,2,1,13.76,4,1,13.03,100,1,13.77,100,1,12.73,100,1,13.79,100,1,12.71,100,1,14.10,2,1,12.50,700,1,14.26,100,1,12.46,200,2,14.28,100,1,12.43,700,1,14.40,100,1,12.42,700,1,14.56,800,2,12.37,700,1,14.60,700,1,12.36,200,2,14.68,1400,2,ARL,319985497
2025-07-17T15:58:14.484902175Z,2025-07-17T15:58:14.484736787Z,10,2,1108,A,A,0,14.84,100,130,165388,267657063,13.04,2,1,13.76,4,1,13.03,100,1,13.77,100,1,12.73,100,1,13.79,100,1,12.71,100,1,14.10,2,1,12.50,700,1,14.26,100,1,12.46,200,2,14.28,100,1,12.43,700,1,14.40,100,1,12.42,700,1,14.56,800,2,12.37,700,1,14.60,700,1,12.36,200,2,14.68,1400,2,ARL,320484709
2025-07-17T15:58:14.484927848Z,2025-07-17T15:58:14.484761664Z,10,2,1108,C,A,0,13.76,4,128,166184,267657070,13.04,2,1,13.77,100,1,13.03,100,1,13.79,100,1,12.73,100,1,14.10,2,1,12.71,100,1,14.26,100,1,12.50,700,1,14.28,100,1,12.46,200,2,14.40,100,1,12.43,700,1,14.56,800,2,12.42,700,1,14.60,700,1,12.37,700,1,14.68,1400,2,12.36,200,2,14.72,100,1,ARL,320484625
2025-07-17T15:58:14.484963870Z,2025-07-17T15:58:14.484798779Z,10,2,1108,C,A,0,13.77,100,130,165091,267657073,13.04,2,1,13.79,100,1,13.03,100,1,14.10,2,1,12.73,100,1,14.26,100,1,12.71,100,1,14.28,100,1,12.50,700,1,14.40,100,1,12.46,200,2,14.56,800,2,12.43,700,1,14.60,700,1,12.42,700,1,14.68,1400,2,12.37,700,1,14.72,100,1,12.36,200,2,14.81,100,1,ARL,320484637
2025-07-17T15:58:14.485392903Z,2025-07-17T15:58:14.485227487Z,10,2,1108,C,A,0,14.81,100,0,165416,267657092,13.04,2,1,13.79,100,1,13.03,100,1,14.10,2,1,12.73,100,1,14.26,100,1,12.71,100,1,14.28,100,1,12.50,700,1,14.40,100,1,12.46,200,2,14.56,800,2,12.43,700,1,14.60,700,1,12.42,700,1,14.68,1400,2,12.37,700,1,14.72,100,1,12.36,200,2,14.84,100,1,ARL,312771781
2025-07-17T15:58:14.485392903Z,2025-07-17T15:58:14.485227487Z,10,2,1108,A,A,0,14.68,100,130,165416,267657092,13.04,2,1,13.79,100,1,13.03,100,1,14.10,2,1,12.73,100,1,14.26,100,1,12.71,100,1,14.28,100,1,12.50,700,1,14.40,100,1,12.46,200,2,14.56,800,2,12.43,700,1,14.60,700,1,12.42,700,1,14.68,1500,3,12.37,700,1,14.72,100,1,12.36,200,2,14.84,100,1,ARL,320484781
2025-07-17T15:58:14.485831602Z,2025-07-17T15:58:14.485666254Z,10,2,1108,C,A,0,16.02,100,0,165348,267657097,13.04,2,1,13.79,100,1,13.03,100,1,14.10,2,1,12.73,100,1,14.26,100,1,12.71,100,1,14.28,100,1,12.50,700,1,14.40,100,1,12.46,200,2,14.56,800,2,12.43,700,1,14.60,700,1,12.42,700,1,14.68,1500,3,12.37,700,1,14.72,100,1,12.36,200,2,14.84,100,1,ARL,312772057
2025-07-17T15:58:14.485831602Z,2025-07-17T15:58:14.485666254Z,10,2,1108,A,A,0,15.86,100,130,165348,267657097,13.04,2,1,13.79,100,1,13.03,100,1,14.10,2,1,12.73,100,1,14.26,100,1,12.71,100,1,14.28,100,1,12.50,700,1,14.40,100,1,12.46,200,2,14.56,800,2,12.43,700,1,14.60,700,1,12.42,700,1,14.68,1500,3,12.37,700,1,14.72,100,1,12.36,200,2,14.84,100,1,ARL,320484817
2025-07-17T15:58:14.485850874Z,2025-07-17T15:58:14.485685308Z,10,2,1108,C,A,0,14.96,100,0,165566,267657098,13.04,2,1,13.79,100,1,13.03,100,1,14.10,2,1,12.73,100,1,14.26,100,1,12.71,100,1,14.28,100,1,12.50,700,1,14.40,100,1,12.46,200,2,14.56,800,2,12.43,700,1,14.60,700,1,12.42,700,1,14.68,1500,3,12.37,700,1,14.72,100,1,12.36,200,2,14.84,100,1,ARL,312772869
2025-07-17T15:58:14.485850874Z,2025-07-17T15:58:14.485685308Z,10,2,1108,A,A,0,14.76,100,130,165566,267657098,13.04,2,1,13.79,100,1,13.03,100,1,14.10,2,1,12.73,100,1,14.26,100,1,12.71,100,1,14.28,100,1,12.50,700,1,14.40,100,1,12.46,200,2,14.56,800,2,12.43,700,1,14.60,700,1,12.42,700,1,14.68,1500,3,12.37,700,1,14.72,100,1,12.36,200,2,14.76,100,1,ARL,320484821
2025-07-17T15:58:14.485989643Z,2025-07-17T15:58:14.485824228Z,10,2,1108,C,A,0,14.89,100,0,165415,267657101,13.04,2,1,13.79,100,1,13.03,100,1,14.10,2,1,12.73,100,1,14.26,100,1,12.71,100,1,14.28,100,1,12.50,700,1,14.40,100,1,12.46,200,2,14.56,800,2,12.43,700,1,14.60,700,1,12.42,700,1,14.68,1500,3,12.37,700,1,14.72,100,1,12.36,200,2,14.76,100,1,ARL,319985025
2025-07-17T15:58:14.485989643Z,2025-07-17T15:58:14.485824228Z,10,2,1108,A,A,0,14.69,100,130,165415,267657101,13.04,2,1,13.79,100,1,13.03,100,1,14.10,2,1,12.73,100,1,14.26,100,1,12.71,100,1,14.28,100,1,12.50,700,1,14.40,100,1,12.46,200,2,14.56,800,2,12.43,700,1,14.60,700,1,12.42,700,1,14.68,1500,3,12.37,700,1,14.69,100,1,12.36,200,2,14.72,100,1,ARL,320484825
2025-07-17T15:58:14.486406355Z,2025-07-17T15:58:14.486240860Z,10,2,1108,C,A,0,17.70,100,0,165495,267657116,13.04,2,1,13.79,100,1,13.03,100,1,14.10,2,1,12.73,100,1,14.26,100,1,12.71,100,1,14.28,100,1,12.50,700,1,14.40,100,1,12.46,200,2,14.56,800,2,12.43,700,1,14.60,700,1,12.42,700,1,14.68,1500,3,12.37,700,1,14.69,100,1,12.36,200,2,14.72,100,1,ARL,312772009
2025-07-17T15:58:14.486406355Z,2025-07-17T15:58:14.486240860Z,10,2,1108,A,A,0,17.52,100,130,165495,267657116,13.04,2,1,13.79,100,1,13.03,100,1,14.10,2,1,12.73,100,1,14.26,100,1,12.71,100,1,14.28,100,1,12.50,700,1,14.40,100,1,12.46,200,2,14.56,800,2,12.43,700,1,14.60,700,1,12.42,700,1,14.68,1500,3,12.37,700,1,14.69,100,1,12.36,200,2,14.72,100,1,ARL,320484837
2025-07-17T15:58:14.508177256Z,2025-07-17T15:58:14.508012098Z,10,2,1108,C,A,0,14.26,100,130,165158,267657330,13.04,2,1,13.79,100,1,13.03,100,1,14.10,2,1,12.73,100,1,14.28,100,1,12.71,100,1,14.40,100,1,12.50,700,1,14.56,800,2,12.46,200,2,14.60,700,1,12.43,700,1,14.68,1500,3,12.42,700,1,14.69,100,1,12.37,700,1,14.72,100,1,12.36,200,2,14.76,100,1,ARL,319985165
2025-07-17T15:58:14.508227890Z,2025-07-17T15:58:14.508062605Z,10,2,1108,A,A,0,14.05,100,130,165285,267657333,13.04,2,1,13.79,100,1,13.03,100,1,14.05,100,1,12.73,100,1,14.10,2,1,12.71,100,1,14.28,100,1,12.50,700,1,14.40,100,1,12.46,200,2,14.56,800,2,12.43,700,1,14.60,700,1,12.42,700,1,14.68,1500,3,12.37,700,1,14.69,100,1,12.36,200,2,14.72,100,1,ARL,320484985
2025-07-17T15:58:14.529557108Z,2025-07-17T15:58:14.529391743Z,10,2,1108,A,B,0,13.02,100,130,165365,267657561,13.04,2,1,13.79,100,1,13.03,100,1,14.05,100,1,13.02,100,1,14.10,2,1,12.73,100,1,14.28,100,1,12.71,100,1,14.40,100,1,12.50,700,1,14.56,800,2,12.46,200,2,14.60,700,1,12.43,700,1,14.68,1500,3,12.42,700,1,14.69,100,1,12.37,700,1,14.72,100,1,ARL,320485385
2025-07-17T15:58:14.529578291Z,2025-07-17T15:58:14.529413184Z,10,2,1108,A,A,0,13.80,100,130,165107,267657562,13.04,2,1,13.79,100,1,13.03,100,1,13.80,100,1,13.02,100,1,14.05,100,1,12.73,100,1,14.10,2,1,12.71,100,1,14.28,100,1,12.50,700,1,14.40,100,1,12.46,200,2,14.56,800,2,12.43,700,1,14.60,700,1,12.42,700,1,14.68,1500,3,12.37,700,1,14.69,100,1,ARL,320485389
2025-07-17T15:58:14.659899426Z,2025-07-17T15:58:14.659734381Z,10,2,1108,C,A,0,13.79,100,130,165045,267658873,13.04,2,1,13.80,100,1,13.03,100,1,14.05,100,1,13.02,100,1,14.10,2,1,12.73,100,1,14.28,100,1,12.71,100,1,14.40,100,1,12.50,700,1,14.56,800,2,12.46,200,2,14.60,700,1,12.43,700,1,14.68,1500,3,12.42,700,1,14.69,100,1,12.37,700,1,14.72,100,1,ARL,320484661
2025-07-17T15:58:14.659939230Z,2025-07-17T15:58:14.659773896Z,10,2,1108,C,A,0,13.80,100,130,165334,267658879,13.04,2,1,14.05,100,1,13.03,100,1,14.10,2,1,13.02,100,1,14.28,100,1,12.73,100,1,14.40,100,1,12.71,100,1,14.56,800,2,12.50,700,1,14.60,700,1,12.46,200,2,14.68,1500,3,12.43,700,1,14.69,100,1,12.42,700,1,14.72,100,1,12.37,700,1,14.76,100,1,ARL,320485389
2025-07-17T15:58:14.660667636Z,2025-07-17T15:58:14.660502341Z,10,2,1108,C,A,0,14.84,100,0,165295,267658892,13.04,2,1,14.05,100,1,13.03,100,1,14.10,2,1,13.02,100,1,14.28,100,1,12.73,100,1,14.40,100,1,12.71,100,1,14.56,800,2,12.50,700,1,14.60,700,1,12.46,200,2,14.68,1500,3,12.43,700,1,14.69,100,1,12.42,700,1,14.72,100,1,12.37,700,1,14.76,100,1,ARL,320484709
2025-07-17T15:58:14.660667636Z,2025-07-17T15:58:14.660502341Z,10,2,1108,A,A,0,14.91,100,130,165295,267658892,13.04,2,1,14.05,100,1,13.03,100,1,14.10,2,1,13.02,100,1,14.28,100,1,12.73,100,1,14.40,100,1,12.71,100,1,14.56,800,2,12.50,700,1,14.60,700,1,12.46,200,2,14.68,1500,3,12.43,700,1,14.69,100,1,12.42,700,1,14.72,100,1,12.37,700,1,14.76,100,1,ARL,320486925
2025-07-17T15:58:14.664378962Z,2025-07-17T15:58:14.664213722Z,10,2,1108,C,A,0,17.52,100,0,165240,267658928,13.04,2,1,14.05,100,1,13.03,100,1,14.10,2,1,13.02,100,1,14.28,100,1,12.73,100,1,14.40,100,1,12.71,100,1,14.56,800,2,12.50,700,1,14.60,700,1,12.46,200,2,14.68,1500,3,12.43,700,1,14.69,100,1,12.42,700,1,14.72,100,1,12.37,700,1,14.76,100,1,ARL,320484837
2025-07-17T15:58:14.664378962Z,2025-07-17T15:58:14.664213722Z,10,2,1108,A,A,0,17.76,100,130,165240,267658928,13.04,2,1,14.05,100,1,13.03,100,1,14.10,2,1,13.02,100,1,14.28,100,1,12.73,100,1,14.40,100,1,12.71,100,1,14.56,800,2,12.50,700,1,14.60,700,1,12.46,200,2,14.68,1500,3,12.43,700,1,14.69,100,1,12.42,700,1,14.72,100,1,12.37,700,1,14.76,100,1,ARL,320486937
2025-07-17T15:58:14.664939310Z,2025-07-17T15:58:14.664774078Z,10,2,1108,C,A,0,15.86,100,0,165232,267658931,13.04,2,1,14.05,100,1,13.03,100,1,14.10,2,1,13.02,100,1,14.28,100,1,12.73,100,1,14.40,100,1,12.71,100,1,14.56,800,2,12.50,700,1,14.60,700,1,12.46,200,2,14.68,1500,3,12.43,700,1,14.69,100,1,12.42,700,1,14.72,100,1,12.37,700,1,14.76,100,1,ARL,320484817
2025-07-17T15:58:14.664939310Z,2025-07-17T15:58:14.664774078Z,10,2,1108,A,A,0,16.08,100,130,165232,267658931,13.04,2,1,14.05,100,1,13.03,100,1,14.10,2,1,13.02,100,1,14.28,100,1,12.73,100,1,14.40,100,1,12.71,100,1,14.56,800,2,12.50,700,1,14.60,700,1,12.46,200,2,14.68,1500,3,12.43,700,1,14.69,100,1,12.42,700,1,14.72,100,1,12.37,700,1,14.76,100,1,ARL,320486945
2025-07-17T15:58:14.672315806Z,2025-07-17T15:58:14.672150755Z,10,2,1108,C,A,0,14.05,100,130,165051,267658982,13.04,2,1,14.10,2,1,13.03,100,1,14.28,100,1,13.02,100,1,14.40,100,1,12.73,100,1,14.56,800,2,12.71,100,1,14.60,700,1,12.50,700,1,14.68,1500,3,12.46,200,2,14.69,100,1,12.43,700,1,14.72,100,1,12.42,700,1,14.76,100,1,12.37,700,1,14.89,100,1,ARL,320484985
2025-07-17T15:58:14.672365974Z,2025-07-17T15:58:14.672200872Z,10,2,1108,A,A,0,14.12,100,130,165102,267658983,13.04,2,1,14.10,2,1,13.03,100,1,14.12,100,1,13.02,100,1,14.28,100,1,12.73,100,1,14.40,100,1,12.71,100,1,14.56,800,2,12.50,700,1,14.60,700,1,12.46,200,2,14.68,1500,3,12.43,700,1,14.69,100,1,12.42,700,1,14.72,100,1,12.37,700,1,14.76,100,1,ARL,320487017
2025-07-17T15:58:14.673184116Z,2025-07-17T15:58:14.673019194Z,10,2,1108,C,A,0,14.12,100,130,164922,267658989,13.04,2,1,14.10,2,1,13.03,100,1,14.28,100,1,13.02,100,1,14.40,100,1,12.73,100,1,14.56,800,2,12.71,100,1,14.60,700,1,12.50,700,1,14.68,1500,3,12.46,200,2,14.69,100,1,12.43,700,1,14.72,100,1,12.42,700,1,14.76,100,1,12.37,700,1,14.89,100,1,ARL,320487017
2025-07-17T15:58:14.673230480Z,2025-07-17T15:58:14.673065320Z,10,2,1108,A,A,0,14.26,100,130,165160,267658990,13.04,2,1,14.10,2,1,13.03,100,1,14.26,100,1,13.02,100,1,14.28,100,1,12.73,100,1,14.40,100,1,12.71,100,1,14.56,800,2,12.50,700,1,14.60,700,1,12.46,200,2,14.68,1500,3,12.43,700,1,14.69,100,1,12.42,700,1,14.72,100,1,12.37,700,1,14.76,100,1,ARL,320487025
2025-07-17T15:58:14.682945541Z,2025-07-17T15:58:14.682780396Z,10,2,1108,C,A,0,14.76,100,0,165145,267659018,13.04,2,1,14.10,2,1,13.03,100,1,14.26,100,1,13.02,100,1,14.28,100,1,12.73,100,1,14.40,100,1,12.71,100,1,14.56,800,2,12.50,700,1,14.60,700,1,12.46,200,2,14.68,1500,3,12.43,700,1,14.69,100,1,12.42,700,1,14.72,100,1,12.37,700,1,14.89,100,1,ARL,320484821
2025-07-17T15:58:14.682945541Z,2025-07-17T15:58:14.682780396Z,10,2,1108,A,A,0,14.96,100,130,165145,267659018,13.04,2,1,14.10,2,1,13.03,100,1,14.26,100,1,13.02,100,1,14.28,100,1,12.73,100,1,14.40,100,1,12.71,100,1,14.56,800,2,12.50,700,1,14.60,700,1,12.46,200,2,14.68,1500,3,12.43,700,1,14.69,100,1,12.42,700,1,14.72,100,1,12.37,700,1,14.89,100,1,ARL,320487105
2025-07-17T15:58:14.710787891Z,2025-07-17T15:58:14.710622495Z,10,2,1108,C,A,0,14.91,100,0,165396,267659178,13.04,2,1,14.10,2,1,13.03,100,1,14.26,100,1,13.02,100,1,14.28,100,1,12.73,100,1,14.40,100,1,12.71,100,1,14.56,800,2,12.50,700,1,14.60,700,1,12.46,200,2,14.68,1500,3,12.43,700,1,14.69,100,1,12.42,700,1,14.72,100,1,12.37,700,1,14.89,100,1,ARL,320486925
2025-07-17T15:58:14.710787891Z,2025-07-17T15:58:14.710622495Z,10,2,1108,A,A,0,15.06,100,130,165396,267659178,13.04,2,1,14.10,2,1,13.03,100,1,14.26,100,1,13.02,100,1,14.28,100,1,12.73,100,1,14.40,100,1,12.71,100,1,14.56,800,2,12.50,700,1,14.60,700,1,12.46,200,2,14.68,1500,3,12.43,700,1,14.69,100,1,12.42,700,1,14.72,100,1,12.37,700,1,14.89,100,1,ARL,320487357
2025-07-17T15:58:15.564070256Z,2025-07-17T15:58:15.563904700Z,10,2,1108,C,A,0,14.68,100,0,165556,267672469,13.04,2,1,14.10,2,1,13.03,100,1,14.26,100,1,13.02,100,1,14.28,100,1,12.73,100,1,14.40,100,1,12.71,100,1,14.56,800,2,12.50,700,1,14.60,700,1,12.46,200,2,14.68,1400,2,12.43,700,1,14.69,100,1,12.42,700,1,14.72,100,1,12.37,700,1,14.89,100,1,ARL,320484781
2025-07-17T15:58:15.564070256Z,2025-07-17T15:58:15.563904700Z,10,2,1108,A,A,0,14.87,100,130,165556,267672469,13.04,2,1,14.10,2,1,13.03,100,1,14.26,100,1,13.02,100,1,14.28,100,1,12.73,100,1,14.40,100,1,12.71,100,1,14.56,800,2,12.50,700,1,14.60,700,1,12.46,200,2,14.68,1400,2,12.43,700,1,14.69,100,1,12.42,700,1,14.72,100,1,12.37,700,1,14.87,100,1,ARL,320504473
2025-07-17T15:58:15.577719796Z,2025-07-17T15:58:15.577554368Z,10,2,1108,C,A,0,14.69,100,0,165428,267672549,13.04,2,1,14.10,2,1,13.03,100,1,14.26,100,1,13.02,100,1,14.28,100,1,12.73,100,1,14.40,100,1,12.71,100,1,14.56,800,2,12.50,700,1,14.60,700,1,12.46,200,2,14.68,1400,2,12.43,700,1,14.72,100,1,12.42,700,1,14.87,100,1,12.37,700,1,14.89,100,1,ARL,320484825
2025-07-17T15:58:15.577719796Z,2025-07-17T15:58:15.577554368Z,10,2,1108,A,A,0,14.88,100,130,165428,267672549,13.04,2,1,14.10,2,1,13.03,100,1,14.26,100,1,13.02,100,1,14.28,100,1,12.73,100,1,14.40,100,1,12.71,100,1,14.56,800,2,12.50,700,1,14.60,700,1,12.46,200,2,14.68,1400,2,12.43,700,1,14.72,100,1,12.42,700,1,14.87,100,1,12.37,700,1,14.88,100,1,ARL,320504609
2025-07-17T15:58:16.502080515Z,2025-07-17T15:58:16.501915292Z,10,2,1108,A,A,0,14.11,100,130,165223,267685252,13.04,2,1,14.10,2,1,13.03,100,1,14.11,100,1,13.02,100,1,14.26,100,1,12.73,100,1,14.28,100,1,12.71,100,1,14.40,100,1,12.50,700,1,14.56,800,2,12.46,200,2,14.60,700,1,12.43,700,1,14.68,1400,2,12.42,700,1,14.72,100,1,12.37,700,1,14.87,100,1,ARL,320519893
2025-07-17T15:58:19.965200980Z,2025-07-17T15:58:19.965034325Z,10,2,1108,A,A,0,13.94,15,130,166655,267738403,13.04,2,1,13.94,15,1,13.03,100,1,14.10,2,1,13.02,100,1,14.11,100,1,12.73,100,1,14.26,100,1,12.71,100,1,14.28,100,1,12.50,700,1,14.40,100,1,12.46,200,2,14.56,800,2,12.43,700,1,14.60,700,1,12.42,700,1,14.68,1400,2,12.37,700,1,14.72,100,1,ARL,320588689
2025-07-17T15:58:20.237833402Z,2025-07-17T15:58:20.237668047Z,10,2,1108,C,A,0,14.11,100,0,165355,267745213,13.04,2,1,13.94,15,1,13.03,100,1,14.10,2,1,13.02,100,1,14.26,100,1,12.73,100,1,14.28,100,1,12.71,100,1,14.40,100,1,12.50,700,1,14.56,800,2,12.46,200,2,14.60,700,1,12.43,700,1,14.68,1400,2,12.42,700,1,14.72,100,1,12.37,700,1,14.87,100,1,ARL,320519893
2025-07-17T15:58:20.237833402Z,2025-07-17T15:58:20.237668047Z,10,2,1108,A,A,0,13.95,100,130,165355,267745213,13.04,2,1,13.94,15,1,13.03,100,1,13.95,100,1,13.02,100,1,14.10,2,1,12.73,100,1,14.26,100,1,12.71,100,1,14.28,100,1,12.50,700,1,14.40,100,1,12.46,200,2,14.56,800,2,12.43,700,1,14.60,700,1,12.42,700,1,14.68,1400,2,12.37,700,1,14.72,100,1,ARL,320595817
2025-07-17T15:58:20.705512171Z,2025-07-17T15:58:20.705344578Z,10,2,1108,C,A,0,13.94,15,128,167593,267754327,13.04,2,1,13.95,100,1,13.03,100,1,14.10,2,1,13.02,100,1,14.26,100,1,12.73,100,1,14.28,100,1,12.71,100,1,14.40,100,1,12.50,700,1,14.56,800,2,12.46,200,2,14.60,700,1,12.43,700,1,14.68,1400,2,12.42,700,1,14.72,100,1,12.37,700,1,14.87,100,1,ARL,320588689
2025-07-17T15:58:30.800053062Z,2025-07-17T15:58:30.799887713Z,10,2,1108,A,A,0,13.89,15,130,165349,267913947,13.04,2,1,13.89,15,1,13.03,100,1,13.95,100,1,13.02,100,1,14.10,2,1,12.73,100,1,14.26,100,1,12.71,100,1,14.28,100,1,12.50,700,1,14.40,100,1,12.46,200,2,14.56,800,2,12.43,700,1,14.60,700,1,12.42,700,1,14.68,1400,2,12.37,700,1,14.72,100,1,ARL,320833897
2025-07-17T15:58:30.905657319Z,2025-07-17T15:58:30.905491759Z,10,2,1108,C,A,0,13.95,100,0,165560,267919515,13.04,2,1,13.89,15,1,13.03,100,1,14.10,2,1,13.02,100,1,14.26,100,1,12.73,100,1,14.28,100,1,12.71,100,1,14.40,100,1,12.50,700,1,14.56,800,2,12.46,200,2,14.60,700,1,12.43,700,1,14.68,1400,2,12.42,700,1,14.72,100,1,12.37,700,1,14.87,100,1,ARL,320595817
2025-07-17T15:58:30.905657319Z,2025-07-17T15:58:30.905491759Z,10,2,1108,A,A,0,13.90,100,130,165560,267919515,13.04,2,1,13.89,15,1,13.03,100,1,13.90,100,1,13.02,100,1,14.10,2,1,12.73,100,1,14.26,100,1,12.71,100,1,14.28,100,1,12.50,700,1,14.40,100,1,12.46,200,2,14.56,800,2,12.43,700,1,14.60,700,1,12.42,700,1,14.68,1400,2,12.37,700,1,14.72,100,1,ARL,320839125
2025-07-17T15:58:30.906412286Z,2025-07-17T15:58:30.906246950Z,10,2,1108,C,A,0,15.06,100,0,165336,267919540,13.04,2,1,13.89,15,1,13.03,100,1,13.90,100,1,13.02,100,1,14.10,2,1,12.73,100,1,14.26,100,1,12.71,100,1,14.28,100,1,12.50,700,1,14.40,100,1,12.46,200,2,14.56,800,2,12.43,700,1,14.60,700,1,12.42,700,1,14.68,1400,2,12.37,700,1,14.72,100,1,ARL,320487357
2025-07-17T15:58:30.906412286Z,2025-07-17T15:58:30.906246950Z,10,2,1108,A,A,0,14.98,100,130,165336,267919540,13.04,2,1,13.89,15,1,13.03,100,1,13.90,100,1,13.02,100,1,14.10,2,1,12.73,100,1,14.26,100,1,12.71,100,1,14.28,100,1,12.50,700,1,14.40,100,1,12.46,200,2,14.56,800,2,12.43,700,1,14.60,700,1,12.42,700,1,14.68,1400,2,12.37,700,1,14.72,100,1,ARL,320839149
2025-07-17T15:58:30.916726353Z,2025-07-17T15:58:30.916561264Z,10,2,1108,C,A,0,14.26,100,130,165089,267919917,13.04,2,1,13.89,15,1,13.03,100,1,13.90,100,1,13.02,100,1,14.10,2,1,12.73,100,1,14.28,100,1,12.71,100,1,14.40,100,1,12.50,700,1,14.56,800,2,12.46,200,2,14.60,700,1,12.43,700,1,14.68,1400,2,12.42,700,1,14.72,100,1,12.37,700,1,14.87,100,1,ARL,320487025
2025-07-17T15:58:30.916784278Z,2025-07-17T15:58:30.916619122Z,10,2,1108,A,A,0,14.18,100,130,165156,267919919,13.04,2,1,13.89,15,1,13.03,100,1,13.90,100,1,13.02,100,1,14.10,2,1,12.73,100,1,14.18,100,1,12.71,100,1,14.28,100,1,12.50,700,1,14.40,100,1,12.46,200,2,14.56,800,2,12.43,700,1,14.60,700,1,12.42,700,1,14.68,1400,2,12.37,700,1,14.72,100,1,ARL,320839577
2025-07-17T15:58:31.124388717Z,2025-07-17T15:58:31.124222733Z,10,2,1108,C,A,0,14.87,100,0,165984,267925564,13.04,2,1,13.89,15,1,13.03,100,1,13.90,100,1,13.02,100,1,14.10,2,1,12.73,100,1,14.18,100,1,12.71,100,1,14.28,100,1,12.50,700,1,14.40,100,1,12.46,200,2,14.56,800,2,12.43,700,1,14.60,700,1,12.42,700,1,14.68,1400,2,12.37,700,1,14.72,100,1,ARL,320504473
2025-07-17T15:58:31.124388717Z,2025-07-17T15:58:31.124222733Z,10,2,1108,A,A,0,14.76,100,130,165984,267925564,13.04,2,1,13.89,15,1,13.03,100,1,13.90,100,1,13.02,100,1,14.10,2,1,12.73,100,1,14.18,100,1,12.71,100,1,14.28,100,1,12.50,700,1,14.40,100,1,12.46,200,2,14.56,800,2,12.43,700,1,14.60,700,1,12.42,700,1,14.68,1400,2,12.37,700,1,14.72,100,1,ARL,320845893
2025-07-17T15:58:31.136439248Z,2025-07-17T15:58:31.136273403Z,10,2,1108,C,A,0,14.88,100,0,165845,267925951,13.04,2,1,13.89,15,1,13.03,100,1,13.90,100,1,13.02,100,1,14.10,2,1,12.73,100,1,14.18,100,1,12.71,100,1,14.28,100,1,12.50,700,1,14.40,100,1,12.46,200,2,14.56,800,2,12.43,700,1,14.60,700,1,12.42,700,1,14.68,1400,2,12.37,700,1,14.72,100,1,ARL,320504609
2025-07-17T15:58:31.136439248Z,2025-07-17T15:58:31.136273403Z,10,2,1108,A,A,0,14.77,100,130,165845,267925951,13.04,2,1,13.89,15,1,13.03,100,1,13.90,100,1,13.02,100,1,14.10,2,1,12.73,100,1,14.18,100,1,12.71,100,1,14.28,100,1,12.50,700,1,14.40,100,1,12.46,200,2,14.56,800,2,12.43,700,1,14.60,700,1,12.42,700,1,14.68,1400,2,12.37,700,1,14.72,100,1,ARL,320846429
2025-07-17T15:58:40.799952243Z,2025-07-17T15:58:40.799787018Z,10,2,1108,A,A,0,13.83,15,130,165225,268074431,13.04,2,1,13.83,15,1,13.03,100,1,13.89,15,1,13.02,100,1,13.90,100,1,12.73,100,1,14.10,2,1,12.71,100,1,14.18,100,1,12.50,700,1,14.28,100,1,12.46,200,2,14.40,100,1,12.43,700,1,14.56,800,2,12.42,700,1,14.60,700,1,12.37,700,1,14.68,1400,2,ARL,321038033
2025-07-17T15:58:43.690244473Z,2025-07-17T15:58:43.690078924Z,10,2,1108,C,A,0,13.90,100,0,165549,268115228,13.04,2,1,13.83,15,1,13.03,100,1,13.89,15,1,13.02,100,1,14.10,2,1,12.73,100,1,14.18,100,1,12.71,100,1,14.28,100,1,12.50,700,1,14.40,100,1,12.46,200,2,14.56,800,2,12.43,700,1,14.60,700,1,12.42,700,1,14.68,1400,2,12.37,700,1,14.72,100,1,ARL,320839125
2025-07-17T15:58:43.690244473Z,2025-07-17T15:58:43.690078924Z,10,2,1108,A,A,0,13.84,100,130,165549,268115228,13.04,2,1,13.83,15,1,13.03,100,1,13.84,100,1,13.02,100,1,13.89,15,1,12.73,100,1,14.10,2,1,12.71,100,1,14.18,100,1,12.50,700,1,14.28,100,1,12.46,200,2,14.40,100,1,12.43,700,1,14.56,800,2,12.42,700,1,14.60,700,1,12.37,700,1,14.68,1400,2,ARL,321096769
2025-07-17T15:58:43.690988921Z,2025-07-17T15:58:43.690823184Z,10,2,1108,C,A,0,14.98,100,0,165737,268115235,13.04,2,1,13.83,15,1,13.03,100,1,13.84,100,1,13.02,100,1,13.89,15,1,12.73,100,1,14.10,2,1,12.71,100,1,14.18,100,1,12.50,700,1,14.28,100,1,12.46,200,2,14.40,100,1,12.43,700,1,14.56,800,2,12.42,700,1,14.60,700,1,12.37,700,1,14.68,1400,2,ARL,320839149
2025-07-17T15:58:43.690988921Z,2025-07-17T15:58:43.690823184Z,10,2,1108,A,A,0,14.91,100,130,165737,268115235,13.04,2,1,13.83,15,1,13.03,100,1,13.84,100,1,13.02,100,1,13.89,15,1,12.73,100,1,14.10,2,1,12.71,100,1,14.18,100,1,12.50,700,1,14.28,100,1,12.46,200,2,14.40,100,1,12.43,700,1,14.56,800,2,12.42,700,1,14.60,700,1,12.37,700,1,14.68,1400,2,ARL,321096793
2025-07-17T15:58:43.693394500Z,2025-07-17T15:58:43.693228946Z,10,2,1108,C,A,0,17.76,100,0,165554,268115265,13.04,2,1,13.83,15,1,13.03,100,1,13.84,100,1,13.02,100,1,13.89,15,1,12.73,100,1,14.10,2,1,12.71,100,1,14.18,100,1,12.50,700,1,14.28,100,1,12.46,200,2,14.40,100,1,12.43,700,1,14.56,800,2,12.42,700,1,14.60,700,1,12.37,700,1,14.68,1400,2,ARL,320486937
2025-07-17T15:58:43.693394500Z,2025-07-17T15:58:43.693228946Z,10,2,1108,A,A,0,17.58,100,130,165554,268115265,13.04,2,1,13.83,15,1,13.03,100,1,13.84,100,1,13.02,100,1,13.89,15,1,12.73,100,1,14.10,2,1,12.71,100,1,14.18,100,1,12.50,700,1,14.28,100,1,12.46,200,2,14.40,100,1,12.43,700,1,14.56,800,2,12.42,700,1,14.60,700,1,12.37,700,1,14.68,1400,2,ARL,321096825
2025-07-17T15:58:43.695055785Z,2025-07-17T15:58:43.694890264Z,10,2,1108,C,A,0,16.08,100,0,165521,268115287,13.04,2,1,13.83,15,1,13.03,100,1,13.84,100,1,13.02,100,1,13.89,15,1,12.73,100,1,14.10,2,1,12.71,100,1,14.18,100,1,12.50,700,1,14.28,100,1,12.46,200,2,14.40,100,1,12.43,700,1,14.56,800,2,12.42,700,1,14.60,700,1,12.37,700,1,14.68,1400,2,ARL,320486945
2025-07-17T15:58:43.695055785Z,2025-07-17T15:58:43.694890264Z,10,2,1108,A,A,0,15.92,100,130,165521,268115287,13.04,2,1,13.83,15,1,13.03,100,1,13.84,100,1,13.02,100,1,13.89,15,1,12.73,100,1,14.10,2,1,12.71,100,1,14.18,100,1,12.50,700,1,14.28,100,1,12.46,200,2,14.40,100,1,12.43,700,1,14.56,800,2,12.42,700,1,14.60,700,1,12.37,700,1,14.68,1400,2,ARL,321096889
2025-07-17T15:58:43.716437124Z,2025-07-17T15:58:43.716271172Z,10,2,1108,C,A,0,14.96,100,0,165952,268115456,13.04,2,1,13.83,15,1,13.03,100,1,13.84,100,1,13.02,100,1,13.89,15,1,12.73,100,1,14.10,2,1,12.71,100,1,14.18,100,1,12.50,700,1,14.28,100,1,12.46,200,2,14.40,100,1,12.43,700,1,14.56,800,2,12.42,700,1,14.60,700,1,12.37,700,1,14.68,1400,2,ARL,320487105
2025-07-17T15:58:43.716437124Z,2025-07-17T15:58:43.716271172Z,10,2,1108,A,A,0,14.81,100,130,165952,268115456,13.04,2,1,13.83,15,1,13.03,100,1,13.84,100,1,13.02,100,1,13.89,15,1,12.73,100,1,14.10,2,1,12.71,100,1,14.18,100,1,12.50,700,1,14.28,100,1,12.46,200,2,14.40,100,1,12.43,700,1,14.56,800,2,12.42,700,1,14.60,700,1,12.37,700,1,14.68,1400,2,ARL,321097197
2025-07-17T15:58:44.903740109Z,2025-07-17T15:58:44.903574654Z,10,2,1108,A,A,0,13.83,100,130,165455,268129040,13.04,2,1,13.83,115,2,13.03,100,1,13.84,100,1,13.02,100,1,13.89,15,1,12.73,100,1,14.10,2,1,12.71,100,1,14.18,100,1,12.50,700,1,14.28,100,1,12.46,200,2,14.40,100,1,12.43,700,1,14.56,800,2,12.42,700,1,14.60,700,1,12.37,700,1,14.68,1400,2,ARL,321114473
2025-07-17T15:58:44.924114268Z,2025-07-17T15:58:44.923948853Z,10,2,1108,C,A,0,14.18,100,130,165415,268129217,13.04,2,1,13.83,115,2,13.03,100,1,13.84,100,1,13.02,100,1,13.89,15,1,12.73,100,1,14.10,2,1,12.71,100,1,14.28,100,1,12.50,700,1,14.40,100,1,12.46,200,2,14.56,800,2,12.43,700,1,14.60,700,1,12.42,700,1,14.68,1400,2,12.37,700,1,14.72,100,1,ARL,320839577
2025-07-17T15:58:44.924165875Z,2025-07-17T15:58:44.924000519Z,10,2,1108,A,A,0,14.11,100,130,165356,268129218,13.04,2,1,13.83,115,2,13.03,100,1,13.84,100,1,13.02,100,1,13.89,15,1,12.73,100,1,14.10,2,1,12.71,100,1,14.11,100,1,12.50,700,1,14.28,100,1,12.46,200,2,14.40,100,1,12.43,700,1,14.56,800,2,12.42,700,1,14.60,700,1,12.37,700,1,14.68,1400,2,ARL,321114729
2025-07-17T15:58:51.241342265Z,2025-07-17T15:58:51.241176997Z,10,2,1108,C,A,0,13.89,15,130,165268,268212338,13.04,2,1,13.83,115,2,13.03,100,1,13.84,100,1,13.02,100,1,14.10,2,1,12.73,100,1,14.11,100,1,12.71,100,1,14.28,100,1,12.50,700,1,14.40,100,1,12.46,200,2,14.56,800,2,12.43,700,1,14.60,700,1,12.42,700,1,14.68,1400,2,12.37,700,1,14.72,100,1,ARL,320833897
2025-07-17T15:58:51.254127339Z,2025-07-17T15:58:51.253961905Z,10,2,1108,A,A,0,13.80,100,130,165434,268212497,13.04,2,1,13.80,100,1,13.03,100,1,13.83,115,2,13.02,100,1,13.84,100,1,12.73,100,1,14.10,2,1,12.71,100,1,14.11,100,1,12.50,700,1,14.28,100,1,12.46,200,2,14.40,100,1,12.43,700,1,14.56,800,2,12.42,700,1,14.60,700,1,12.37,700,1,14.68,1400,2,ARL,321225725
2025-07-17T15:58:51.254871890Z,2025-07-17T15:58:51.254706004Z,10,2,1108,C,A,0,14.91,100,0,165886,268212499,13.04,2,1,13.80,100,1,13.03,100,1,13.83,115,2,13.02,100,1,13.84,100,1,12.73,100,1,14.10,2,1,12.71,100,1,14.11,100,1,12.50,700,1,14.28,100,1,12.46,200,2,14.40,100,1,12.43,700,1,14.56,800,2,12.42,700,1,14.60,700,1,12.37,700,1,14.68,1400,2,ARL,321096793
2025-07-17T15:58:51.254871890Z,2025-07-17T15:58:51.254706004Z,10,2,1108,A,A,0,14.87,100,130,165886,268212499,13.04,2,1,13.80,100,1,13.03,100,1,13.83,115,2,13.02,100,1,13.84,100,1,12.73,100,1,14.10,2,1,12.71,100,1,14.11,100,1,12.50,700,1,14.28,100,1,12.46,200,2,14.40,100,1,12.43,700,1,14.56,800,2,12.42,700,1,14.60,700,1,12.37,700,1,14.68,1400,2,ARL,321225745
2025-07-17T15:58:51.260753179Z,2025-07-17T15:58:51.260587778Z,10,2,1108,C,A,0,13.83,100,130,165401,268212534,13.04,2,1,13.80,100,1,13.03,100,1,13.83,15,1,13.02,100,1,13.84,100,1,12.73,100,1,14.10,2,1,12.71,100,1,14.11,100,1,12.50,700,1,14.28,100,1,12.46,200,2,14.40,100,1,12.43,700,1,14.56,800,2,12.42,700,1,14.60,700,1,12.37,700,1,14.68,1400,2,ARL,321114473
2025-07-17T15:58:53.579628288Z,2025-07-17T15:58:53.579462029Z,10,2,1108,C,A,0,13.83,15,130,166259,268250290,13.04,2,1,13.80,100,1,13.03,100,1,13.84,100,1,13.02,100,1,14.10,2,1,12.73,100,1,14.11,100,1,12.71,100,1,14.28,100,1,12.50,700,1,14.40,100,1,12.46,200,2,14.56,800,2,12.43,700,1,14.60,700,1,12.42,700,1,14.68,1400,2,12.37,700,1,14.72,100,1,ARL,321038033
2025-07-17T15:58:53.580217445Z,2025-07-17T15:58:53.580052014Z,10,2,1108,C,A,0,13.84,100,0,165431,268250346,13.04,2,1,13.80,100,1,13.03,100,1,14.10,2,1,13.02,100,1,14.11,100,1,12.73,100,1,14.28,100,1,12.71,100,1,14.40,100,1,12.50,700,1,14.56,800,2,12.46,200,2,14.60,700,1,12.43,700,1,14.68,1400,2,12.42,700,1,14.72,100,1,12.37,700,1,14.76,100,1,ARL,321096769
2025-07-17T15:58:53.580217445Z,2025-07-17T15:58:53.580052014Z,10,2,1108,A,A,0,13.81,100,130,165431,268250346,13.04,2,1,13.80,100,1,13.03,100,1,13.81,100,1,13.02,100,1,14.10,2,1,12.73,100,1,14.11,100,1,12.71,100,1,14.28,100,1,12.50,700,1,14.40,100,1,12.46,200,2,14.56,800,2,12.43,700,1,14.60,700,1,12.42,700,1,14.68,1400,2,12.37,700,1,14.72,100,1,ARL,321272581
2025-07-17T15:58:54.584124215Z,2025-07-17T15:58:54.583958582Z,10,2,1108,C,A,0,14.77,100,0,165633,268265585,13.04,2,1,13.80,100,1,13.03,100,1,13.81,100,1,13.02,100,1,14.10,2,1,12.73,100,1,14.11,100,1,12.71,100,1,14.28,100,1,12.50,700,1,14.40,100,1,12.46,200,2,14.56,800,2,12.43,700,1,14.60,700,1,12.42,700,1,14.68,1400,2,12.37,700,1,14.72,100,1,ARL,320846429
2025-07-17T15:58:54.584124215Z,2025-07-17T15:58:54.583958582Z,10,2,1108,A,A,0,14.65,100,130,165633,268265585,13.04,2,1,13.80,100,1,13.03,100,1,13.81,100,1,13.02,100,1,14.10,2,1,12.73,100,1,14.11,100,1,12.71,100,1,14.28,100,1,12.50,700,1,14.40,100,1,12.46,200,2,14.56,800,2,12.43,700,1,14.60,700,1,12.42,700,1,14.65,100,1,12.37,700,1,14.68,1400,2,ARL,321293737
2025-07-17T15:58:54.584260712Z,2025-07-17T15:58:54.584094980Z,10,2,1108,C,A,0,14.76,100,0,165732,268265586,13.04,2,1,13.80,100,1,13.03,100,1,13.81,100,1,13.02,100,1,14.10,2,1,12.73,100,1,14.11,100,1,12.71,100,1,14.28,100,1,12.50,700,1,14.40,100,1,12.46,200,2,14.56,800,2,12.43,700,1,14.60,700,1,12.42,700,1,14.65,100,1,12.37,700,1,14.68,1400,2,ARL,320845893
2025-07-17T15:58:54.584260712Z,2025-07-17T15:58:54.584094980Z,10,2,1108,A,A,0,14.64,100,130,165732,268265586,13.04,2,1,13.80,100,1,13.03,100,1,13.81,100,1,13.02,100,1,14.10,2,1,12.73,100,1,14.11,100,1,12.71,100,1,14.28,100,1,12.50,700,1,14.40,100,1,12.46,200,2,14.56,800,2,12.43,700,1,14.60,700,1,12.42,700,1,14.64,100,1,12.37,700,1,14.65,100,1,ARL,321293741
2025-07-17T15:58:55.305104029Z,2025-07-17T15:58:55.304938318Z,10,2,1108,A,A,0,13.78,100,130,165711,268277940,13.04,2,1,13.78,100,1,13.03,100,1,13.80,100,1,13.02,100,1,13.81,100,1,12.73,100,1,14.10,2,1,12.71,100,1,14.11,100,1,12.50,700,1,14.28,100,1,12.46,200,2,14.40,100,1,12.43,700,1,14.56,800,2,12.42,700,1,14.60,700,1,12.37,700,1,14.64,100,1,ARL,321309865
2025-07-17T15:58:55.307508305Z,2025-07-17T15:58:55.307342971Z,10,2,1108,C,A,0,14.72,100,130,165334,268277999,13.04,2,1,13.78,100,1,13.03,100,1,13.80,100,1,13.02,100,1,13.81,100,1,12.73,100,1,14.10,2,1,12.71,100,1,14.11,100,1,12.50,700,1,14.28,100,1,12.46,200,2,14.40,100,1,12.43,700,1,14.56,800,2,12.42,700,1,14.60,700,1,12.37,700,1,14.64,100,1,ARL,312772061
2025-07-17T15:58:55.307637209Z,2025-07-17T15:58:55.307472032Z,10,2,1108,A,A,0,14.58,100,130,165177,268278004,13.04,2,1,13.78,100,1,13.03,100,1,13.80,100,1,13.02,100,1,13.81,100,1,12.73,100,1,14.10,2,1,12.71,100,1,14.11,100,1,12.50,700,1,14.28,100,1,12.46,200,2,14.40,100,1,12.43,700,1,14.56,800,2,12.42,700,1,14.58,100,1,12.37,700,1,14.60,700,1,ARL,321309941
2025-07-17T15:58:55.311899965Z,2025-07-17T15:58:55.311734700Z,10,2,1108,C,A,0,13.80,100,130,165265,268278030,13.04,2,1,13.78,100,1,13.03,100,1,13.81,100,1,13.02,100,1,14.10,2,1,12.73,100,1,14.11,100,1,12.71,100,1,14.28,100,1,12.50,700,1,14.40,100,1,12.46,200,2,14.56,800,2,12.43,700,1,14.58,100,1,12.42,700,1,14.60,700,1,12.37,700,1,14.64,100,1,ARL,321225725
2025-07-17T15:58:58.668252306Z,2025-07-17T15:58:58.668086788Z,10,2,1108,C,A,0,13.81,100,0,165518,268321684,13.04,2,1,13.78,100,1,13.03,100,1,14.10,2,1,13.02,100,1,14.11,100,1,12.73,100,1,14.28,100,1,12.71,100,1,14.40,100,1,12.50,700,1,14.56,800,2,12.46,200,2,14.58,100,1,12.43,700,1,14.60,700,1,12.42,700,1,14.64,100,1,12.37,700,1,14.65,100,1,ARL,321272581
2025-07-17T15:58:58.668252306Z,2025-07-17T15:58:58.668086788Z,10,2,1108,A,A,0,13.79,100,130,165518,268321684,13.04,2,1,13.78,100,1,13.03,100,1,13.79,100,1,13.02,100,1,14.10,2,1,12.73,100,1,14.11,100,1,12.71,100,1,14.28,100,1,12.50,700,1,14.40,100,1,12.46,200,2,14.56,800,2,12.43,700,1,14.58,100,1,12.42,700,1,14.60,700,1,12.37,700,1,14.64,100,1,ARL,321364281
2025-07-17T15:59:03.613692913Z,2025-07-17T15:59:03.613527621Z,10,2,1108,A,A,0,13.72,15,130,165292,268437919,13.04,2,1,13.72,15,1,13.03,100,1,13.78,100,1,13.02,100,1,13.79,100,1,12.73,100,1,14.10,2,1,12.71,100,1,14.11,100,1,12.50,700,1,14.28,100,1,12.46,200,2,14.40,100,1,12.43,700,1,14.56,800,2,12.42,700,1,14.58,100,1,12.37,700,1,14.60,700,1,ARL,321500117
2025-07-17T15:59:03.626346616Z,2025-07-17T15:59:03.626181384Z,10,2,1108,A,A,0,13.76,100,130,165232,268438110,13.04,2,1,13.72,15,1,13.03,100,1,13.76,100,1,13.02,100,1,13.78,100,1,12.73,100,1,13.79,100,1,12.71,100,1,14.10,2,1,12.50,700,1,14.11,100,1,12.46,200,2,14.28,100,1,12.43,700,1,14.40,100,1,12.42,700,1,14.56,800,2,12.37,700,1,14.58,100,1,ARL,321500317
2025-07-17T15:59:03.627086888Z,2025-07-17T15:59:03.626920954Z,10,2,1108,C,A,0,14.87,100,0,165934,268438112,13.04,2,1,13.72,15,1,13.03,100,1,13.76,100,1,13.02,100,1,13.78,100,1,12.73,100,1,13.79,100,1,12.71,100,1,14.10,2,1,12.50,700,1,14.11,100,1,12.46,200,2,14.28,100,1,12.43,700,1,14.40,100,1,12.42,700,1,14.56,800,2,12.37,700,1,14.58,100,1,ARL,321225745
2025-07-17T15:59:03.627086888Z,2025-07-17T15:59:03.626920954Z,10,2,1108,A,A,0,14.83,100,130,165934,268438112,13.04,2,1,13.72,15,1,13.03,100,1,13.76,100,1,13.02,100,1,13.78,100,1,12.73,100,1,13.79,100,1,12.71,100,1,14.10,2,1,12.50,700,1,14.11,100,1,12.46,200,2,14.28,100,1,12.43,700,1,14.40,100,1,12.42,700,1,14.56,800,2,12.37,700,1,14.58,100,1,ARL,321500333
2025-07-17T15:59:03.628945278Z,2025-07-17T15:59:03.628779364Z,10,2,1108,C,A,0,14.89,100,0,165914,268438129,13.04,2,1,13.72,15,1,13.03,100,1,13.76,100,1,13.02,100,1,13.78,100,1,12.73,100,1,13.79,100,1,12.71,100,1,14.10,2,1,12.50,700,1,14.11,100,1,12.46,200,2,14.28,100,1,12.43,700,1,14.40,100,1,12.42,700,1,14.56,800,2,12.37,700,1,14.58,100,1,ARL,312771785
2025-07-17T15:59:03.628945278Z,2025-07-17T15:59:03.628779364Z,10,2,1108,A,A,0,14.73,100,130,165914,268438129,13.04,2,1,13.72,15,1,13.03,100,1,13.76,100,1,13.02,100,1,13.78,100,1,12.73,100,1,13.79,100,1,12.71,100,1,14.10,2,1,12.50,700,1,14.11,100,1,12.46,200,2,14.28,100,1,12.43,700,1,14.40,100,1,12.42,700,1,14.56,800,2,12.37,700,1,14.58,100,1,ARL,321500349
2025-07-17T15:59:03.633093258Z,2025-07-17T15:59:03.632928023Z,10,2,1108,C,A,0,13.78,100,130,165235,268438149,13.04,2,1,13.72,15,1,13.03,100,1,13.76,100,1,13.02,100,1,13.79,100,1,12.73,100,1,14.10,2,1,12.71,100,1,14.11,100,1,12.50,700,1,14.28,100,1,12.46,200,2,14.40,100,1,12.43,700,1,14.56,800,2,12.42,700,1,14.58,100,1,12.37,700,1,14.60,700,1,ARL,321309865
2025-07-17T15:59:03.649282063Z,2025-07-17T15:59:03.649116452Z,10,2,1108,C,A,0,14.11,100,130,165611,268438330,13.04,2,1,13.72,15,1,13.03,100,1,13.76,100,1,13.02,100,1,13.79,100,1,12.73,100,1,14.10,2,1,12.71,100,1,14.28,100,1,12.50,700,1,14.40,100,1,12.46,200,2,14.56,800,2,12.43,700,1,14.58,100,1,12.42,700,1,14.60,700,1,12.37,700,1,14.64,100,1,ARL,321114729
2025-07-17T15:59:03.649332873Z,2025-07-17T15:59:03.649167617Z,10,2,1108,A,A,0,14.04,100,130,165256,268438331,13.04,2,1,13.72,15,1,13.03,100,1,13.76,100,1,13.02,100,1,13.79,100,1,12.73,100,1,14.04,100,1,12.71,100,1,14.10,2,1,12.50,700,1,14.28,100,1,12.46,200,2,14.40,100,1,12.43,700,1,14.56,800,2,12.42,700,1,14.58,100,1,12.37,700,1,14.60,700,1,ARL,321500957
2025-07-17T15:59:04.224000805Z,2025-07-17T15:59:04.223835151Z,10,2,1108,C,A,0,13.79,100,0,165654,268447989,13.04,2,1,13.72,15,1,13.03,100,1,13.76,100,1,13.02,100,1,14.04,100,1,12.73,100,1,14.10,2,1,12.71,100,1,14.28,100,1,12.50,700,1,14.40,100,1,12.46,200,2,14.56,800,2,12.43,700,1,14.58,100,1,12.42,700,1,14.60,700,1,12.37,700,1,14.64,100,1,ARL,321364281
2025-07-17T15:59:04.224000805Z,2025-07-17T15:59:04.223835151Z,10,2,1108,A,A,0,13.73,100,130,165654,268447989,13.04,2,1,13.72,15,1,13.03,100,1,13.73,100,1,13.02,100,1,13.76,100,1,12.73,100,1,14.04,100,1,12.71,100,1,14.10,2,1,12.50,700,1,14.28,100,1,12.46,200,2,14.40,100,1,12.43,700,1,14.56,800,2,12.42,700,1,14.58,100,1,12.37,700,1,14.60,700,1,ARL,321511377
2025-07-17T15:59:04.224749333Z,2025-07-17T15:59:04.224583946Z,10,2,1108,C,A,0,14.83,100,0,165387,268448014,13.04,2,1,13.72,15,1,13.03,100,1,13.73,100,1,13.02,100,1,13.76,100,1,12.73,100,1,14.04,100,1,12.71,100,1,14.10,2,1,12.50,700,1,14.28,100,1,12.46,200,2,14.40,100,1,12.43,700,1,14.56,800,2,12.42,700,1,14.58,100,1,12.37,700,1,14.60,700,1,ARL,321500333
2025-07-17T15:59:04.224749333Z,2025-07-17T15:59:04.224583946Z,10,2,1108,A,A,0,14.79,100,130,165387,268448014,13.04,2,1,13.72,15,1,13.03,100,1,13.73,100,1,13.02,100,1,13.76,100,1,12.73,100,1,14.04,100,1,12.71,100,1,14.10,2,1,12.50,700,1,14.28,100,1,12.46,200,2,14.40,100,1,12.43,700,1,14.56,800,2,12.42,700,1,14.58,100,1,12.37,700,1,14.60,700,1,ARL,321511477
2025-07-17T15:59:04.799998642Z,2025-07-17T15:59:04.799833206Z,10,2,1108,C,A,0,13.72,15,130,165436,268457531,13.04,2,1,13.73,100,1,13.03,100,1,13.76,100,1,13.02,100,1,14.04,100,1,12.73,100,1,14.10,2,1,12.71,100,1,14.28,100,1,12.50,700,1,14.40,100,1,12.46,200,2,14.56,800,2,12.43,700,1,14.58,100,1,12.42,700,1,14.60,700,1,12.37,700,1,14.64,100,1,ARL,321500117
2025-07-17T16:00:13.989937414Z,2025-07-17T16:00:13.989771852Z,10,2,1108,C,A,0,14.10,2,0,165562,269514876,13.04,2,1,13.73,100,1,13.03,100,1,13.76,100,1,13.02,100,1,14.04,100,1,12.73,100,1,14.28,100,1,12.71,100,1,14.40,100,1,12.50,700,1,14.56,800,2,12.46,200,2,14.58,100,1,12.43,700,1,14.60,700,1,12.42,700,1,14.64,100,1,12.37,700,1,14.65,100,1,ARL,316098525
2025-07-17T16:00:13.989937414Z,2025-07-17T16:00:13.989771852Z,10,2,1108,A,A,0,14.01,2,130,165562,269514876,13.04,2,1,13.73,100,1,13.03,100,1,13.76,100,1,13.02,100,1,14.01,2,1,12.73,100,1,14.04,100,1,12.71,100,1,14.28,100,1,12.50,700,1,14.40,100,1,12.46,200,2,14.56,800,2,12.43,700,1,14.58,100,1,12.42,700,1,14.60,700,1,12.37,700,1,14.64,100,1,ARL,322898193
2025-07-17T16:00:28.803015930Z,2025-07-17T16:00:28.802849928Z,10,2,1108,A,A,0,13.72,15,130,166002,269765653,13.04,2,1,13.72,15,1,13.03,100,1,13.73,100,1,13.02,100,1,13.76,100,1,12.73,100,1,14.01,2,1,12.71,100,1,14.04,100,1,12.50,700,1,14.28,100,1,12.46,200,2,14.40,100,1,12.43,700,1,14.56,800,2,12.42,700,1,14.58,100,1,12.37,700,1,14.60,700,1,ARL,323238809
2025-07-17T16:00:32.549412616Z,2025-07-17T16:00:32.549247168Z,10,2,1108,A,A,0,13.74,100,130,165448,269878282,13.04,2,1,13.72,15,1,13.03,100,1,13.73,100,1,13.02,100,1,13.74,100,1,12.73,100,1,13.76,100,1,12.71,100,1,14.01,2,1,12.50,700,1,14.04,100,1,12.46,200,2,14.28,100,1,12.43,700,1,14.40,100,1,12.42,700,1,14.56,800,2,12.37,700,1,14.58,100,1,ARL,323370569
2025-07-17T16:00:32.560989093Z,2025-07-17T16:00:32.560823786Z,10,2,1108,C,A,0,13.76,100,130,165307,269878639,13.04,2,1,13.72,15,1,13.03,100,1,13.73,100,1,13.02,100,1,13.74,100,1,12.73,100,1,14.01,2,1,12.71,100,1,14.04,100,1,12.50,700,1,14.28,100,1,12.46,200,2,14.40,100,1,12.43,700,1,14.56,800,2,12.42,700,1,14.58,100,1,12.37,700,1,14.60,700,1,ARL,321500317
2025-07-17T16:00:35.513164458Z,2025-07-17T16:00:35.512999155Z,10,2,1108,A,A,0,13.69,15,130,165303,269940539,13.04,2,1,13.69,15,1,13.03,100,1,13.72,15,1,13.02,100,1,13.73,100,1,12.73,100,1,13.74,100,1,12.71,100,1,14.01,2,1,12.50,700,1,14.04,100,1,12.46,200,2,14.28,100,1,12.43,700,1,14.40,100,1,12.42,700,1,14.56,800,2,12.37,700,1,14.58,100,1,ARL,323455221
2025-07-17T16:00:42.614229184Z,2025-07-17T16:00:42.614063415Z,10,2,1108,C,A,0,13.73,100,0,165769,270051089,13.04,2,1,13.69,15,1,13.03,100,1,13.72,15,1,13.02,100,1,13.74,100,1,12.73,100,1,14.01,2,1,12.71,100,1,14.04,100,1,12.50,700,1,14.28,100,1,12.46,200,2,14.40,100,1,12.43,700,1,14.56,800,2,12.42,700,1,14.58,100,1,12.37,700,1,14.60,700,1,ARL,321511377
2025-07-17T16:00:42.614229184Z,2025-07-17T16:00:42.614063415Z,10,2,1108,A,A,0,13.70,100,130,165769,270051089,13.04,2,1,13.69,15,1,13.03,100,1,13.70,100,1,13.02,100,1,13.72,15,1,12.73,100,1,13.74,100,1,12.71,100,1,14.01,2,1,12.50,700,1,14.04,100,1,12.46,200,2,14.28,100,1,12.43,700,1,14.40,100,1,12.42,700,1,14.56,800,2,12.37,700,1,14.58,100,1,ARL,323599605
2025-07-17T16:00:42.614254199Z,2025-07-17T16:00:42.614088947Z,10,2,1108,A,A,0,13.72,100,130,165252,270051090,13.04,2,1,13.69,15,1,13.03,100,1,13.70,100,1,13.02,100,1,13.72,115,2,12.73,100,1,13.74,100,1,12.71,100,1,14.01,2,1,12.50,700,1,14.04,100,1,12.46,200,2,14.28,100,1,12.43,700,1,14.40,100,1,12.42,700,1,14.56,800,2,12.37,700,1,14.58,100,1,ARL,323599609
2025-07-17T16:00:42.614396214Z,2025-07-17T16:00:42.614231125Z,10,2,1108,C,A,0,13.74,100,130,165089,270051092,13.04,2,1,13.69,15,1,13.03,100,1,13.70,100,1,13.02,100,1,13.72,115,2,12.73,100,1,14.01,2,1,12.71,100,1,14.04,100,1,12.50,700,1,14.28,100,1,12.46,200,2,14.40,100,1,12.43,700,1,14.56,800,2,12.42,700,1,14.58,100,1,12.37,700,1,14.60,700,1,ARL,323370569
2025-07-17T16:00:42.616178962Z,2025-07-17T16:00:42.616013371Z,10,2,1108,C,A,0,14.81,100,0,165591,270051093,13.04,2,1,13.69,15,1,13.03,100,1,13.70,100,1,13.02,100,1,13.72,115,2,12.73,100,1,14.01,2,1,12.71,100,1,14.04,100,1,12.50,700,1,14.28,100,1,12.46,200,2,14.40,100,1,12.43,700,1,14.56,800,2,12.42,700,1,14.58,100,1,12.37,700,1,14.60,700,1,ARL,321097197
2025-07-17T16:00:42.616178962Z,2025-07-17T16:00:42.616013371Z,10,2,1108,A,A,0,14.66,100,130,165591,270051093,13.04,2,1,13.69,15,1,13.03,100,1,13.70,100,1,13.02,100,1,13.72,115,2,12.73,100,1,14.01,2,1,12.71,100,1,14.04,100,1,12.50,700,1,14.28,100,1,12.46,200,2,14.40,100,1,12.43,700,1,14.56,800,2,12.42,700,1,14.58,100,1,12.37,700,1,14.60,700,1,ARL,323599625
2025-07-17T16:00:42.616321879Z,2025-07-17T16:00:42.616156310Z,10,2,1108,C,A,0,15.92,100,0,165569,270051094,13.04,2,1,13.69,15,1,13.03,100,1,13.70,100,1,13.02,100,1,13.72,115,2,12.73,100,1,14.01,2,1,12.71,100,1,14.04,100,1,12.50,700,1,14.28,100,1,12.46,200,2,14.40,100,1,12.43,700,1,14.56,800,2,12.42,700,1,14.58,100,1,12.37,700,1,14.60,700,1,ARL,321096889
2025-07-17T16:00:42.616321879Z,2025-07-17T16:00:42.616156310Z,10,2,1108,A,A,0,15.76,100,130,165569,270051094,13.04,2,1,13.69,15,1,13.03,100,1,13.70,100,1,13.02,100,1,13.72,115,2,12.73,100,1,14.01,2,1,12.71,100,1,14.04,100,1,12.50,700,1,14.28,100,1,12.46,200,2,14.40,100,1,12.43,700,1,14.56,800,2,12.42,700,1,14.58,100,1,12.37,700,1,14.60,700,1,ARL,323599629
2025-07-17T16:00:42.616352247Z,2025-07-17T16:00:42.616186901Z,10,2,1108,C,A,0,17.58,100,0,165346,270051095,13.04,2,1,13.69,15,1,13.03,100,1,13.70,100,1,13.02,100,1,13.72,115,2,12.73,100,1,14.01,2,1,12.71,100,1,14.04,100,1,12.50,700,1,14.28,100,1,12.46,200,2,14.40,100,1,12.43,700,1,14.56,800,2,12.42,700,1,14.58,100,1,12.37,700,1,14.60,700,1,ARL,321096825
2025-07-17T16:00:42.616352247Z,2025-07-17T16:00:42.616186901Z,10,2,1108,A,A,0,17.40,100,130,165346,270051095,13.04,2,1,13.69,15,1,13.03,100,1,13.70,100,1,13.02,100,1,13.72,115,2,12.73,100,1,14.01,2,1,12.71,100,1,14.04,100,1,12.50,700,1,14.28,100,1,12.46,200,2,14.40,100,1,12.43,700,1,14.56,800,2,12.42,700,1,14.58,100,1,12.37,700,1,14.60,700,1,ARL,323599633
2025-07-17T16:00:42.636761176Z,2025-07-17T16:00:42.636595817Z,10,2,1108,C,A,0,14.04,100,130,165359,270051179,13.04,2,1,13.69,15,1,13.03,100,1,13.70,100,1,13.02,100,1,13.72,115,2,12.73,100,1,14.01,2,1,12.71,100,1,14.28,100,1,12.50,700,1,14.40,100,1,12.46,200,2,14.56,800,2,12.43,700,1,14.58,100,1,12.42,700,1,14.60,700,1,12.37,700,1,14.64,100,1,ARL,321500957
2025-07-17T16:00:42.636814704Z,2025-07-17T16:00:42.636649389Z,10,2,1108,A,A,0,13.97,100,130,165315,270051181,13.04,2,1,13.69,15,1,13.03,100,1,13.70,100,1,13.02,100,1,13.72,115,2,12.73,100,1,13.97,100,1,12.71,100,1,14.01,2,1,12.50,700,1,14.28,100,1,12.46,200,2,14.40,100,1,12.43,700,1,14.56,800,2,12.42,700,1,14.58,100,1,12.37,700,1,14.60,700,1,ARL,323599765
2025-07-17T16:00:46.803262460Z,2025-07-17T16:00:46.803097192Z,10,2,1108,C,A,0,13.72,15,130,165268,270102799,13.04,2,1,13.69,15,1,13.03,100,1,13.70,100,1,13.02,100,1,13.72,100,1,12.73,100,1,13.97,100,1,12.71,100,1,14.01,2,1,12.50,700,1,14.28,100,1,12.46,200,2,14.40,100,1,12.43,700,1,14.56,800,2,12.42,700,1,14.58,100,1,12.37,700,1,14.60,700,1,ARL,323238809
2025-07-17T16:00:49.255631264Z,2025-07-17T16:00:49.255465939Z,10,2,1108,A,A,0,13.66,15,130,165325,270140405,13.04,2,1,13.66,15,1,13.03,100,1,13.69,15,1,13.02,100,1,13.70,100,1,12.73,100,1,13.72,100,1,12.71,100,1,13.97,100,1,12.50,700,1,14.01,2,1,12.46,200,2,14.28,100,1,12.43,700,1,14.40,100,1,12.42,700,1,14.56,800,2,12.37,700,1,14.58,100,1,ARL,323720189
2025-07-17T16:00:49.739644604Z,2025-07-17T16:00:49.739479408Z,10,2,1108,A,A,0,13.70,100,130,165196,270146528,13.04,2,1,13.66,15,1,13.03,100,1,13.69,15,1,13.02,100,1,13.70,200,2,12.73,100,1,13.72,100,1,12.71,100,1,13.97,100,1,12.50,700,1,14.01,2,1,12.46,200,2,14.28,100,1,12.43,700,1,14.40,100,1,12.42,700,1,14.56,800,2,12.37,700,1,14.58,100,1,ARL,323730309
2025-07-17T16:00:49.745038261Z,2025-07-17T16:00:49.744872763Z,10,2,1108,C,A,0,13.70,100,0,165498,270146577,13.04,2,1,13.66,15,1,13.03,100,1,13.69,15,1,13.02,100,1,13.70,100,1,12.73,100,1,13.72,100,1,12.71,100,1,13.97,100,1,12.50,700,1,14.01,2,1,12.46,200,2,14.28,100,1,12.43,700,1,14.40,100,1,12.42,700,1,14.56,800,2,12.37,700,1,14.58,100,1,ARL,323599605
2025-07-17T16:00:49.745038261Z,2025-07-17T16:00:49.744872763Z,10,2,1108,A,A,0,13.67,100,130,165498,270146577,13.04,2,1,13.66,15,1,13.03,100,1,13.67,100,1,13.02,100,1,13.69,15,1,12.73,100,1,13.70,100,1,12.71,100,1,13.72,100,1,12.50,700,1,13.97,100,1,12.46,200,2,14.01,2,1,12.43,700,1,14.28,100,1,12.42,700,1,14.40,100,1,12.37,700,1,14.56,800,2,ARL,323730353
2025-07-17T16:00:49.745778725Z,2025-07-17T16:00:49.745613051Z,10,2,1108,C,A,0,14.79,100,0,165674,270146581,13.04,2,1,13.66,15,1,13.03,100,1,13.67,100,1,13.02,100,1,13.69,15,1,12.73,100,1,13.70,100,1,12.71,100,1,13.72,100,1,12.50,700,1,13.97,100,1,12.46,200,2,14.01,2,1,12.43,700,1,14.28,100,1,12.42,700,1,14.40,100,1,12.37,700,1,14.56,800,2,ARL,321511477
2025-07-17T16:00:49.745778725Z,2025-07-17T16:00:49.745613051Z,10,2,1108,A,A,0,14.73,100,130,165674,270146581,13.04,2,1,13.66,15,1,13.03,100,1,13.67,100,1,13.02,100,1,13.69,15,1,12.73,100,1,13.70,100,1,12.71,100,1,13.72,100,1,12.50,700,1,13.97,100,1,12.46,200,2,14.01,2,1,12.43,700,1,14.28,100,1,12.42,700,1,14.40,100,1,12.37,700,1,14.56,800,2,ARL,323730369
2025-07-17T16:00:49.746422142Z,2025-07-17T16:00:49.746256906Z,10,2,1108,C,A,0,13.72,100,130,165236,270146586,13.04,2,1,13.66,15,1,13.03,100,1,13.67,100,1,13.02,100,1,13.69,15,1,12.73,100,1,13.70,100,1,12.71,100,1,13.97,100,1,12.50,700,1,14.01,2,1,12.46,200,2,14.28,100,1,12.43,700,1,14.40,100,1,12.42,700,1,14.56,800,2,12.37,700,1,14.58,100,1,ARL,323599609
2025-07-17T16:00:49.772631967Z,2025-07-17T16:00:49.772466772Z,10,2,1108,A,A,0,15.59,100,130,165195,270146838,13.04,2,1,13.66,15,1,13.03,100,1,13.67,100,1,13.02,100,1,13.69,15,1,12.73,100,1,13.70,100,1,12.71,100,1,13.97,100,1,12.50,700,1,14.01,2,1,12.46,200,2,14.28,100,1,12.43,700,1,14.40,100,1,12.42,700,1,14.56,800,2,12.37,700,1,14.58,100,1,ARL,323730697
2025-07-17T16:00:49.772645303Z,2025-07-17T16:00:49.772479921Z,10,2,1108,C,A,0,15.86,100,130,165382,270146839,13.04,2,1,13.66,15,1,13.03,100,1,13.67,100,1,13.02,100,1,13.69,15,1,12.73,100,1,13.70,100,1,12.71,100,1,13.97,100,1,12.50,700,1,14.01,2,1,12.46,200,2,14.28,100,1,12.43,700,1,14.40,100,1,12.42,700,1,14.56,800,2,12.37,700,1,14.58,100,1,ARL,312771645
2025-07-17T16:00:51.624811889Z,2025-07-17T16:00:51.624646272Z,10,2,1108,C,A,0,14.65,100,0,165617,270181394,13.04,2,1,13.66,15,1,13.03,100,1,13.67,100,1,13.02,100,1,13.69,15,1,12.73,100,1,13.70,100,1,12.71,100,1,13.97,100,1,12.50,700,1,14.01,2,1,12.46,200,2,14.28,100,1,12.43,700,1,14.40,100,1,12.42,700,1,14.56,800,2,12.37,700,1,14.58,100,1,ARL,321293737
2025-07-17T16:00:51.624811889Z,2025-07-17T16:00:51.624646272Z,10,2,1108,A,A,0,14.54,100,130,165617,270181394,13.04,2,1,13.66,15,1,13.03,100,1,13.67,100,1,13.02,100,1,13.69,15,1,12.73,100,1,13.70,100,1,12.71,100,1,13.97,100,1,12.50,700,1,14.01,2,1,12.46,200,2,14.28,100,1,12.43,700,1,14.40,100,1,12.42,700,1,14.54,100,1,12.37,700,1,14.56,800,2,ARL,323775433
2025-07-17T16:00:51.625372516Z,2025-07-17T16:00:51.625206675Z,10,2,1108,C,A,0,14.64,100,0,165841,270181399,13.04,2,1,13.66,15,1,13.03,100,1,13.67,100,1,13.02,100,1,13.69,15,1,12.73,100,1,13.70,100,1,12.71,100,1,13.97,100,1,12.50,700,1,14.01,2,1,12.46,200,2,14.28,100,1,12.43,700,1,14.40,100,1,12.42,700,1,14.54,100,1,12.37,700,1,14.56,800,2,ARL,321293741
2025-07-17T16:00:51.625372516Z,2025-07-17T16:00:51.625206675Z,10,2,1108,A,A,0,14.53,100,130,165841,270181399,13.04,2,1,13.66,15,1,13.03,100,1,13.67,100,1,13.02,100,1,13.69,15,1,12.73,100,1,13.70,100,1,12.71,100,1,13.97,100,1,12.50,700,1,14.01,2,1,12.46,200,2,14.28,100,1,12.43,700,1,14.40,100,1,12.42,700,1,14.53,100,1,12.37,700,1,14.54,100,1,ARL,323775457
2025-07-17T16:00:53.749335010Z,2025-07-17T16:00:53.749169565Z,10,2,1108,A,A,0,13.67,100,130,165445,270204567,13.04,2,1,13.66,15,1,13.03,100,1,13.67,200,2,13.02,100,1,13.69,15,1,12.73,100,1,13.70,100,1,12.71,100,1,13.97,100,1,12.50,700,1,14.01,2,1,12.46,200,2,14.28,100,1,12.43,700,1,14.40,100,1,12.42,700,1,14.53,100,1,12.37,700,1,14.54,100,1,ARL,323803301
2025-07-17T16:00:53.755966680Z,2025-07-17T16:00:53.755801462Z,10,2,1108,C,A,0,13.70,100,130,165218,270204616,13.04,2,1,13.66,15,1,13.03,100,1,13.67,200,2,13.02,100,1,13.69,15,1,12.73,100,1,13.97,100,1,12.71,100,1,14.01,2,1,12.50,700,1,14.28,100,1,12.46,200,2,14.40,100,1,12.43,700,1,14.53,100,1,12.42,700,1,14.54,100,1,12.37,700,1,14.56,800,2,ARL,323730309
2025-07-17T16:01:00.801342739Z,2025-07-17T16:01:00.801177403Z,10,2,1108,C,A,0,13.69,15,130,165336,270319932,13.04,2,1,13.66,15,1,13.03,100,1,13.67,200,2,13.02,100,1,13.97,100,1,12.73,100,1,14.01,2,1,12.71,100,1,14.28,100,1,12.50,700,1,14.40,100,1,12.46,200,2,14.53,100,1,12.43,700,1,14.54,100,1,12.42,700,1,14.56,800,2,12.37,700,1,14.58,100,1,ARL,323455221
2025-07-17T16:01:10.802877570Z,2025-07-17T16:01:10.802712247Z,10,2,1108,A,A,0,13.62,15,130,165323,270493149,13.04,2,1,13.62,15,1,13.03,100,1,13.66,15,1,13.02,100,1,13.67,200,2,12.73,100,1,13.97,100,1,12.71,100,1,14.01,2,1,12.50,700,1,14.28,100,1,12.46,200,2,14.40,100,1,12.43,700,1,14.53,100,1,12.42,700,1,14.54,100,1,12.37,700,1,14.56,800,2,ARL,324161541
2025-07-17T16:01:11.418837472Z,2025-07-17T16:01:11.418671671Z,10,2,1108,A,A,0,13.65,100,130,165801,270503944,13.04,2,1,13.62,15,1,13.03,100,1,13.65,100,1,13.02,100,1,13.66,15,1,12.73,100,1,13.67,200,2,12.71,100,1,13.97,100,1,12.50,700,1,14.01,2,1,12.46,200,2,14.28,100,1,12.43,700,1,14.40,100,1,12.42,700,1,14.53,100,1,12.37,700,1,14.54,100,1,ARL,324175569
2025-07-17T16:01:11.425922184Z,2025-07-17T16:01:11.425757014Z,10,2,1108,C,A,0,13.67,100,130,165170,270504009,13.04,2,1,13.62,15,1,13.03,100,1,13.65,100,1,13.02,100,1,13.66,15,1,12.73,100,1,13.67,100,1,12.71,100,1,13.97,100,1,12.50,700,1,14.01,2,1,12.46,200,2,14.28,100,1,12.43,700,1,14.40,100,1,12.42,700,1,14.53,100,1,12.37,700,1,14.54,100,1,ARL,323803301
2025-07-17T16:01:11.820753616Z,2025-07-17T16:01:11.820588141Z,10,2,1108,C,A,0,13.67,100,0,165475,270509970,13.04,2,1,13.62,15,1,13.03,100,1,13.65,100,1,13.02,100,1,13.66,15,1,12.73,100,1,13.97,100,1,12.71,100,1,14.01,2,1,12.50,700,1,14.28,100,1,12.46,200,2,14.40,100,1,12.43,700,1,14.53,100,1,12.42,700,1,14.54,100,1,12.37,700,1,14.56,800,2,ARL,323730353
2025-07-17T16:01:11.820753616Z,2025-07-17T16:01:11.820588141Z,10,2,1108,A,A,0,13.63,100,130,165475,270509970,13.04,2,1,13.62,15,1,13.03,100,1,13.63,100,1,13.02,100,1,13.65,100,1,12.73,100,1,13.66,15,1,12.71,100,1,13.97,100,1,12.50,700,1,14.01,2,1,12.46,200,2,14.28,100,1,12.43,700,1,14.40,100,1,12.42,700,1,14.53,100,1,12.37,700,1,14.54,100,1,ARL,324186213
2025-07-17T16:01:11.821515043Z,2025-07-17T16:01:11.821349600Z,10,2,1108,C,A,0,14.73,100,0,165443,270509983,13.04,2,1,13.62,15,1,13.03,100,1,13.63,100,1,13.02,100,1,13.65,100,1,12.73,100,1,13.66,15,1,12.71,100,1,13.97,100,1,12.50,700,1,14.01,2,1,12.46,200,2,14.28,100,1,12.43,700,1,14.40,100,1,12.42,700,1,14.53,100,1,12.37,700,1,14.54,100,1,ARL,323730369
2025-07-17T16:01:11.821515043Z,2025-07-17T16:01:11.821349600Z,10,2,1108,A,A,0,14.69,100,130,165443,270509983,13.04,2,1,13.62,15,1,13.03,100,1,13.63,100,1,13.02,100,1,13.65,100,1,12.73,100,1,13.66,15,1,12.71,100,1,13.97,100,1,12.50,700,1,14.01,2,1,12.46,200,2,14.28,100,1,12.43,700,1,14.40,100,1,12.42,700,1,14.53,100,1,12.37,700,1,14.54,100,1,ARL,324186233
2025-07-17T16:01:11.826399871Z,2025-07-17T16:01:11.826234488Z,10,2,1108,C,A,0,13.97,100,130,165383,270510142,13.04,2,1,13.62,15,1,13.03,100,1,13.63,100,1,13.02,100,1,13.65,100,1,12.73,100,1,13.66,15,1,12.71,100,1,14.01,2,1,12.50,700,1,14.28,100,1,12.46,200,2,14.40,100,1,12.43,700,1,14.53,100,1,12.42,700,1,14.54,100,1,12.37,700,1,14.56,800,2,ARL,323599765
2025-07-17T16:01:11.826451447Z,2025-07-17T16:01:11.826286284Z,10,2,1108,A,A,0,13.90,100,130,165163,270510143,13.04,2,1,13.62,15,1,13.03,100,1,13.63,100,1,13.02,100,1,13.65,100,1,12.73,100,1,13.66,15,1,12.71,100,1,13.90,100,1,12.50,700,1,14.01,2,1,12.46,200,2,14.28,100,1,12.43,700,1,14.40,100,1,12.42,700,1,14.53,100,1,12.37,700,1,14.54,100,1,ARL,324186721
2025-07-17T16:01:11.828630414Z,2025-07-17T16:01:11.828464891Z,10,2,1108,C,A,0,14.58,100,0,165523,270510182,13.04,2,1,13.62,15,1,13.03,100,1,13.63,100,1,13.02,100,1,13.65,100,1,12.73,100,1,13.66,15,1,12.71,100,1,13.90,100,1,12.50,700,1,14.01,2,1,12.46,200,2,14.28,100,1,12.43,700,1,14.40,100,1,12.42,700,1,14.53,100,1,12.37,700,1,14.54,100,1,ARL,321309941
2025-07-17T16:01:11.828630414Z,2025-07-17T16:01:11.828464891Z,10,2,1108,A,A,0,14.43,100,130,165523,270510182,13.04,2,1,13.62,15,1,13.03,100,1,13.63,100,1,13.02,100,1,13.65,100,1,12.73,100,1,13.66,15,1,12.71,100,1,13.90,100,1,12.50,700,1,14.01,2,1,12.46,200,2,14.28,100,1,12.43,700,1,14.40,100,1,12.42,700,1,14.43,100,1,12.37,700,1,14.53,100,1,ARL,324186781
2025-07-17T16:01:22.802518536Z,2025-07-17T16:01:22.802353061Z,10,2,1108,C,A,0,13.66,15,130,165475,270674903,13.04,2,1,13.62,15,1,13.03,100,1,13.63,100,1,13.02,100,1,13.65,100,1,12.73,100,1,13.90,100,1,12.71,100,1,14.01,2,1,12.50,700,1,14.28,100,1,12.46,200,2,14.40,100,1,12.43,700,1,14.43,100,1,12.42,700,1,14.53,100,1,12.37,700,1,14.54,100,1,ARL,323720189
2025-07-17T16:01:32.804004639Z,2025-07-17T16:01:32.803839043Z,10,2,1108,A,A,0,13.60,15,130,165596,270824320,13.04,2,1,13.60,15,1,13.03,100,1,13.62,15,1,13.02,100,1,13.63,100,1,12.73,100,1,13.65,100,1,12.71,100,1,13.90,100,1,12.50,700,1,14.01,2,1,12.46,200,2,14.28,100,1,12.43,700,1,14.40,100,1,12.42,700,1,14.43,100,1,12.37,700,1,14.53,100,1,ARL,324619361
2025-07-17T16:01:32.804274168Z,2025-07-17T16:01:32.804108576Z,10,2,1108,C,A,0,13.63,100,0,165592,270824323,13.04,2,1,13.60,15,1,13.03,100,1,13.62,15,1,13.02,100,1,13.65,100,1,12.73,100,1,13.90,100,1,12.71,100,1,14.01,2,1,12.50,700,1,14.28,100,1,12.46,200,2,14.40,100,1,12.43,700,1,14.43,100,1,12.42,700,1,14.53,100,1,12.37,700,1,14.54,100,1,ARL,324186213
2025-07-17T16:01:32.804274168Z,2025-07-17T16:01:32.804108576Z,10,2,1108,A,A,0,13.61,100,130,165592,270824323,13.04,2,1,13.60,15,1,13.03,100,1,13.61,100,1,13.02,100,1,13.62,15,1,12.73,100,1,13.65,100,1,12.71,100,1,13.90,100,1,12.50,700,1,14.01,2,1,12.46,200,2,14.28,100,1,12.43,700,1,14.40,100,1,12.42,700,1,14.43,100,1,12.37,700,1,14.53,100,1,ARL,324619369
2025-07-17T16:01:32.806299464Z,2025-07-17T16:01:32.806134020Z,10,2,1108,C,A,0,14.73,100,0,165444,270824400,13.04,2,1,13.60,15,1,13.03,100,1,13.61,100,1,13.02,100,1,13.62,15,1,12.73,100,1,13.65,100,1,12.71,100,1,13.90,100,1,12.50,700,1,14.01,2,1,12.46,200,2,14.28,100,1,12.43,700,1,14.40,100,1,12.42,700,1,14.43,100,1,12.37,700,1,14.53,100,1,ARL,321500349
2025-07-17T16:01:32.806299464Z,2025-07-17T16:01:32.806134020Z,10,2,1108,A,A,0,14.57,100,130,165444,270824400,13.04,2,1,13.60,15,1,13.03,100,1,13.61,100,1,13.02,100,1,13.62,15,1,12.73,100,1,13.65,100,1,12.71,100,1,13.90,100,1,12.50,700,1,14.01,2,1,12.46,200,2,14.28,100,1,12.43,700,1,14.40,100,1,12.42,700,1,14.43,100,1,12.37,700,1,14.53,100,1,ARL,324619409
2025-07-17T16:01:32.815913520Z,2025-07-17T16:01:32.815748258Z,10,2,1108,A,A,0,13.63,100,130,165262,270824657,13.04,2,1,13.60,15,1,13.03,100,1,13.61,100,1,13.02,100,1,13.62,15,1,12.73,100,1,13.63,100,1,12.71,100,1,13.65,100,1,12.50,700,1,13.90,100,1,12.46,200,2,14.01,2,1,12.43,700,1,14.28,100,1,12.42,700,1,14.40,100,1,12.37,700,1,14.43,100,1,ARL,324619837
2025-07-17T16:01:32.822608966Z,2025-07-17T16:01:32.822443626Z,10,2,1108,C,A,0,13.65,100,130,165340,270824747,13.04,2,1,13.60,15,1,13.03,100,1,13.61,100,1,13.02,100,1,13.62,15,1,12.73,100,1,13.63,100,1,12.71,100,1,13.90,100,1,12.50,700,1,14.01,2,1,12.46,200,2,14.28,100,1,12.43,700,1,14.40,100,1,12.42,700,1,14.43,100,1,12.37,700,1,14.53,100,1,ARL,324175569
2025-07-17T16:01:37.242690420Z,2025-07-17T16:01:37.242525208Z,10,2,1108,C,A,0,13.62,15,130,165212,270889017,13.04,2,1,13.60,15,1,13.03,100,1,13.61,100,1,13.02,100,1,13.63,100,1,12.73,100,1,13.90,100,1,12.71,100,1,14.01,2,1,12.50,700,1,14.28,100,1,12.46,200,2,14.40,100,1,12.43,700,1,14.43,100,1,12.42,700,1,14.53,100,1,12.37,700,1,14.54,100,1,ARL,324161541
2025-07-17T16:01:40.605797765Z,2025-07-17T16:01:40.605632399Z,10,2,1108,A,A,0,13.61,100,130,165366,270946497,13.04,2,1,13.60,15,1,13.03,100,1,13.61,200,2,13.02,100,1,13.63,100,1,12.73,100,1,13.90,100,1,12.71,100,1,14.01,2,1,12.50,700,1,14.28,100,1,12.46,200,2,14.40,100,1,12.43,700,1,14.43,100,1,12.42,700,1,14.53,100,1,12.37,700,1,14.54,100,1,ARL,324782841
2025-07-17T16:01:40.653738176Z,2025-07-17T16:01:40.653572805Z,10,2,1108,C,A,0,13.63,100,130,165371,270946779,13.04,2,1,13.60,15,1,13.03,100,1,13.61,200,2,13.02,100,1,13.90,100,1,12.73,100,1,14.01,2,1,12.71,100,1,14.28,100,1,12.50,700,1,14.40,100,1,12.46,200,2,14.43,100,1,12.43,700,1,14.53,100,1,12.42,700,1,14.54,100,1,12.37,700,1,14.56,800,2,ARL,324619837
2025-07-17T16:01:47.565991684Z,2025-07-17T16:01:47.565825466Z,10,2,1108,A,A,0,13.57,15,128,166218,271062350,13.04,2,1,13.57,15,1,13.03,100,1,13.60,15,1,13.02,100,1,13.61,200,2,12.73,100,1,13.90,100,1,12.71,100,1,14.01,2,1,12.50,700,1,14.28,100,1,12.46,200,2,14.40,100,1,12.43,700,1,14.43,100,1,12.42,700,1,14.53,100,1,12.37,700,1,14.54,100,1,ARL,324934601
2025-07-17T16:01:47.902969773Z,2025-07-17T16:01:47.902804446Z,10,2,1108,C,A,0,13.61,100,0,165327,271068098,13.04,2,1,13.57,15,1,13.03,100,1,13.60,15,1,13.02,100,1,13.61,100,1,12.73,100,1,13.90,100,1,12.71,100,1,14.01,2,1,12.50,700,1,14.28,100,1,12.46,200,2,14.40,100,1,12.43,700,1,14.43,100,1,12.42,700,1,14.53,100,1,12.37,700,1,14.54,100,1,ARL,324619369
2025-07-17T16:01:47.902969773Z,2025-07-17T16:01:47.902804446Z,10,2,1108,A,A,0,13.58,100,130,165327,271068098,13.04,2,1,13.57,15,1,13.03,100,1,13.58,100,1,13.02,100,1,13.60,15,1,12.73,100,1,13.61,100,1,12.71,100,1,13.90,100,1,12.50,700,1,14.01,2,1,12.46,200,2,14.28,100,1,12.43,700,1,14.40,100,1,12.42,700,1,14.43,100,1,12.37,700,1,14.53,100,1,ARL,324942229
2025-07-17T16:01:47.903711757Z,2025-07-17T16:01:47.903546622Z,10,2,1108,C,A,0,14.40,100,130,165135,271068105,13.04,2,1,13.57,15,1,13.03,100,1,13.58,100,1,13.02,100,1,13.60,15,1,12.73,100,1,13.61,100,1,12.71,100,1,13.90,100,1,12.50,700,1,14.01,2,1,12.46,200,2,14.28,100,1,12.43,700,1,14.43,100,1,12.42,700,1,14.53,100,1,12.37,700,1,14.54,100,1,ARL,289726421
2025-07-17T16:01:47.903714323Z,2025-07-17T16:01:47.903548861Z,10,2,1108,C,A,0,14.69,100,0,165462,271068106,13.04,2,1,13.57,15,1,13.03,100,1,13.58,100,1,13.02,100,1,13.60,15,1,12.73,100,1,13.61,100,1,12.71,100,1,13.90,100,1,12.50,700,1,14.01,2,1,12.46,200,2,14.28,100,1,12.43,700,1,14.43,100,1,12.42,700,1,14.53,100,1,12.37,700,1,14.54,100,1,ARL,324186233
2025-07-17T16:01:47.903714323Z,2025-07-17T16:01:47.903548861Z,10,2,1108,A,A,0,14.63,100,130,165462,271068106,13.04,2,1,13.57,15,1,13.03,100,1,13.58,100,1,13.02,100,1,13.60,15,1,12.73,100,1,13.61,100,1,12.71,100,1,13.90,100,1,12.50,700,1,14.01,2,1,12.46,200,2,14.28,100,1,12.43,700,1,14.43,100,1,12.42,700,1,14.53,100,1,12.37,700,1,14.54,100,1,ARL,324942257
2025-07-17T16:01:47.904067686Z,2025-07-17T16:01:47.903902473Z,10,2,1108,A,A,0,14.19,100,130,165213,271068115,13.04,2,1,13.57,15,1,13.03,100,1,13.58,100,1,13.02,100,1,13.60,15,1,12.73,100,1,13.61,100,1,12.71,100,1,13.90,100,1,12.50,700,1,14.01,2,1,12.46,200,2,14.19,100,1,12.43,700,1,14.28,100,1,12.42,700,1,14.43,100,1,12.37,700,1,14.53,100,1,ARL,324942273
2025-07-17T16:01:47.905355779Z,2025-07-17T16:01:47.905189816Z,10,2,1108,C,A,0,15.23,100,0,165963,271068134,13.04,2,1,13.57,15,1,13.03,100,1,13.58,100,1,13.02,100,1,13.60,15,1,12.73,100,1,13.61,100,1,12.71,100,1,13.90,100,1,12.50,700,1,14.01,2,1,12.46,200,2,14.19,100,1,12.43,700,1,14.28,100,1,12.42,700,1,14.43,100,1,12.37,700,1,14.53,100,1,ARL,282776017
2025-07-17T16:01:47.905355779Z,2025-07-17T16:01:47.905189816Z,10,2,1108,A,A,0,14.94,100,130,165963,271068134,13.04,2,1,13.57,15,1,13.03,100,1,13.58,100,1,13.02,100,1,13.60,15,1,12.73,100,1,13.61,100,1,12.71,100,1,13.90,100,1,12.50,700,1,14.01,2,1,12.46,200,2,14.19,100,1,12.43,700,1,14.28,100,1,12.42,700,1,14.43,100,1,12.37,700,1,14.53,100,1,ARL,324942277
2025-07-17T16:01:47.909479724Z,2025-07-17T16:01:47.909314303Z,10,2,1108,C,A,0,17.40,100,0,165421,271068173,13.04,2,1,13.57,15,1,13.03,100,1,13.58,100,1,13.02,100,1,13.60,15,1,12.73,100,1,13.61,100,1,12.71,100,1,13.90,100,1,12.50,700,1,14.01,2,1,12.46,200,2,14.19,100,1,12.43,700,1,14.28,100,1,12.42,700,1,14.43,100,1,12.37,700,1,14.53,100,1,ARL,323599633
2025-07-17T16:01:47.909479724Z,2025-07-17T16:01:47.909314303Z,10,2,1108,A,A,0,17.25,100,130,165421,271068173,13.04,2,1,13.57,15,1,13.03,100,1,13.58,100,1,13.02,100,1,13.60,15,1,12.73,100,1,13.61,100,1,12.71,100,1,13.90,100,1,12.50,700,1,14.01,2,1,12.46,200,2,14.19,100,1,12.43,700,1,14.28,100,1,12.42,700,1,14.43,100,1,12.37,700,1,14.53,100,1,ARL,324942361
2025-07-17T16:01:50.799100504Z,2025-07-17T16:01:50.798934838Z,10,2,1108,A,A,0,13.59,100,130,165666,271131418,13.04,2,1,13.57,15,1,13.03,100,1,13.58,100,1,13.02,100,1,13.59,100,1,12.73,100,1,13.60,15,1,12.71,100,1,13.61,100,1,12.50,700,1,13.90,100,1,12.46,200,2,14.01,2,1,12.43,700,1,14.19,100,1,12.42,700,1,14.28,100,1,12.37,700,1,14.43,100,1,ARL,325022101
2025-07-17T16:01:50.805653961Z,2025-07-17T16:01:50.805488726Z,10,2,1108,C,A,0,13.61,100,130,165235,271131583,13.04,2,1,13.57,15,1,13.03,100,1,13.58,100,1,13.02,100,1,13.59,100,1,12.73,100,1,13.60,15,1,12.71,100,1,13.90,100,1,12.50,700,1,14.01,2,1,12.46,200,2,14.19,100,1,12.43,700,1,14.28,100,1,12.42,700,1,14.43,100,1,12.37,700,1,14.53,100,1,ARL,324782841
2025-07-17T16:01:52.133063761Z,2025-07-17T16:01:52.132898568Z,10,2,1108,C,A,0,13.60,15,130,165193,271153294,13.04,2,1,13.57,15,1,13.03,100,1,13.58,100,1,13.02,100,1,13.59,100,1,12.73,100,1,13.90,100,1,12.71,100,1,14.01,2,1,12.50,700,1,14.19,100,1,12.46,200,2,14.28,100,1,12.43,700,1,14.43,100,1,12.42,700,1,14.53,100,1,12.37,700,1,14.54,100,1,ARL,324619361
2025-07-17T16:01:53.137501962Z,2025-07-17T16:01:53.137336077Z,10,2,1108,A,A,0,13.55,15,130,165885,271200452,13.04,2,1,13.55,15,1,13.03,100,1,13.57,15,1,13.02,100,1,13.58,100,1,12.73,100,1,13.59,100,1,12.71,100,1,13.90,100,1,12.50,700,1,14.01,2,1,12.46,200,2,14.19,100,1,12.43,700,1,14.28,100,1,12.42,700,1,14.43,100,1,12.37,700,1,14.53,100,1,ARL,325109165
2025-07-17T16:01:56.264154095Z,2025-07-17T16:01:56.263988198Z,10,2,1108,C,A,0,13.58,100,0,165897,271251019,13.04,2,1,13.55,15,1,13.03,100,1,13.57,15,1,13.02,100,1,13.59,100,1,12.73,100,1,13.90,100,1,12.71,100,1,14.01,2,1,12.50,700,1,14.19,100,1,12.46,200,2,14.28,100,1,12.43,700,1,14.43,100,1,12.42,700,1,14.53,100,1,12.37,700,1,14.54,100,1,ARL,324942229
2025-07-17T16:01:56.264154095Z,2025-07-17T16:01:56.263988198Z,10,2,1108,A,A,0,13.56,100,130,165897,271251019,13.04,2,1,13.55,15,1,13.03,100,1,13.56,100,1,13.02,100,1,13.57,15,1,12.73,100,1,13.59,100,1,12.71,100,1,13.90,100,1,12.50,700,1,14.01,2,1,12.46,200,2,14.19,100,1,12.43,700,1,14.28,100,1,12.42,700,1,14.43,100,1,12.37,700,1,14.53,100,1,ARL,325176181
2025-07-17T16:01:56.269623788Z,2025-07-17T16:01:56.269458197Z,10,2,1108,C,A,0,13.90,100,130,165591,271251357,13.04,2,1,13.55,15,1,13.03,100,1,13.56,100,1,13.02,100,1,13.57,15,1,12.73,100,1,13.59,100,1,12.71,100,1,14.01,2,1,12.50,700,1,14.19,100,1,12.46,200,2,14.28,100,1,12.43,700,1,14.43,100,1,12.42,700,1,14.53,100,1,12.37,700,1,14.54,100,1,ARL,324186721
2025-07-17T16:01:56.269674232Z,2025-07-17T16:01:56.269508928Z,10,2,1108,A,A,0,13.83,100,130,165304,271251358,13.04,2,1,13.55,15,1,13.03,100,1,13.56,100,1,13.02,100,1,13.57,15,1,12.73,100,1,13.59,100,1,12.71,100,1,13.83,100,1,12.50,700,1,14.01,2,1,12.46,200,2,14.19,100,1,12.43,700,1,14.28,100,1,12.42,700,1,14.43,100,1,12.37,700,1,14.53,100,1,ARL,325176373
2025-07-17T16:01:56.272340730Z,2025-07-17T16:01:56.272175169Z,10,2,1108,C,A,0,15.76,100,0,165561,271251490,13.04,2,1,13.55,15,1,13.03,100,1,13.56,100,1,13.02,100,1,13.57,15,1,12.73,100,1,13.59,100,1,12.71,100,1,13.83,100,1,12.50,700,1,14.01,2,1,12.46,200,2,14.19,100,1,12.43,700,1,14.28,100,1,12.42,700,1,14.43,100,1,12.37,700,1,14.53,100,1,ARL,323599629
2025-07-17T16:01:56.272340730Z,2025-07-17T16:01:56.272175169Z,10,2,1108,A,A,0,15.60,100,130,165561,271251490,13.04,2,1,13.55,15,1,13.03,100,1,13.56,100,1,13.02,100,1,13.57,15,1,12.73,100,1,13.59,100,1,12.71,100,1,13.83,100,1,12.50,700,1,14.01,2,1,12.46,200,2,14.19,100,1,12.43,700,1,14.28,100,1,12.42,700,1,14.43,100,1,12.37,700,1,14.53,100,1,ARL,325176677
2025-07-17T16:01:56.300889378Z,2025-07-17T16:01:56.300723805Z,10,2,1108,C,A,0,14.66,100,0,165573,271252044,13.04,2,1,13.55,15,1,13.03,100,1,13.56,100,1,13.02,100,1,13.57,15,1,12.73,100,1,13.59,100,1,12.71,100,1,13.83,100,1,12.50,700,1,14.01,2,1,12.46,200,2,14.19,100,1,12.43,700,1,14.28,100,1,12.42,700,1,14.43,100,1,12.37,700,1,14.53,100,1,ARL,323599625
2025-07-17T16:01:56.300889378Z,2025-07-17T16:01:56.300723805Z,10,2,1108,A,A,0,14.51,100,130,165573,271252044,13.04,2,1,13.55,15,1,13.03,100,1,13.56,100,1,13.02,100,1,13.57,15,1,12.73,100,1,13.59,100,1,12.71,100,1,13.83,100,1,12.50,700,1,14.01,2,1,12.46,200,2,14.19,100,1,12.43,700,1,14.28,100,1,12.42,700,1,14.43,100,1,12.37,700,1,14.51,100,1,ARL,325177757
2025-07-17T16:01:56.776980244Z,2025-07-17T16:01:56.776814001Z,10,2,1108,T,N,0,13.41,16,130,166243,271255700,13.04,2,1,13.55,15,1,13.03,100,1,13.56,100,1,13.02,100,1,13.57,15,1,12.73,100,1,13.59,100,1,12.71,100,1,13.83,100,1,12.50,700,1,14.01,2,1,12.46,200,2,14.19,100,1,12.43,700,1,14.28,100,1,12.42,700,1,14.43,100,1,12.37,700,1,14.51,100,1,ARL,0
2025-07-17T16:01:56.777414332Z,2025-07-17T16:01:56.777248616Z,10,2,1108,T,N,0,13.41,16,130,165716,271255708,13.04,2,1,13.55,15,1,13.03,100,1,13.56,100,1,13.02,100,1,13.57,15,1,12.73,100,1,13.59,100,1,12.71,100,1,13.83,100,1,12.50,700,1,14.01,2,1,12.46,200,2,14.19,100,1,12.43,700,1,14.28,100,1,12.42,700,1,14.43,100,1,12.37,700,1,14.51,100,1,ARL,0
2025-07-17T16:01:56.777906069Z,2025-07-17T16:01:56.777739254Z,10,2,1108,T,N,0,13.41,4,130,166815,271255712,13.04,2,1,13.55,15,1,13.03,100,1,13.56,100,1,13.02,100,1,13.57,15,1,12.73,100,1,13.59,100,1,12.71,100,1,13.83,100,1,12.50,700,1,14.01,2,1,12.46,200,2,14.19,100,1,12.43,700,1,14.28,100,1,12.42,700,1,14.43,100,1,12.37,700,1,14.51,100,1,ARL,0
2025-07-17T16:02:01.992544607Z,2025-07-17T16:02:01.992379223Z,10,2,1108,C,A,0,14.01,2,0,165384,271343251,13.04,2,1,13.55,15,1,13.03,100,1,13.56,100,1,13.02,100,1,13.57,15,1,12.73,100,1,13.59,100,1,12.71,100,1,13.83,100,1,12.50,700,1,14.19,100,1,12.46,200,2,14.28,100,1,12.43,700,1,14.43,100,1,12.42,700,1,14.51,100,1,12.37,700,1,14.53,100,1,ARL,322898193
2025-07-17T16:02:01.992544607Z,2025-07-17T16:02:01.992379223Z,10,2,1108,A,A,0,13.92,2,130,165384,271343251,13.04,2,1,13.55,15,1,13.03,100,1,13.56,100,1,13.02,100,1,13.57,15,1,12.73,100,1,13.59,100,1,12.71,100,1,13.83,100,1,12.50,700,1,13.92,2,1,12.46,200,2,14.19,100,1,12.43,700,1,14.28,100,1,12.42,700,1,14.43,100,1,12.37,700,1,14.51,100,1,ARL,325297093
2025-07-17T16:02:03.207720826Z,2025-07-17T16:02:03.207555626Z,10,2,1108,C,A,0,13.57,15,130,165200,271367066,13.04,2,1,13.55,15,1,13.03,100,1,13.56,100,1,13.02,100,1,13.59,100,1,12.73,100,1,13.83,100,1,12.71,100,1,13.92,2,1,12.50,700,1,14.19,100,1,12.46,200,2,14.28,100,1,12.43,700,1,14.43,100,1,12.42,700,1,14.51,100,1,12.37,700,1,14.53,100,1,ARL,324934601
2025-07-17T16:02:04.212956339Z,2025-07-17T16:02:04.212791108Z,10,2,1108,A,A,0,13.53,15,130,165231,271415821,13.04,2,1,13.53,15,1,13.03,100,1,13.55,15,1,13.02,100,1,13.56,100,1,12.73,100,1,13.59,100,1,12.71,100,1,13.83,100,1,12.50,700,1,13.92,2,1,12.46,200,2,14.19,100,1,12.43,700,1,14.28,100,1,12.42,700,1,14.43,100,1,12.37,700,1,14.51,100,1,ARL,325382429
2025-07-17T16:02:04.214348814Z,2025-07-17T16:02:04.214183279Z,10,2,1108,C,A,0,14.54,100,0,165535,271415834,13.04,2,1,13.53,15,1,13.03,100,1,13.55,15,1,13.02,100,1,13.56,100,1,12.73,100,1,13.59,100,1,12.71,100,1,13.83,100,1,12.50,700,1,13.92,2,1,12.46,200,2,14.19,100,1,12.43,700,1,14.28,100,1,12.42,700,1,14.43,100,1,12.37,700,1,14.51,100,1,ARL,323775433
2025-07-17T16:02:04.214348814Z,2025-07-17T16:02:04.214183279Z,10,2,1108,A,A,0,14.43,100,130,165535,271415834,13.04,2,1,13.53,15,1,13.03,100,1,13.55,15,1,13.02,100,1,13.56,100,1,12.73,100,1,13.59,100,1,12.71,100,1,13.83,100,1,12.50,700,1,13.92,2,1,12.46,200,2,14.19,100,1,12.43,700,1,14.28,100,1,12.42,700,1,14.43,200,2,12.37,700,1,14.51,100,1,ARL,325382437
2025-07-17T16:02:04.840132668Z,2025-07-17T16:02:04.839967173Z,10,2,1108,C,A,0,13.56,100,0,165495,271432190,13.04,2,1,13.53,15,1,13.03,100,1,13.55,15,1,13.02,100,1,13.59,100,1,12.73,100,1,13.83,100,1,12.71,100,1,13.92,2,1,12.50,700,1,14.19,100,1,12.46,200,2,14.28,100,1,12.43,700,1,14.43,200,2,12.42,700,1,14.51,100,1,12.37,700,1,14.53,100,1,ARL,325176181
2025-07-17T16:02:04.840132668Z,2025-07-17T16:02:04.839967173Z,10,2,1108,A,A,0,13.54,100,130,165495,271432190,13.04,2,1,13.53,15,1,13.03,100,1,13.54,100,1,13.02,100,1,13.55,15,1,12.73,100,1,13.59,100,1,12.71,100,1,13.83,100,1,12.50,700,1,13.92,2,1,12.46,200,2,14.19,100,1,12.43,700,1,14.28,100,1,12.42,700,1,14.43,200,2,12.37,700,1,14.51,100,1,ARL,325400045
2025-07-17T16:02:04.840171240Z,2025-07-17T16:02:04.840006082Z,10,2,1108,A,A,0,14.27,700,130,165158,271432192,13.04,2,1,13.53,15,1,13.03,100,1,13.54,100,1,13.02,100,1,13.55,15,1,12.73,100,1,13.59,100,1,12.71,100,1,13.83,100,1,12.50,700,1,13.92,2,1,12.46,200,2,14.19,100,1,12.43,700,1,14.27,700,1,12.42,700,1,14.28,100,1,12.37,700,1,14.43,200,2,ARL,325400053
2025-07-17T16:02:04.840210880Z,2025-07-17T16:02:04.840045694Z,10,2,1108,C,A,0,14.68,700,130,165186,271432193,13.04,2,1,13.53,15,1,13.03,100,1,13.54,100,1,13.02,100,1,13.55,15,1,12.73,100,1,13.59,100,1,12.71,100,1,13.83,100,1,12.50,700,1,13.92,2,1,12.46,200,2,14.19,100,1,12.43,700,1,14.27,700,1,12.42,700,1,14.28,100,1,12.37,700,1,14.43,200,2,ARL,283592941
2025-07-17T16:02:04.840877603Z,2025-07-17T16:02:04.840711803Z,10,2,1108,C,A,0,14.63,100,0,165800,271432231,13.04,2,1,13.53,15,1,13.03,100,1,13.54,100,1,13.02,100,1,13.55,15,1,12.73,100,1,13.59,100,1,12.71,100,1,13.83,100,1,12.50,700,1,13.92,2,1,12.46,200,2,14.19,100,1,12.43,700,1,14.27,700,1,12.42,700,1,14.28,100,1,12.37,700,1,14.43,200,2,ARL,324942257
2025-07-17T16:02:04.840877603Z,2025-07-17T16:02:04.840711803Z,10,2,1108,A,A,0,14.59,100,130,165800,271432231,13.04,2,1,13.53,15,1,13.03,100,1,13.54,100,1,13.02,100,1,13.55,15,1,12.73,100,1,13.59,100,1,12.71,100,1,13.83,100,1,12.50,700,1,13.92,2,1,12.46,200,2,14.19,100,1,12.43,700,1,14.27,700,1,12.42,700,1,14.28,100,1,12.37,700,1,14.43,200,2,ARL,325400105
2025-07-17T16:02:11.249291142Z,2025-07-17T16:02:11.249125653Z,10,2,1108,C,A,0,14.53,100,0,165489,271526467,13.04,2,1,13.53,15,1,13.03,100,1,13.54,100,1,13.02,100,1,13.55,15,1,12.73,100,1,13.59,100,1,12.71,100,1,13.83,100,1,12.50,700,1,13.92,2,1,12.46,200,2,14.19,100,1,12.43,700,1,14.27,700,1,12.42,700,1,14.28,100,1,12.37,700,1,14.43,200,2,ARL,323775457
2025-07-17T16:02:11.249291142Z,2025-07-17T16:02:11.249125653Z,10,2,1108,A,A,0,14.42,100,130,165489,271526467,13.04,2,1,13.53,15,1,13.03,100,1,13.54,100,1,13.02,100,1,13.55,15,1,12.73,100,1,13.59,100,1,12.71,100,1,13.83,100,1,12.50,700,1,13.92,2,1,12.46,200,2,14.19,100,1,12.43,700,1,14.27,700,1,12.42,700,1,14.28,100,1,12.37,700,1,14.42,100,1,ARL,325520705
2025-07-17T16:02:15.062774661Z,2025-07-17T16:02:15.062605521Z,10,2,1108,C,A,0,13.53,15,128,169140,271576282,13.04,2,1,13.54,100,1,13.03,100,1,13.55,15,1,13.02,100,1,13.59,100,1,12.73,100,1,13.83,100,1,12.71,100,1,13.92,2,1,12.50,700,1,14.19,100,1,12.46,200,2,14.27,700,1,12.43,700,1,14.28,100,1,12.42,700,1,14.42,100,1,12.37,700,1,14.43,200,2,ARL,325382429
2025-07-17T16:02:15.068449048Z,2025-07-17T16:02:15.068283706Z,10,2,1108,C,A,0,13.55,15,130,165342,271577104,13.04,2,1,13.54,100,1,13.03,100,1,13.59,100,1,13.02,100,1,13.83,100,1,12.73,100,1,13.92,2,1,12.71,100,1,14.19,100,1,12.50,700,1,14.27,700,1,12.46,200,2,14.28,100,1,12.43,700,1,14.42,100,1,12.42,700,1,14.43,200,2,12.37,700,1,14.51,100,1,ARL,325109165
2025-07-17T16:02:20.635028489Z,2025-07-17T16:02:20.634863301Z,10,2,1108,C,A,0,13.54,100,130,165188,271675842,13.04,2,1,13.59,100,1,13.03,100,1,13.83,100,1,13.02,100,1,13.92,2,1,12.73,100,1,14.19,100,1,12.71,100,1,14.27,700,1,12.50,700,1,14.28,100,1,12.46,200,2,14.42,100,1,12.43,700,1,14.43,200,2,12.42,700,1,14.51,100,1,12.37,700,1,14.56,800,2,ARL,325400045
2025-07-17T16:02:20.635782472Z,2025-07-17T16:02:20.635616654Z,10,2,1108,C,A,0,14.59,100,0,165818,271675858,13.04,2,1,13.59,100,1,13.03,100,1,13.83,100,1,13.02,100,1,13.92,2,1,12.73,100,1,14.19,100,1,12.71,100,1,14.27,700,1,12.50,700,1,14.28,100,1,12.46,200,2,14.42,100,1,12.43,700,1,14.43,200,2,12.42,700,1,14.51,100,1,12.37,700,1,14.56,800,2,ARL,325400105
2025-07-17T16:02:20.635782472Z,2025-07-17T16:02:20.635616654Z,10,2,1108,A,A,0,14.64,100,130,165818,271675858,13.04,2,1,13.59,100,1,13.03,100,1,13.83,100,1,13.02,100,1,13.92,2,1,12.73,100,1,14.19,100,1,12.71,100,1,14.27,700,1,12.50,700,1,14.28,100,1,12.46,200,2,14.42,100,1,12.43,700,1,14.43,200,2,12.42,700,1,14.51,100,1,12.37,700,1,14.56,800,2,ARL,325714169
2025-07-17T16:02:20.650466751Z,2025-07-17T16:02:20.650301212Z,10,2,1108,C,A,0,13.59,100,130,165539,271676032,13.04,2,1,13.83,100,1,13.03,100,1,13.92,2,1,13.02,100,1,14.19,100,1,12.73,100,1,14.27,700,1,12.71,100,1,14.28,100,1,12.50,700,1,14.42,100,1,12.46,200,2,14.43,200,2,12.43,700,1,14.51,100,1,12.42,700,1,14.56,800,2,12.37,700,1,14.57,100,1,ARL,325022101
2025-07-17T16:02:20.650501448Z,2025-07-17T16:02:20.650335946Z,10,2,1108,C,A,0,14.27,700,130,165502,271676033,13.04,2,1,13.83,100,1,13.03,100,1,13.92,2,1,13.02,100,1,14.19,100,1,12.73,100,1,14.28,100,1,12.71,100,1,14.42,100,1,12.50,700,1,14.43,200,2,12.46,200,2,14.51,100,1,12.43,700,1,14.56,800,2,12.42,700,1,14.57,100,1,12.37,700,1,14.60,700,1,ARL,325400053
2025-07-17T16:02:20.650546483Z,2025-07-17T16:02:20.650381040Z,10,2,1108,A,A,0,14.53,700,130,165443,271676035,13.04,2,1,13.83,100,1,13.03,100,1,13.92,2,1,13.02,100,1,14.19,100,1,12.73,100,1,14.28,100,1,12.71,100,1,14.42,100,1,12.50,700,1,14.43,200,2,12.46,200,2,14.51,100,1,12.43,700,1,14.53,700,1,12.42,700,1,14.56,800,2,12.37,700,1,14.57,100,1,ARL,325714545
2025-07-17T16:02:20.651186537Z,2025-07-17T16:02:20.651020858Z,10,2,1108,C,A,0,14.42,100,0,165679,271676048,13.04,2,1,13.83,100,1,13.03,100,1,13.92,2,1,13.02,100,1,14.19,100,1,12.73,100,1,14.28,100,1,12.71,100,1,14.43,200,2,12.50,700,1,14.51,100,1,12.46,200,2,14.53,700,1,12.43,700,1,14.56,800,2,12.42,700,1,14.57,100,1,12.37,700,1,14.60,700,1,ARL,325520705
2025-07-17T16:02:20.651186537Z,2025-07-17T16:02:20.651020858Z,10,2,1108,A,A,0,14.73,100,130,165679,271676048,13.04,2,1,13.83,100,1,13.03,100,1,13.92,2,1,13.02,100,1,14.19,100,1,12.73,100,1,14.28,100,1,12.71,100,1,14.43,200,2,12.50,700,1,14.51,100,1,12.46,200,2,14.53,700,1,12.43,700,1,14.56,800,2,12.42,700,1,14.57,100,1,12.37,700,1,14.60,700,1,ARL,325714577
2025-07-17T16:02:20.651201182Z,2025-07-17T16:02:20.651035000Z,10,2,1108,C,A,0,14.19,100,130,166182,271676049,13.04,2,1,13.83,100,1,13.03,100,1,13.92,2,1,13.02,100,1,14.28,100,1,12.73,100,1,14.43,200,2,12.71,100,1,14.51,100,1,12.50,700,1,14.53,700,1,12.46,200,2,14.56,800,2,12.43,700,1,14.57,100,1,12.42,700,1,14.60,700,1,12.37,700,1,14.64,100,1,ARL,324942273
2025-07-17T16:02:20.651459317Z,2025-07-17T16:02:20.651293729Z,10,2,1108,C,A,0,17.25,100,0,165588,271676055,13.04,2,1,13.83,100,1,13.03,100,1,13.92,2,1,13.02,100,1,14.28,100,1,12.73,100,1,14.43,200,2,12.71,100,1,14.51,100,1,12.50,700,1,14.53,700,1,12.46,200,2,14.56,800,2,12.43,700,1,14.57,100,1,12.42,700,1,14.60,700,1,12.37,700,1,14.64,100,1,ARL,324942361
2025-07-17T16:02:20.651459317Z,2025-07-17T16:02:20.651293729Z,10,2,1108,A,A,0,17.57,100,130,165588,271676055,13.04,2,1,13.83,100,1,13.03,100,1,13.92,2,1,13.02,100,1,14.28,100,1,12.73,100,1,14.43,200,2,12.71,100,1,14.51,100,1,12.50,700,1,14.53,700,1,12.46,200,2,14.56,800,2,12.43,700,1,14.57,100,1,12.42,700,1,14.60,700,1,12.37,700,1,14.64,100,1,ARL,325714589
2025-07-17T16:02:20.651558948Z,2025-07-17T16:02:20.651393708Z,10,2,1108,A,A,0,14.45,100,130,165240,271676057,13.04,2,1,13.83,100,1,13.03,100,1,13.92,2,1,13.02,100,1,14.28,100,1,12.73,100,1,14.43,200,2,12.71,100,1,14.45,100,1,12.50,700,1,14.51,100,1,12.46,200,2,14.53,700,1,12.43,700,1,14.56,800,2,12.42,700,1,14.57,100,1,12.37,700,1,14.60,700,1,ARL,325714601
2025-07-17T16:02:20.651787813Z,2025-07-17T16:02:20.651618897Z,10,2,1108,C,A,0,14.43,100,0,168916,271676089,13.04,2,1,13.83,100,1,13.03,100,1,13.92,2,1,13.02,100,1,14.28,100,1,12.73,100,1,14.43,100,1,12.71,100,1,14.45,100,1,12.50,700,1,14.51,100,1,12.46,200,2,14.53,700,1,12.43,700,1,14.56,800,2,12.42,700,1,14.57,100,1,12.37,700,1,14.60,700,1,ARL,325382437
2025-07-17T16:02:20.651787813Z,2025-07-17T16:02:20.651618897Z,10,2,1108,A,A,0,14.73,100,128,168916,271676089,13.04,2,1,13.83,100,1,13.03,100,1,13.92,2,1,13.02,100,1,14.28,100,1,12.73,100,1,14.43,100,1,12.71,100,1,14.45,100,1,12.50,700,1,14.51,100,1,12.46,200,2,14.53,700,1,12.43,700,1,14.56,800,2,12.42,700,1,14.57,100,1,12.37,700,1,14.60,700,1,ARL,325714613
2025-07-17T16:02:20.652021618Z,2025-07-17T16:02:20.651854531Z,10,2,1108,C,A,0,14.57,100,0,167087,271676104,13.04,2,1,13.83,100,1,13.03,100,1,13.92,2,1,13.02,100,1,14.28,100,1,12.73,100,1,14.43,100,1,12.71,100,1,14.45,100,1,12.50,700,1,14.51,100,1,12.46,200,2,14.53,700,1,12.43,700,1,14.56,800,2,12.42,700,1,14.60,700,1,12.37,700,1,14.64,100,1,ARL,324619409
2025-07-17T16:02:20.652021618Z,2025-07-17T16:02:20.651854531Z,10,2,1108,A,A,0,14.80,100,130,167087,271676104,13.04,2,1,13.83,100,1,13.03,100,1,13.92,2,1,13.02,100,1,14.28,100,1,12.73,100,1,14.43,100,1,12.71,100,1,14.45,100,1,12.50,700,1,14.51,100,1,12.46,200,2,14.53,700,1,12.43,700,1,14.56,800,2,12.42,700,1,14.60,700,1,12.37,700,1,14.64,100,1,ARL,325714629
2025-07-17T16:02:20.652097288Z,2025-07-17T16:02:20.651932129Z,10,2,1108,C,A,0,14.43,100,130,165159,271676110,13.04,2,1,13.83,100,1,13.03,100,1,13.92,2,1,13.02,100,1,14.28,100,1,12.73,100,1,14.45,100,1,12.71,100,1,14.51,100,1,12.50,700,1,14.53,700,1,12.46,200,2,14.56,800,2,12.43,700,1,14.60,700,1,12.42,700,1,14.64,100,1,12.37,700,1,14.68,700,1,ARL,324186781
2025-07-17T16:02:20.652160470Z,2025-07-17T16:02:20.651994883Z,10,2,1108,C,A,0,15.60,100,0,165587,271676111,13.04,2,1,13.83,100,1,13.03,100,1,13.92,2,1,13.02,100,1,14.28,100,1,12.73,100,1,14.45,100,1,12.71,100,1,14.51,100,1,12.50,700,1,14.53,700,1,12.46,200,2,14.56,800,2,12.43,700,1,14.60,700,1,12.42,700,1,14.64,100,1,12.37,700,1,14.68,700,1,ARL,325176677
2025-07-17T16:02:20.652160470Z,2025-07-17T16:02:20.651994883Z,10,2,1108,A,A,0,15.91,100,130,165587,271676111,13.04,2,1,13.83,100,1,13.03,100,1,13.92,2,1,13.02,100,1,14.28,100,1,12.73,100,1,14.45,100,1,12.71,100,1,14.51,100,1,12.50,700,1,14.53,700,1,12.46,200,2,14.56,800,2,12.43,700,1,14.60,700,1,12.42,700,1,14.64,100,1,12.37,700,1,14.68,700,1,ARL,325714633
2025-07-17T16:02:20.652259931Z,2025-07-17T16:02:20.652094426Z,10,2,1108,A,A,0,14.63,100,130,165505,271676118,13.04,2,1,13.83,100,1,13.03,100,1,13.92,2,1,13.02,100,1,14.28,100,1,12.73,100,1,14.45,100,1,12.71,100,1,14.51,100,1,12.50,700,1,14.53,700,1,12.46,200,2,14.56,800,2,12.43,700,1,14.60,700,1,12.42,700,1,14.63,100,1,12.37,700,1,14.64,100,1,ARL,325714653
2025-07-17T16:02:20.653626391Z,2025-07-17T16:02:20.653460814Z,10,2,1108,A,B,0,13.27,10,130,165577,271676147,13.27,10,1,13.83,100,1,13.04,2,1,13.92,2,1,13.03,100,1,14.28,100,1,13.02,100,1,14.45,100,1,12.73,100,1,14.51,100,1,12.71,100,1,14.53,700,1,12.50,700,1,14.56,800,2,12.46,200,2,14.60,700,1,12.43,700,1,14.63,100,1,12.42,700,1,14.64,100,1,ARL,325714717
2025-07-17T16:02:20.653627232Z,2025-07-17T16:02:20.653461966Z,10,2,1108,A,A,0,13.83,15,130,165266,271676148,13.27,10,1,13.83,115,2,13.04,2,1,13.92,2,1,13.03,100,1,14.28,100,1,13.02,100,1,14.45,100,1,12.73,100,1,14.51,100,1,12.71,100,1,14.53,700,1,12.50,700,1,14.56,800,2,12.46,200,2,14.60,700,1,12.43,700,1,14.63,100,1,12.42,700,1,14.64,100,1,ARL,325714721
2025-07-17T16:02:20.653886896Z,2025-07-17T16:02:20.653721185Z,10,2,1108,C,B,0,13.02,100,0,165711,271676153,13.27,10,1,13.83,115,2,13.04,2,1,13.92,2,1,13.03,100,1,14.28,100,1,12.73,100,1,14.45,100,1,12.71,100,1,14.51,100,1,12.50,700,1,14.53,700,1,12.46,200,2,14.56,800,2,12.43,700,1,14.60,700,1,12.42,700,1,14.63,100,1,12.37,700,1,14.64,100,1,ARL,320485385
2025-07-17T16:02:20.653886896Z,2025-07-17T16:02:20.653721185Z,10,2,1108,A,B,0,13.26,100,130,165711,271676153,13.27,10,1,13.83,115,2,13.26,100,1,13.92,2,1,13.04,2,1,14.28,100,1,13.03,100,1,14.45,100,1,12.73,100,1,14.51,100,1,12.71,100,1,14.53,700,1,12.50,700,1,14.56,800,2,12.46,200,2,14.60,700,1,12.43,700,1,14.63,100,1,12.42,700,1,14.64,100,1,ARL,325714729
2025-07-17T16:02:20.655277066Z,2025-07-17T16:02:20.655111649Z,10,2,1108,C,B,0,13.04,2,0,165417,271676165,13.27,10,1,13.83,115,2,13.26,100,1,13.92,2,1,13.03,100,1,14.28,100,1,12.73,100,1,14.45,100,1,12.71,100,1,14.51,100,1,12.50,700,1,14.53,700,1,12.46,200,2,14.56,800,2,12.43,700,1,14.60,700,1,12.42,700,1,14.63,100,1,12.37,700,1,14.64,100,1,ARL,293594281
2025-07-17T16:02:20.655277066Z,2025-07-17T16:02:20.655111649Z,10,2,1108,A,B,0,12.91,2,130,165417,271676165,13.27,10,1,13.83,115,2,13.26,100,1,13.92,2,1,13.03,100,1,14.28,100,1,12.91,2,1,14.45,100,1,12.73,100,1,14.51,100,1,12.71,100,1,14.53,700,1,12.50,700,1,14.56,800,2,12.46,200,2,14.60,700,1,12.43,700,1,14.63,100,1,12.42,700,1,14.64,100,1,ARL,325714741
2025-07-17T16:02:20.663374576Z,2025-07-17T16:02:20.663209235Z,10,2,1108,C,A,0,13.83,100,130,165341,271676274,13.27,10,1,13.83,15,1,13.26,100,1,13.92,2,1,13.03,100,1,14.28,100,1,12.91,2,1,14.45,100,1,12.73,100,1,14.51,100,1,12.71,100,1,14.53,700,1,12.50,700,1,14.56,800,2,12.46,200,2,14.60,700,1,12.43,700,1,14.63,100,1,12.42,700,1,14.64,100,1,ARL,325176373
2025-07-17T16:02:20.663406861Z,2025-07-17T16:02:20.663241882Z,10,2,1108,C,A,0,14.53,700,130,164979,271676275,13.27,10,1,13.83,15,1,13.26,100,1,13.92,2,1,13.03,100,1,14.28,100,1,12.91,2,1,14.45,100,1,12.73,100,1,14.51,100,1,12.71,100,1,14.56,800,2,12.50,700,1,14.60,700,1,12.46,200,2,14.63,100,1,12.43,700,1,14.64,100,1,12.42,700,1,14.68,700,1,ARL,325714545
2025-07-17T16:02:20.663426974Z,2025-07-17T16:02:20.663261632Z,10,2,1108,A,A,0,14.11,100,130,165342,271676276,13.27,10,1,13.83,15,1,13.26,100,1,13.92,2,1,13.03,100,1,14.11,100,1,12.91,2,1,14.28,100,1,12.73,100,1,14.45,100,1,12.71,100,1,14.51,100,1,12.50,700,1,14.56,800,2,12.46,200,2,14.60,700,1,12.43,700,1,14.63,100,1,12.42,700,1,14.64,100,1,ARL,325714905
2025-07-17T16:02:20.663559466Z,2025-07-17T16:02:20.663394059Z,10,2,1108,A,A,0,15.94,100,130,165407,271676277,13.27,10,1,13.83,15,1,13.26,100,1,13.92,2,1,13.03,100,1,14.11,100,1,12.91,2,1,14.28,100,1,12.73,100,1,14.45,100,1,12.71,100,1,14.51,100,1,12.50,700,1,14.56,800,2,12.46,200,2,14.60,700,1,12.43,700,1,14.63,100,1,12.42,700,1,14.64,100,1,ARL,325714909
2025-07-17T16:02:20.663572634Z,2025-07-17T16:02:20.663407337Z,10,2,1108,C,A,0,15.59,100,130,165297,271676278,13.27,10,1,13.83,15,1,13.26,100,1,13.92,2,1,13.03,100,1,14.11,100,1,12.91,2,1,14.28,100,1,12.73,100,1,14.45,100,1,12.71,100,1,14.51,100,1,12.50,700,1,14.56,800,2,12.46,200,2,14.60,700,1,12.43,700,1,14.63,100,1,12.42,700,1,14.64,100,1,ARL,323730697
2025-07-17T16:02:20.664956400Z,2025-07-17T16:02:20.664790768Z,10,2,1108,C,A,0,17.57,100,0,165632,271676310,13.27,10,1,13.83,15,1,13.26,100,1,13.92,2,1,13.03,100,1,14.11,100,1,12.91,2,1,14.28,100,1,12.73,100,1,14.45,100,1,12.71,100,1,14.51,100,1,12.50,700,1,14.56,800,2,12.46,200,2,14.60,700,1,12.43,700,1,14.63,100,1,12.42,700,1,14.64,100,1,ARL,325714589
2025-07-17T16:02:20.664956400Z,2025-07-17T16:02:20.664790768Z,10,2,1108,A,A,0,17.76,100,130,165632,271676310,13.27,10,1,13.83,15,1,13.26,100,1,13.92,2,1,13.03,100,1,14.11,100,1,12.91,2,1,14.28,100,1,12.73,100,1,14.45,100,1,12.71,100,1,14.51,100,1,12.50,700,1,14.56,800,2,12.46,200,2,14.60,700,1,12.43,700,1,14.63,100,1,12.42,700,1,14.64,100,1,ARL,325714949
2025-07-17T16:02:20.665129279Z,2025-07-17T16:02:20.664963386Z,10,2,1108,C,A,0,14.80,100,0,165893,271676320,13.27,10,1,13.83,15,1,13.26,100,1,13.92,2,1,13.03,100,1,14.11,100,1,12.91,2,1,14.28,100,1,12.73,100,1,14.45,100,1,12.71,100,1,14.51,100,1,12.50,700,1,14.56,800,2,12.46,200,2,14.60,700,1,12.43,700,1,14.63,100,1,12.42,700,1,14.64,100,1,ARL,325714629
2025-07-17T16:02:20.665129279Z,2025-07-17T16:02:20.664963386Z,10,2,1108,A,A,0,14.96,100,130,165893,271676320,13.27,10,1,13.83,15,1,13.26,100,1,13.92,2,1,13.03,100,1,14.11,100,1,12.91,2,1,14.28,100,1,12.73,100,1,14.45,100,1,12.71,100,1,14.51,100,1,12.50,700,1,14.56,800,2,12.46,200,2,14.60,700,1,12.43,700,1,14.63,100,1,12.42,700,1,14.64,100,1,ARL,325714953
2025-07-17T16:02:20.665200392Z,2025-07-17T16:02:20.665034825Z,10,2,1108,C,A,0,15.91,100,0,165567,271676330,13.27,10,1,13.83,15,1,13.26,100,1,13.92,2,1,13.03,100,1,14.11,100,1,12.91,2,1,14.28,100,1,12.73,100,1,14.45,100,1,12.71,100,1,14.51,100,1,12.50,700,1,14.56,800,2,12.46,200,2,14.60,700,1,12.43,700,1,14.63,100,1,12.42,700,1,14.64,100,1,ARL,325714633
2025-07-17T16:02:20.665200392Z,2025-07-17T16:02:20.665034825Z,10,2,1108,A,A,0,16.08,100,130,165567,271676330,13.27,10,1,13.83,15,1,13.26,100,1,13.92,2,1,13.03,100,1,14.11,100,1,12.91,2,1,14.28,100,1,12.73,100,1,14.45,100,1,12.71,100,1,14.51,100,1,12.50,700,1,14.56,800,2,12.46,200,2,14.60,700,1,12.43,700,1,14.63,100,1,12.42,700,1,14.64,100,1,ARL,325714957
2025-07-17T16:02:20.665457595Z,2025-07-17T16:02:20.665292049Z,10,2,1108,C,A,0,14.94,100,0,165546,271676355,13.27,10,1,13.83,15,1,13.26,100,1,13.92,2,1,13.03,100,1,14.11,100,1,12.91,2,1,14.28,100,1,12.73,100,1,14.45,100,1,12.71,100,1,14.51,100,1,12.50,700,1,14.56,800,2,12.46,200,2,14.60,700,1,12.43,700,1,14.63,100,1,12.42,700,1,14.64,100,1,ARL,324942277
2025-07-17T16:02:20.665457595Z,2025-07-17T16:02:20.665292049Z,10,2,1108,A,A,0,15.38,100,130,165546,271676355,13.27,10,1,13.83,15,1,13.26,100,1,13.92,2,1,13.03,100,1,14.11,100,1,12.91,2,1,14.28,100,1,12.73,100,1,14.45,100,1,12.71,100,1,14.51,100,1,12.50,700,1,14.56,800,2,12.46,200,2,14.60,700,1,12.43,700,1,14.63,100,1,12.42,700,1,14.64,100,1,ARL,325714965
2025-07-17T16:02:20.669701452Z,2025-07-17T16:02:20.669536385Z,10,2,1108,C,A,0,14.11,100,130,165067,271676398,13.27,10,1,13.83,15,1,13.26,100,1,13.92,2,1,13.03,100,1,14.28,100,1,12.91,2,1,14.45,100,1,12.73,100,1,14.51,100,1,12.71,100,1,14.56,800,2,12.50,700,1,14.60,700,1,12.46,200,2,14.63,100,1,12.43,700,1,14.64,100,1,12.42,700,1,14.68,700,1,ARL,325714905
2025-07-17T16:02:20.669748954Z,2025-07-17T16:02:20.669583810Z,10,2,1108,A,A,0,14.26,100,130,165144,271676399,13.27,10,1,13.83,15,1,13.26,100,1,13.92,2,1,13.03,100,1,14.26,100,1,12.91,2,1,14.28,100,1,12.73,100,1,14.45,100,1,12.71,100,1,14.51,100,1,12.50,700,1,14.56,800,2,12.46,200,2,14.60,700,1,12.43,700,1,14.63,100,1,12.42,700,1,14.64,100,1,ARL,325715045
2025-07-17T16:02:20.669752979Z,2025-07-17T16:02:20.669587514Z,10,2,1108,C,A,0,14.51,100,0,165465,271676400,13.27,10,1,13.83,15,1,13.26,100,1,13.92,2,1,13.03,100,1,14.26,100,1,12.91,2,1,14.28,100,1,12.73,100,1,14.45,100,1,12.71,100,1,14.56,800,2,12.50,700,1,14.60,700,1,12.46,200,2,14.63,100,1,12.43,700,1,14.64,100,1,12.42,700,1,14.68,700,1,ARL,325177757
2025-07-17T16:02:20.669752979Z,2025-07-17T16:02:20.669587514Z,10,2,1108,A,A,0,14.96,100,130,165465,271676400,13.27,10,1,13.83,15,1,13.26,100,1,13.92,2,1,13.03,100,1,14.26,100,1,12.91,2,1,14.28,100,1,12.73,100,1,14.45,100,1,12.71,100,1,14.56,800,2,12.50,700,1,14.60,700,1,12.46,200,2,14.63,100,1,12.43,700,1,14.64,100,1,12.42,700,1,14.68,700,1,ARL,325715053
2025-07-17T16:02:20.685252049Z,2025-07-17T16:02:20.685086585Z,10,2,1108,C,A,0,14.64,100,0,165464,271676621,13.27,10,1,13.83,15,1,13.26,100,1,13.92,2,1,13.03,100,1,14.26,100,1,12.91,2,1,14.28,100,1,12.73,100,1,14.45,100,1,12.71,100,1,14.56,800,2,12.50,700,1,14.60,700,1,12.46,200,2,14.63,100,1,12.43,700,1,14.68,700,1,12.42,700,1,14.73,200,2,ARL,325714169
2025-07-17T16:02:20.685252049Z,2025-07-17T16:02:20.685086585Z,10,2,1108,A,A,0,15.06,100,130,165464,271676621,13.27,10,1,13.83,15,1,13.26,100,1,13.92,2,1,13.03,100,1,14.26,100,1,12.91,2,1,14.28,100,1,12.73,100,1,14.45,100,1,12.71,100,1,14.56,800,2,12.50,700,1,14.60,700,1,12.46,200,2,14.63,100,1,12.43,700,1,14.68,700,1,12.42,700,1,14.73,200,2,ARL,325715113
2025-07-17T16:02:20.832112637Z,2025-07-17T16:02:20.831947250Z,10,2,1108,A,A,0,14.68,700,130,165387,271678584,13.27,10,1,13.83,15,1,13.26,100,1,13.92,2,1,13.03,100,1,14.26,100,1,12.91,2,1,14.28,100,1,12.73,100,1,14.45,100,1,12.71,100,1,14.56,800,2,12.50,700,1,14.60,700,1,12.46,200,2,14.63,100,1,12.43,700,1,14.68,1400,2,12.42,700,1,14.73,200,2,ARL,325716945
2025-07-17T16:02:20.936787418Z,2025-07-17T16:02:20.936622241Z,10,2,1108,C,B,0,13.26,100,130,165177,271679553,13.27,10,1,13.83,15,1,13.03,100,1,13.92,2,1,12.91,2,1,14.26,100,1,12.73,100,1,14.28,100,1,12.71,100,1,14.45,100,1,12.50,700,1,14.56,800,2,12.46,200,2,14.60,700,1,12.43,700,1,14.63,100,1,12.42,700,1,14.68,1400,2,12.37,700,1,14.73,200,2,ARL,325714729
2025-07-17T16:02:20.936837611Z,2025-07-17T16:02:20.936672130Z,10,2,1108,A,A,0,13.91,5,130,165481,271679555,13.27,10,1,13.83,15,1,13.03,100,1,13.91,5,1,12.91,2,1,13.92,2,1,12.73,100,1,14.26,100,1,12.71,100,1,14.28,100,1,12.50,700,1,14.45,100,1,12.46,200,2,14.56,800,2,12.43,700,1,14.60,700,1,12.42,700,1,14.63,100,1,12.37,700,1,14.68,1400,2,ARL,325718477
2025-07-17T16:02:20.936914901Z,2025-07-17T16:02:20.936748894Z,10,2,1108,T,N,0,13.28,11,130,166007,271679557,13.27,10,1,13.83,15,1,13.03,100,1,13.91,5,1,12.91,2,1,13.92,2,1,12.73,100,1,14.26,100,1,12.71,100,1,14.28,100,1,12.50,700,1,14.45,100,1,12.46,200,2,14.56,800,2,12.43,700,1,14.60,700,1,12.42,700,1,14.63,100,1,12.37,700,1,14.68,1400,2,ARL,0
2025-07-17T16:02:20.936999211Z,2025-07-17T16:02:20.936833988Z,10,2,1108,A,A,0,13.84,100,130,165223,271679558,13.27,10,1,13.83,15,1,13.03,100,1,13.84,100,1,12.91,2,1,13.91,5,1,12.73,100,1,13.92,2,1,12.71,100,1,14.26,100,1,12.50,700,1,14.28,100,1,12.46,200,2,14.45,100,1,12.43,700,1,14.56,800,2,12.42,700,1,14.60,700,1,12.37,700,1,14.63,100,1,ARL,325718485
2025-07-17T16:02:20.937307935Z,2025-07-17T16:02:20.937142186Z,10,2,1108,T,N,0,13.28,11,130,165749,271679562,13.27,10,1,13.83,15,1,13.03,100,1,13.84,100,1,12.91,2,1,13.91,5,1,12.73,100,1,13.92,2,1,12.71,100,1,14.26,100,1,12.50,700,1,14.28,100,1,12.46,200,2,14.45,100,1,12.43,700,1,14.56,800,2,12.42,700,1,14.60,700,1,12.37,700,1,14.63,100,1,ARL,0
2025-07-17T16:02:20.937744264Z,2025-07-17T16:02:20.937578907Z,10,2,1108,C,A,0,15.06,100,0,165357,271679565,13.27,10,1,13.83,15,1,13.03,100,1,13.84,100,1,12.91,2,1,13.91,5,1,12.73,100,1,13.92,2,1,12.71,100,1,14.26,100,1,12.50,700,1,14.28,100,1,12.46,200,2,14.45,100,1,12.43,700,1,14.56,800,2,12.42,700,1,14.60,700,1,12.37,700,1,14.63,100,1,ARL,325715113
2025-07-17T16:02:20.937744264Z,2025-07-17T16:02:20.937578907Z,10,2,1108,A,A,0,14.91,100,130,165357,271679565,13.27,10,1,13.83,15,1,13.03,100,1,13.84,100,1,12.91,2,1,13.91,5,1,12.73,100,1,13.92,2,1,12.71,100,1,14.26,100,1,12.50,700,1,14.28,100,1,12.46,200,2,14.45,100,1,12.43,700,1,14.56,800,2,12.42,700,1,14.60,700,1,12.37,700,1,14.63,100,1,ARL,325718509
2025-07-17T16:02:20.937901293Z,2025-07-17T16:02:20.937736247Z,10,2,1108,C,A,0,13.91,5,130,165046,271679567,13.27,10,1,13.83,15,1,13.03,100,1,13.84,100,1,12.91,2,1,13.92,2,1,12.73,100,1,14.26,100,1,12.71,100,1,14.28,100,1,12.50,700,1,14.45,100,1,12.46,200,2,14.56,800,2,12.43,700,1,14.60,700,1,12.42,700,1,14.63,100,1,12.37,700,1,14.68,1400,2,ARL,325718477
2025-07-17T16:02:20.938093286Z,2025-07-17T16:02:20.937927380Z,10,2,1108,C,A,0,14.96,100,0,165906,271679569,13.27,10,1,13.83,15,1,13.03,100,1,13.84,100,1,12.91,2,1,13.92,2,1,12.73,100,1,14.26,100,1,12.71,100,1,14.28,100,1,12.50,700,1,14.45,100,1,12.46,200,2,14.56,800,2,12.43,700,1,14.60,700,1,12.42,700,1,14.63,100,1,12.37,700,1,14.68,1400,2,ARL,325715053
2025-07-17T16:02:20.938093286Z,2025-07-17T16:02:20.937927380Z,10,2,1108,A,A,0,14.81,100,130,165906,271679569,13.27,10,1,13.83,15,1,13.03,100,1,13.84,100,1,12.91,2,1,13.92,2,1,12.73,100,1,14.26,100,1,12.71,100,1,14.28,100,1,12.50,700,1,14.45,100,1,12.46,200,2,14.56,800,2,12.43,700,1,14.60,700,1,12.42,700,1,14.63,100,1,12.37,700,1,14.68,1400,2,ARL,325718517
2025-07-17T16:02:20.938297839Z,2025-07-17T16:02:20.938132716Z,10,2,1108,C,A,0,16.08,100,0,165123,271679571,13.27,10,1,13.83,15,1,13.03,100,1,13.84,100,1,12.91,2,1,13.92,2,1,12.73,100,1,14.26,100,1,12.71,100,1,14.28,100,1,12.50,700,1,14.45,100,1,12.46,200,2,14.56,800,2,12.43,700,1,14.60,700,1,12.42,700,1,14.63,100,1,12.37,700,1,14.68,1400,2,ARL,325714957
